[2023-01-19T04:10:05.421+0000] {processor.py:156} INFO - Started process (PID=3823) to work on /opt/airflow/dags/bentoml/pik_rec_bento/bento_service_pik_rec.py
[2023-01-19T04:10:05.422+0000] {processor.py:758} INFO - Processing file /opt/airflow/dags/bentoml/pik_rec_bento/bento_service_pik_rec.py for tasks to queue
[2023-01-19T04:10:05.422+0000] {logging_mixin.py:117} INFO - [2023-01-19T04:10:05.422+0000] {dagbag.py:525} INFO - Filling up the DagBag from /opt/airflow/dags/bentoml/pik_rec_bento/bento_service_pik_rec.py
[2023-01-19T04:10:07.754+0000] {logging_mixin.py:117} INFO - [2023-01-19T04:10:07.752+0000] {dagbag.py:330} ERROR - Failed to import: /opt/airflow/dags/bentoml/pik_rec_bento/bento_service_pik_rec.py
Traceback (most recent call last):
  File "/home/airflow/.local/lib/python3.8/site-packages/fs/osfs.py", line 647, in open
    return io.open(
FileNotFoundError: [Errno 2] No such file or directory: b'/home/airflow/bentoml/models/pik_recommender_model/latest'

During handling of the above exception, another exception occurred:

Traceback (most recent call last):
  File "/home/airflow/.local/lib/python3.8/site-packages/bentoml/_internal/store.py", line 132, in get
    _tag.version = self._fs.readtext(_tag.latest_path())
  File "/home/airflow/.local/lib/python3.8/site-packages/fs/base.py", line 693, in readtext
    self.open(
  File "/home/airflow/.local/lib/python3.8/site-packages/fs/osfs.py", line 647, in open
    return io.open(
  File "/home/airflow/.local/lib/python3.8/site-packages/fs/error_tools.py", line 89, in __exit__
    reraise(fserror, fserror(self._path, exc=exc_value), traceback)
  File "/home/airflow/.local/lib/python3.8/site-packages/six.py", line 718, in reraise
    raise value.with_traceback(tb)
  File "/home/airflow/.local/lib/python3.8/site-packages/fs/osfs.py", line 647, in open
    return io.open(
fs.errors.ResourceNotFound: resource 'pik_recommender_model/latest' not found

During handling of the above exception, another exception occurred:

Traceback (most recent call last):
  File "/home/airflow/.local/lib/python3.8/site-packages/bentoml/_internal/store.py", line 106, in _recreate_latest
    items = self.list(tag.name)
  File "/home/airflow/.local/lib/python3.8/site-packages/bentoml/_internal/store.py", line 83, in list
    raise NotFound(
bentoml.exceptions.NotFound: no Models with name 'pik_recommender_model' found

During handling of the above exception, another exception occurred:

Traceback (most recent call last):
  File "/home/airflow/.local/lib/python3.8/site-packages/airflow/models/dagbag.py", line 326, in parse
    loader.exec_module(new_module)
  File "<frozen importlib._bootstrap_external>", line 843, in exec_module
  File "<frozen importlib._bootstrap>", line 219, in _call_with_frames_removed
  File "/opt/airflow/dags/bentoml/pik_rec_bento/bento_service_pik_rec.py", line 31, in <module>
    runner = bentoml.transformers.get("pik_recommender_model:latest").to_runner()
  File "/home/airflow/.local/lib/python3.8/site-packages/bentoml/_internal/frameworks/transformers.py", line 151, in get
    model = bentoml.models.get(tag_like)
  File "/home/airflow/.local/lib/python3.8/site-packages/simple_di/__init__.py", line 139, in _
    return func(*_inject_args(bind.args), **_inject_kwargs(bind.kwargs))
  File "/home/airflow/.local/lib/python3.8/site-packages/bentoml/models.py", line 41, in get
    return _model_store.get(tag)
  File "/home/airflow/.local/lib/python3.8/site-packages/bentoml/_internal/store.py", line 137, in get
    self._recreate_latest(_tag)
  File "/home/airflow/.local/lib/python3.8/site-packages/bentoml/_internal/store.py", line 108, in _recreate_latest
    raise NotFound(
bentoml.exceptions.NotFound: no Models with name 'pik_recommender_model' exist in BentoML store <osfs '/home/airflow/bentoml/models'>
[2023-01-19T04:10:07.755+0000] {processor.py:770} WARNING - No viable dags retrieved from /opt/airflow/dags/bentoml/pik_rec_bento/bento_service_pik_rec.py
[2023-01-19T04:10:07.768+0000] {processor.py:178} INFO - Processing /opt/airflow/dags/bentoml/pik_rec_bento/bento_service_pik_rec.py took 2.350 seconds
[2023-01-19T04:10:38.635+0000] {processor.py:156} INFO - Started process (PID=3884) to work on /opt/airflow/dags/bentoml/pik_rec_bento/bento_service_pik_rec.py
[2023-01-19T04:10:38.636+0000] {processor.py:758} INFO - Processing file /opt/airflow/dags/bentoml/pik_rec_bento/bento_service_pik_rec.py for tasks to queue
[2023-01-19T04:10:38.637+0000] {logging_mixin.py:117} INFO - [2023-01-19T04:10:38.637+0000] {dagbag.py:525} INFO - Filling up the DagBag from /opt/airflow/dags/bentoml/pik_rec_bento/bento_service_pik_rec.py
[2023-01-19T04:10:40.829+0000] {logging_mixin.py:117} INFO - [2023-01-19T04:10:40.827+0000] {dagbag.py:330} ERROR - Failed to import: /opt/airflow/dags/bentoml/pik_rec_bento/bento_service_pik_rec.py
Traceback (most recent call last):
  File "/home/airflow/.local/lib/python3.8/site-packages/fs/osfs.py", line 647, in open
    return io.open(
FileNotFoundError: [Errno 2] No such file or directory: b'/home/airflow/bentoml/models/pik_recommender_model/latest'

During handling of the above exception, another exception occurred:

Traceback (most recent call last):
  File "/home/airflow/.local/lib/python3.8/site-packages/bentoml/_internal/store.py", line 132, in get
    _tag.version = self._fs.readtext(_tag.latest_path())
  File "/home/airflow/.local/lib/python3.8/site-packages/fs/base.py", line 693, in readtext
    self.open(
  File "/home/airflow/.local/lib/python3.8/site-packages/fs/osfs.py", line 647, in open
    return io.open(
  File "/home/airflow/.local/lib/python3.8/site-packages/fs/error_tools.py", line 89, in __exit__
    reraise(fserror, fserror(self._path, exc=exc_value), traceback)
  File "/home/airflow/.local/lib/python3.8/site-packages/six.py", line 718, in reraise
    raise value.with_traceback(tb)
  File "/home/airflow/.local/lib/python3.8/site-packages/fs/osfs.py", line 647, in open
    return io.open(
fs.errors.ResourceNotFound: resource 'pik_recommender_model/latest' not found

During handling of the above exception, another exception occurred:

Traceback (most recent call last):
  File "/home/airflow/.local/lib/python3.8/site-packages/bentoml/_internal/store.py", line 106, in _recreate_latest
    items = self.list(tag.name)
  File "/home/airflow/.local/lib/python3.8/site-packages/bentoml/_internal/store.py", line 83, in list
    raise NotFound(
bentoml.exceptions.NotFound: no Models with name 'pik_recommender_model' found

During handling of the above exception, another exception occurred:

Traceback (most recent call last):
  File "/home/airflow/.local/lib/python3.8/site-packages/airflow/models/dagbag.py", line 326, in parse
    loader.exec_module(new_module)
  File "<frozen importlib._bootstrap_external>", line 843, in exec_module
  File "<frozen importlib._bootstrap>", line 219, in _call_with_frames_removed
  File "/opt/airflow/dags/bentoml/pik_rec_bento/bento_service_pik_rec.py", line 31, in <module>
    runner = bentoml.transformers.get("pik_recommender_model:latest").to_runner()
  File "/home/airflow/.local/lib/python3.8/site-packages/bentoml/_internal/frameworks/transformers.py", line 151, in get
    model = bentoml.models.get(tag_like)
  File "/home/airflow/.local/lib/python3.8/site-packages/simple_di/__init__.py", line 139, in _
    return func(*_inject_args(bind.args), **_inject_kwargs(bind.kwargs))
  File "/home/airflow/.local/lib/python3.8/site-packages/bentoml/models.py", line 41, in get
    return _model_store.get(tag)
  File "/home/airflow/.local/lib/python3.8/site-packages/bentoml/_internal/store.py", line 137, in get
    self._recreate_latest(_tag)
  File "/home/airflow/.local/lib/python3.8/site-packages/bentoml/_internal/store.py", line 108, in _recreate_latest
    raise NotFound(
bentoml.exceptions.NotFound: no Models with name 'pik_recommender_model' exist in BentoML store <osfs '/home/airflow/bentoml/models'>
[2023-01-19T04:10:40.829+0000] {processor.py:770} WARNING - No viable dags retrieved from /opt/airflow/dags/bentoml/pik_rec_bento/bento_service_pik_rec.py
[2023-01-19T04:10:40.841+0000] {processor.py:178} INFO - Processing /opt/airflow/dags/bentoml/pik_rec_bento/bento_service_pik_rec.py took 2.209 seconds
[2023-01-19T04:11:11.310+0000] {processor.py:156} INFO - Started process (PID=3945) to work on /opt/airflow/dags/bentoml/pik_rec_bento/bento_service_pik_rec.py
[2023-01-19T04:11:11.311+0000] {processor.py:758} INFO - Processing file /opt/airflow/dags/bentoml/pik_rec_bento/bento_service_pik_rec.py for tasks to queue
[2023-01-19T04:11:11.312+0000] {logging_mixin.py:117} INFO - [2023-01-19T04:11:11.311+0000] {dagbag.py:525} INFO - Filling up the DagBag from /opt/airflow/dags/bentoml/pik_rec_bento/bento_service_pik_rec.py
[2023-01-19T04:11:13.483+0000] {logging_mixin.py:117} INFO - [2023-01-19T04:11:13.480+0000] {dagbag.py:330} ERROR - Failed to import: /opt/airflow/dags/bentoml/pik_rec_bento/bento_service_pik_rec.py
Traceback (most recent call last):
  File "/home/airflow/.local/lib/python3.8/site-packages/fs/osfs.py", line 647, in open
    return io.open(
FileNotFoundError: [Errno 2] No such file or directory: b'/home/airflow/bentoml/models/pik_recommender_model/latest'

During handling of the above exception, another exception occurred:

Traceback (most recent call last):
  File "/home/airflow/.local/lib/python3.8/site-packages/bentoml/_internal/store.py", line 132, in get
    _tag.version = self._fs.readtext(_tag.latest_path())
  File "/home/airflow/.local/lib/python3.8/site-packages/fs/base.py", line 693, in readtext
    self.open(
  File "/home/airflow/.local/lib/python3.8/site-packages/fs/osfs.py", line 647, in open
    return io.open(
  File "/home/airflow/.local/lib/python3.8/site-packages/fs/error_tools.py", line 89, in __exit__
    reraise(fserror, fserror(self._path, exc=exc_value), traceback)
  File "/home/airflow/.local/lib/python3.8/site-packages/six.py", line 718, in reraise
    raise value.with_traceback(tb)
  File "/home/airflow/.local/lib/python3.8/site-packages/fs/osfs.py", line 647, in open
    return io.open(
fs.errors.ResourceNotFound: resource 'pik_recommender_model/latest' not found

During handling of the above exception, another exception occurred:

Traceback (most recent call last):
  File "/home/airflow/.local/lib/python3.8/site-packages/bentoml/_internal/store.py", line 106, in _recreate_latest
    items = self.list(tag.name)
  File "/home/airflow/.local/lib/python3.8/site-packages/bentoml/_internal/store.py", line 83, in list
    raise NotFound(
bentoml.exceptions.NotFound: no Models with name 'pik_recommender_model' found

During handling of the above exception, another exception occurred:

Traceback (most recent call last):
  File "/home/airflow/.local/lib/python3.8/site-packages/airflow/models/dagbag.py", line 326, in parse
    loader.exec_module(new_module)
  File "<frozen importlib._bootstrap_external>", line 843, in exec_module
  File "<frozen importlib._bootstrap>", line 219, in _call_with_frames_removed
  File "/opt/airflow/dags/bentoml/pik_rec_bento/bento_service_pik_rec.py", line 31, in <module>
    runner = bentoml.transformers.get("pik_recommender_model:latest").to_runner()
  File "/home/airflow/.local/lib/python3.8/site-packages/bentoml/_internal/frameworks/transformers.py", line 151, in get
    model = bentoml.models.get(tag_like)
  File "/home/airflow/.local/lib/python3.8/site-packages/simple_di/__init__.py", line 139, in _
    return func(*_inject_args(bind.args), **_inject_kwargs(bind.kwargs))
  File "/home/airflow/.local/lib/python3.8/site-packages/bentoml/models.py", line 41, in get
    return _model_store.get(tag)
  File "/home/airflow/.local/lib/python3.8/site-packages/bentoml/_internal/store.py", line 137, in get
    self._recreate_latest(_tag)
  File "/home/airflow/.local/lib/python3.8/site-packages/bentoml/_internal/store.py", line 108, in _recreate_latest
    raise NotFound(
bentoml.exceptions.NotFound: no Models with name 'pik_recommender_model' exist in BentoML store <osfs '/home/airflow/bentoml/models'>
[2023-01-19T04:11:13.483+0000] {processor.py:770} WARNING - No viable dags retrieved from /opt/airflow/dags/bentoml/pik_rec_bento/bento_service_pik_rec.py
[2023-01-19T04:11:13.498+0000] {processor.py:178} INFO - Processing /opt/airflow/dags/bentoml/pik_rec_bento/bento_service_pik_rec.py took 2.190 seconds
[2023-01-19T04:11:44.189+0000] {processor.py:156} INFO - Started process (PID=4003) to work on /opt/airflow/dags/bentoml/pik_rec_bento/bento_service_pik_rec.py
[2023-01-19T04:11:44.190+0000] {processor.py:758} INFO - Processing file /opt/airflow/dags/bentoml/pik_rec_bento/bento_service_pik_rec.py for tasks to queue
[2023-01-19T04:11:44.191+0000] {logging_mixin.py:117} INFO - [2023-01-19T04:11:44.190+0000] {dagbag.py:525} INFO - Filling up the DagBag from /opt/airflow/dags/bentoml/pik_rec_bento/bento_service_pik_rec.py
[2023-01-19T04:11:46.461+0000] {logging_mixin.py:117} INFO - [2023-01-19T04:11:46.459+0000] {dagbag.py:330} ERROR - Failed to import: /opt/airflow/dags/bentoml/pik_rec_bento/bento_service_pik_rec.py
Traceback (most recent call last):
  File "/home/airflow/.local/lib/python3.8/site-packages/fs/osfs.py", line 647, in open
    return io.open(
FileNotFoundError: [Errno 2] No such file or directory: b'/home/airflow/bentoml/models/pik_recommender_model/latest'

During handling of the above exception, another exception occurred:

Traceback (most recent call last):
  File "/home/airflow/.local/lib/python3.8/site-packages/bentoml/_internal/store.py", line 132, in get
    _tag.version = self._fs.readtext(_tag.latest_path())
  File "/home/airflow/.local/lib/python3.8/site-packages/fs/base.py", line 693, in readtext
    self.open(
  File "/home/airflow/.local/lib/python3.8/site-packages/fs/osfs.py", line 647, in open
    return io.open(
  File "/home/airflow/.local/lib/python3.8/site-packages/fs/error_tools.py", line 89, in __exit__
    reraise(fserror, fserror(self._path, exc=exc_value), traceback)
  File "/home/airflow/.local/lib/python3.8/site-packages/six.py", line 718, in reraise
    raise value.with_traceback(tb)
  File "/home/airflow/.local/lib/python3.8/site-packages/fs/osfs.py", line 647, in open
    return io.open(
fs.errors.ResourceNotFound: resource 'pik_recommender_model/latest' not found

During handling of the above exception, another exception occurred:

Traceback (most recent call last):
  File "/home/airflow/.local/lib/python3.8/site-packages/bentoml/_internal/store.py", line 106, in _recreate_latest
    items = self.list(tag.name)
  File "/home/airflow/.local/lib/python3.8/site-packages/bentoml/_internal/store.py", line 83, in list
    raise NotFound(
bentoml.exceptions.NotFound: no Models with name 'pik_recommender_model' found

During handling of the above exception, another exception occurred:

Traceback (most recent call last):
  File "/home/airflow/.local/lib/python3.8/site-packages/airflow/models/dagbag.py", line 326, in parse
    loader.exec_module(new_module)
  File "<frozen importlib._bootstrap_external>", line 843, in exec_module
  File "<frozen importlib._bootstrap>", line 219, in _call_with_frames_removed
  File "/opt/airflow/dags/bentoml/pik_rec_bento/bento_service_pik_rec.py", line 31, in <module>
    runner = bentoml.transformers.get("pik_recommender_model:latest").to_runner()
  File "/home/airflow/.local/lib/python3.8/site-packages/bentoml/_internal/frameworks/transformers.py", line 151, in get
    model = bentoml.models.get(tag_like)
  File "/home/airflow/.local/lib/python3.8/site-packages/simple_di/__init__.py", line 139, in _
    return func(*_inject_args(bind.args), **_inject_kwargs(bind.kwargs))
  File "/home/airflow/.local/lib/python3.8/site-packages/bentoml/models.py", line 41, in get
    return _model_store.get(tag)
  File "/home/airflow/.local/lib/python3.8/site-packages/bentoml/_internal/store.py", line 137, in get
    self._recreate_latest(_tag)
  File "/home/airflow/.local/lib/python3.8/site-packages/bentoml/_internal/store.py", line 108, in _recreate_latest
    raise NotFound(
bentoml.exceptions.NotFound: no Models with name 'pik_recommender_model' exist in BentoML store <osfs '/home/airflow/bentoml/models'>
[2023-01-19T04:11:46.461+0000] {processor.py:770} WARNING - No viable dags retrieved from /opt/airflow/dags/bentoml/pik_rec_bento/bento_service_pik_rec.py
[2023-01-19T04:11:46.474+0000] {processor.py:178} INFO - Processing /opt/airflow/dags/bentoml/pik_rec_bento/bento_service_pik_rec.py took 2.288 seconds
[2023-01-19T04:12:16.753+0000] {processor.py:156} INFO - Started process (PID=4060) to work on /opt/airflow/dags/bentoml/pik_rec_bento/bento_service_pik_rec.py
[2023-01-19T04:12:16.754+0000] {processor.py:758} INFO - Processing file /opt/airflow/dags/bentoml/pik_rec_bento/bento_service_pik_rec.py for tasks to queue
[2023-01-19T04:12:16.754+0000] {logging_mixin.py:117} INFO - [2023-01-19T04:12:16.754+0000] {dagbag.py:525} INFO - Filling up the DagBag from /opt/airflow/dags/bentoml/pik_rec_bento/bento_service_pik_rec.py
[2023-01-19T04:12:18.938+0000] {logging_mixin.py:117} INFO - [2023-01-19T04:12:18.936+0000] {dagbag.py:330} ERROR - Failed to import: /opt/airflow/dags/bentoml/pik_rec_bento/bento_service_pik_rec.py
Traceback (most recent call last):
  File "/home/airflow/.local/lib/python3.8/site-packages/fs/osfs.py", line 647, in open
    return io.open(
FileNotFoundError: [Errno 2] No such file or directory: b'/home/airflow/bentoml/models/pik_recommender_model/latest'

During handling of the above exception, another exception occurred:

Traceback (most recent call last):
  File "/home/airflow/.local/lib/python3.8/site-packages/bentoml/_internal/store.py", line 132, in get
    _tag.version = self._fs.readtext(_tag.latest_path())
  File "/home/airflow/.local/lib/python3.8/site-packages/fs/base.py", line 693, in readtext
    self.open(
  File "/home/airflow/.local/lib/python3.8/site-packages/fs/osfs.py", line 647, in open
    return io.open(
  File "/home/airflow/.local/lib/python3.8/site-packages/fs/error_tools.py", line 89, in __exit__
    reraise(fserror, fserror(self._path, exc=exc_value), traceback)
  File "/home/airflow/.local/lib/python3.8/site-packages/six.py", line 718, in reraise
    raise value.with_traceback(tb)
  File "/home/airflow/.local/lib/python3.8/site-packages/fs/osfs.py", line 647, in open
    return io.open(
fs.errors.ResourceNotFound: resource 'pik_recommender_model/latest' not found

During handling of the above exception, another exception occurred:

Traceback (most recent call last):
  File "/home/airflow/.local/lib/python3.8/site-packages/bentoml/_internal/store.py", line 106, in _recreate_latest
    items = self.list(tag.name)
  File "/home/airflow/.local/lib/python3.8/site-packages/bentoml/_internal/store.py", line 83, in list
    raise NotFound(
bentoml.exceptions.NotFound: no Models with name 'pik_recommender_model' found

During handling of the above exception, another exception occurred:

Traceback (most recent call last):
  File "/home/airflow/.local/lib/python3.8/site-packages/airflow/models/dagbag.py", line 326, in parse
    loader.exec_module(new_module)
  File "<frozen importlib._bootstrap_external>", line 843, in exec_module
  File "<frozen importlib._bootstrap>", line 219, in _call_with_frames_removed
  File "/opt/airflow/dags/bentoml/pik_rec_bento/bento_service_pik_rec.py", line 31, in <module>
    runner = bentoml.transformers.get("pik_recommender_model:latest").to_runner()
  File "/home/airflow/.local/lib/python3.8/site-packages/bentoml/_internal/frameworks/transformers.py", line 151, in get
    model = bentoml.models.get(tag_like)
  File "/home/airflow/.local/lib/python3.8/site-packages/simple_di/__init__.py", line 139, in _
    return func(*_inject_args(bind.args), **_inject_kwargs(bind.kwargs))
  File "/home/airflow/.local/lib/python3.8/site-packages/bentoml/models.py", line 41, in get
    return _model_store.get(tag)
  File "/home/airflow/.local/lib/python3.8/site-packages/bentoml/_internal/store.py", line 137, in get
    self._recreate_latest(_tag)
  File "/home/airflow/.local/lib/python3.8/site-packages/bentoml/_internal/store.py", line 108, in _recreate_latest
    raise NotFound(
bentoml.exceptions.NotFound: no Models with name 'pik_recommender_model' exist in BentoML store <osfs '/home/airflow/bentoml/models'>
[2023-01-19T04:12:18.938+0000] {processor.py:770} WARNING - No viable dags retrieved from /opt/airflow/dags/bentoml/pik_rec_bento/bento_service_pik_rec.py
[2023-01-19T04:12:18.950+0000] {processor.py:178} INFO - Processing /opt/airflow/dags/bentoml/pik_rec_bento/bento_service_pik_rec.py took 2.201 seconds
[2023-01-19T04:12:49.269+0000] {processor.py:156} INFO - Started process (PID=4119) to work on /opt/airflow/dags/bentoml/pik_rec_bento/bento_service_pik_rec.py
[2023-01-19T04:12:49.270+0000] {processor.py:758} INFO - Processing file /opt/airflow/dags/bentoml/pik_rec_bento/bento_service_pik_rec.py for tasks to queue
[2023-01-19T04:12:49.271+0000] {logging_mixin.py:117} INFO - [2023-01-19T04:12:49.270+0000] {dagbag.py:525} INFO - Filling up the DagBag from /opt/airflow/dags/bentoml/pik_rec_bento/bento_service_pik_rec.py
[2023-01-19T04:12:51.465+0000] {logging_mixin.py:117} INFO - [2023-01-19T04:12:51.463+0000] {dagbag.py:330} ERROR - Failed to import: /opt/airflow/dags/bentoml/pik_rec_bento/bento_service_pik_rec.py
Traceback (most recent call last):
  File "/home/airflow/.local/lib/python3.8/site-packages/fs/osfs.py", line 647, in open
    return io.open(
FileNotFoundError: [Errno 2] No such file or directory: b'/home/airflow/bentoml/models/pik_recommender_model/latest'

During handling of the above exception, another exception occurred:

Traceback (most recent call last):
  File "/home/airflow/.local/lib/python3.8/site-packages/bentoml/_internal/store.py", line 132, in get
    _tag.version = self._fs.readtext(_tag.latest_path())
  File "/home/airflow/.local/lib/python3.8/site-packages/fs/base.py", line 693, in readtext
    self.open(
  File "/home/airflow/.local/lib/python3.8/site-packages/fs/osfs.py", line 647, in open
    return io.open(
  File "/home/airflow/.local/lib/python3.8/site-packages/fs/error_tools.py", line 89, in __exit__
    reraise(fserror, fserror(self._path, exc=exc_value), traceback)
  File "/home/airflow/.local/lib/python3.8/site-packages/six.py", line 718, in reraise
    raise value.with_traceback(tb)
  File "/home/airflow/.local/lib/python3.8/site-packages/fs/osfs.py", line 647, in open
    return io.open(
fs.errors.ResourceNotFound: resource 'pik_recommender_model/latest' not found

During handling of the above exception, another exception occurred:

Traceback (most recent call last):
  File "/home/airflow/.local/lib/python3.8/site-packages/bentoml/_internal/store.py", line 106, in _recreate_latest
    items = self.list(tag.name)
  File "/home/airflow/.local/lib/python3.8/site-packages/bentoml/_internal/store.py", line 83, in list
    raise NotFound(
bentoml.exceptions.NotFound: no Models with name 'pik_recommender_model' found

During handling of the above exception, another exception occurred:

Traceback (most recent call last):
  File "/home/airflow/.local/lib/python3.8/site-packages/airflow/models/dagbag.py", line 326, in parse
    loader.exec_module(new_module)
  File "<frozen importlib._bootstrap_external>", line 843, in exec_module
  File "<frozen importlib._bootstrap>", line 219, in _call_with_frames_removed
  File "/opt/airflow/dags/bentoml/pik_rec_bento/bento_service_pik_rec.py", line 31, in <module>
    runner = bentoml.transformers.get("pik_recommender_model:latest").to_runner()
  File "/home/airflow/.local/lib/python3.8/site-packages/bentoml/_internal/frameworks/transformers.py", line 151, in get
    model = bentoml.models.get(tag_like)
  File "/home/airflow/.local/lib/python3.8/site-packages/simple_di/__init__.py", line 139, in _
    return func(*_inject_args(bind.args), **_inject_kwargs(bind.kwargs))
  File "/home/airflow/.local/lib/python3.8/site-packages/bentoml/models.py", line 41, in get
    return _model_store.get(tag)
  File "/home/airflow/.local/lib/python3.8/site-packages/bentoml/_internal/store.py", line 137, in get
    self._recreate_latest(_tag)
  File "/home/airflow/.local/lib/python3.8/site-packages/bentoml/_internal/store.py", line 108, in _recreate_latest
    raise NotFound(
bentoml.exceptions.NotFound: no Models with name 'pik_recommender_model' exist in BentoML store <osfs '/home/airflow/bentoml/models'>
[2023-01-19T04:12:51.465+0000] {processor.py:770} WARNING - No viable dags retrieved from /opt/airflow/dags/bentoml/pik_rec_bento/bento_service_pik_rec.py
[2023-01-19T04:12:51.478+0000] {processor.py:178} INFO - Processing /opt/airflow/dags/bentoml/pik_rec_bento/bento_service_pik_rec.py took 2.211 seconds
[2023-01-19T04:13:22.183+0000] {processor.py:156} INFO - Started process (PID=4177) to work on /opt/airflow/dags/bentoml/pik_rec_bento/bento_service_pik_rec.py
[2023-01-19T04:13:22.184+0000] {processor.py:758} INFO - Processing file /opt/airflow/dags/bentoml/pik_rec_bento/bento_service_pik_rec.py for tasks to queue
[2023-01-19T04:13:22.184+0000] {logging_mixin.py:117} INFO - [2023-01-19T04:13:22.184+0000] {dagbag.py:525} INFO - Filling up the DagBag from /opt/airflow/dags/bentoml/pik_rec_bento/bento_service_pik_rec.py
[2023-01-19T04:13:24.338+0000] {logging_mixin.py:117} INFO - [2023-01-19T04:13:24.336+0000] {dagbag.py:330} ERROR - Failed to import: /opt/airflow/dags/bentoml/pik_rec_bento/bento_service_pik_rec.py
Traceback (most recent call last):
  File "/home/airflow/.local/lib/python3.8/site-packages/fs/osfs.py", line 647, in open
    return io.open(
FileNotFoundError: [Errno 2] No such file or directory: b'/home/airflow/bentoml/models/pik_recommender_model/latest'

During handling of the above exception, another exception occurred:

Traceback (most recent call last):
  File "/home/airflow/.local/lib/python3.8/site-packages/bentoml/_internal/store.py", line 132, in get
    _tag.version = self._fs.readtext(_tag.latest_path())
  File "/home/airflow/.local/lib/python3.8/site-packages/fs/base.py", line 693, in readtext
    self.open(
  File "/home/airflow/.local/lib/python3.8/site-packages/fs/osfs.py", line 647, in open
    return io.open(
  File "/home/airflow/.local/lib/python3.8/site-packages/fs/error_tools.py", line 89, in __exit__
    reraise(fserror, fserror(self._path, exc=exc_value), traceback)
  File "/home/airflow/.local/lib/python3.8/site-packages/six.py", line 718, in reraise
    raise value.with_traceback(tb)
  File "/home/airflow/.local/lib/python3.8/site-packages/fs/osfs.py", line 647, in open
    return io.open(
fs.errors.ResourceNotFound: resource 'pik_recommender_model/latest' not found

During handling of the above exception, another exception occurred:

Traceback (most recent call last):
  File "/home/airflow/.local/lib/python3.8/site-packages/bentoml/_internal/store.py", line 106, in _recreate_latest
    items = self.list(tag.name)
  File "/home/airflow/.local/lib/python3.8/site-packages/bentoml/_internal/store.py", line 83, in list
    raise NotFound(
bentoml.exceptions.NotFound: no Models with name 'pik_recommender_model' found

During handling of the above exception, another exception occurred:

Traceback (most recent call last):
  File "/home/airflow/.local/lib/python3.8/site-packages/airflow/models/dagbag.py", line 326, in parse
    loader.exec_module(new_module)
  File "<frozen importlib._bootstrap_external>", line 843, in exec_module
  File "<frozen importlib._bootstrap>", line 219, in _call_with_frames_removed
  File "/opt/airflow/dags/bentoml/pik_rec_bento/bento_service_pik_rec.py", line 31, in <module>
    runner = bentoml.transformers.get("pik_recommender_model:latest").to_runner()
  File "/home/airflow/.local/lib/python3.8/site-packages/bentoml/_internal/frameworks/transformers.py", line 151, in get
    model = bentoml.models.get(tag_like)
  File "/home/airflow/.local/lib/python3.8/site-packages/simple_di/__init__.py", line 139, in _
    return func(*_inject_args(bind.args), **_inject_kwargs(bind.kwargs))
  File "/home/airflow/.local/lib/python3.8/site-packages/bentoml/models.py", line 41, in get
    return _model_store.get(tag)
  File "/home/airflow/.local/lib/python3.8/site-packages/bentoml/_internal/store.py", line 137, in get
    self._recreate_latest(_tag)
  File "/home/airflow/.local/lib/python3.8/site-packages/bentoml/_internal/store.py", line 108, in _recreate_latest
    raise NotFound(
bentoml.exceptions.NotFound: no Models with name 'pik_recommender_model' exist in BentoML store <osfs '/home/airflow/bentoml/models'>
[2023-01-19T04:13:24.339+0000] {processor.py:770} WARNING - No viable dags retrieved from /opt/airflow/dags/bentoml/pik_rec_bento/bento_service_pik_rec.py
[2023-01-19T04:13:24.351+0000] {processor.py:178} INFO - Processing /opt/airflow/dags/bentoml/pik_rec_bento/bento_service_pik_rec.py took 2.171 seconds
[2023-01-19T04:13:54.418+0000] {processor.py:156} INFO - Started process (PID=4235) to work on /opt/airflow/dags/bentoml/pik_rec_bento/bento_service_pik_rec.py
[2023-01-19T04:13:54.419+0000] {processor.py:758} INFO - Processing file /opt/airflow/dags/bentoml/pik_rec_bento/bento_service_pik_rec.py for tasks to queue
[2023-01-19T04:13:54.420+0000] {logging_mixin.py:117} INFO - [2023-01-19T04:13:54.420+0000] {dagbag.py:525} INFO - Filling up the DagBag from /opt/airflow/dags/bentoml/pik_rec_bento/bento_service_pik_rec.py
[2023-01-19T04:13:56.584+0000] {logging_mixin.py:117} INFO - [2023-01-19T04:13:56.582+0000] {dagbag.py:330} ERROR - Failed to import: /opt/airflow/dags/bentoml/pik_rec_bento/bento_service_pik_rec.py
Traceback (most recent call last):
  File "/home/airflow/.local/lib/python3.8/site-packages/fs/osfs.py", line 647, in open
    return io.open(
FileNotFoundError: [Errno 2] No such file or directory: b'/home/airflow/bentoml/models/pik_recommender_model/latest'

During handling of the above exception, another exception occurred:

Traceback (most recent call last):
  File "/home/airflow/.local/lib/python3.8/site-packages/bentoml/_internal/store.py", line 132, in get
    _tag.version = self._fs.readtext(_tag.latest_path())
  File "/home/airflow/.local/lib/python3.8/site-packages/fs/base.py", line 693, in readtext
    self.open(
  File "/home/airflow/.local/lib/python3.8/site-packages/fs/osfs.py", line 647, in open
    return io.open(
  File "/home/airflow/.local/lib/python3.8/site-packages/fs/error_tools.py", line 89, in __exit__
    reraise(fserror, fserror(self._path, exc=exc_value), traceback)
  File "/home/airflow/.local/lib/python3.8/site-packages/six.py", line 718, in reraise
    raise value.with_traceback(tb)
  File "/home/airflow/.local/lib/python3.8/site-packages/fs/osfs.py", line 647, in open
    return io.open(
fs.errors.ResourceNotFound: resource 'pik_recommender_model/latest' not found

During handling of the above exception, another exception occurred:

Traceback (most recent call last):
  File "/home/airflow/.local/lib/python3.8/site-packages/bentoml/_internal/store.py", line 106, in _recreate_latest
    items = self.list(tag.name)
  File "/home/airflow/.local/lib/python3.8/site-packages/bentoml/_internal/store.py", line 83, in list
    raise NotFound(
bentoml.exceptions.NotFound: no Models with name 'pik_recommender_model' found

During handling of the above exception, another exception occurred:

Traceback (most recent call last):
  File "/home/airflow/.local/lib/python3.8/site-packages/airflow/models/dagbag.py", line 326, in parse
    loader.exec_module(new_module)
  File "<frozen importlib._bootstrap_external>", line 843, in exec_module
  File "<frozen importlib._bootstrap>", line 219, in _call_with_frames_removed
  File "/opt/airflow/dags/bentoml/pik_rec_bento/bento_service_pik_rec.py", line 31, in <module>
    runner = bentoml.transformers.get("pik_recommender_model:latest").to_runner()
  File "/home/airflow/.local/lib/python3.8/site-packages/bentoml/_internal/frameworks/transformers.py", line 151, in get
    model = bentoml.models.get(tag_like)
  File "/home/airflow/.local/lib/python3.8/site-packages/simple_di/__init__.py", line 139, in _
    return func(*_inject_args(bind.args), **_inject_kwargs(bind.kwargs))
  File "/home/airflow/.local/lib/python3.8/site-packages/bentoml/models.py", line 41, in get
    return _model_store.get(tag)
  File "/home/airflow/.local/lib/python3.8/site-packages/bentoml/_internal/store.py", line 137, in get
    self._recreate_latest(_tag)
  File "/home/airflow/.local/lib/python3.8/site-packages/bentoml/_internal/store.py", line 108, in _recreate_latest
    raise NotFound(
bentoml.exceptions.NotFound: no Models with name 'pik_recommender_model' exist in BentoML store <osfs '/home/airflow/bentoml/models'>
[2023-01-19T04:13:56.585+0000] {processor.py:770} WARNING - No viable dags retrieved from /opt/airflow/dags/bentoml/pik_rec_bento/bento_service_pik_rec.py
[2023-01-19T04:13:56.597+0000] {processor.py:178} INFO - Processing /opt/airflow/dags/bentoml/pik_rec_bento/bento_service_pik_rec.py took 2.182 seconds
[2023-01-19T04:14:27.185+0000] {processor.py:156} INFO - Started process (PID=4292) to work on /opt/airflow/dags/bentoml/pik_rec_bento/bento_service_pik_rec.py
[2023-01-19T04:14:27.185+0000] {processor.py:758} INFO - Processing file /opt/airflow/dags/bentoml/pik_rec_bento/bento_service_pik_rec.py for tasks to queue
[2023-01-19T04:14:27.186+0000] {logging_mixin.py:117} INFO - [2023-01-19T04:14:27.186+0000] {dagbag.py:525} INFO - Filling up the DagBag from /opt/airflow/dags/bentoml/pik_rec_bento/bento_service_pik_rec.py
[2023-01-19T04:14:29.557+0000] {logging_mixin.py:117} INFO - [2023-01-19T04:14:29.555+0000] {dagbag.py:330} ERROR - Failed to import: /opt/airflow/dags/bentoml/pik_rec_bento/bento_service_pik_rec.py
Traceback (most recent call last):
  File "/home/airflow/.local/lib/python3.8/site-packages/fs/osfs.py", line 647, in open
    return io.open(
FileNotFoundError: [Errno 2] No such file or directory: b'/home/airflow/bentoml/models/pik_recommender_model/latest'

During handling of the above exception, another exception occurred:

Traceback (most recent call last):
  File "/home/airflow/.local/lib/python3.8/site-packages/bentoml/_internal/store.py", line 132, in get
    _tag.version = self._fs.readtext(_tag.latest_path())
  File "/home/airflow/.local/lib/python3.8/site-packages/fs/base.py", line 693, in readtext
    self.open(
  File "/home/airflow/.local/lib/python3.8/site-packages/fs/osfs.py", line 647, in open
    return io.open(
  File "/home/airflow/.local/lib/python3.8/site-packages/fs/error_tools.py", line 89, in __exit__
    reraise(fserror, fserror(self._path, exc=exc_value), traceback)
  File "/home/airflow/.local/lib/python3.8/site-packages/six.py", line 718, in reraise
    raise value.with_traceback(tb)
  File "/home/airflow/.local/lib/python3.8/site-packages/fs/osfs.py", line 647, in open
    return io.open(
fs.errors.ResourceNotFound: resource 'pik_recommender_model/latest' not found

During handling of the above exception, another exception occurred:

Traceback (most recent call last):
  File "/home/airflow/.local/lib/python3.8/site-packages/bentoml/_internal/store.py", line 106, in _recreate_latest
    items = self.list(tag.name)
  File "/home/airflow/.local/lib/python3.8/site-packages/bentoml/_internal/store.py", line 83, in list
    raise NotFound(
bentoml.exceptions.NotFound: no Models with name 'pik_recommender_model' found

During handling of the above exception, another exception occurred:

Traceback (most recent call last):
  File "/home/airflow/.local/lib/python3.8/site-packages/airflow/models/dagbag.py", line 326, in parse
    loader.exec_module(new_module)
  File "<frozen importlib._bootstrap_external>", line 843, in exec_module
  File "<frozen importlib._bootstrap>", line 219, in _call_with_frames_removed
  File "/opt/airflow/dags/bentoml/pik_rec_bento/bento_service_pik_rec.py", line 31, in <module>
    runner = bentoml.transformers.get("pik_recommender_model:latest").to_runner()
  File "/home/airflow/.local/lib/python3.8/site-packages/bentoml/_internal/frameworks/transformers.py", line 151, in get
    model = bentoml.models.get(tag_like)
  File "/home/airflow/.local/lib/python3.8/site-packages/simple_di/__init__.py", line 139, in _
    return func(*_inject_args(bind.args), **_inject_kwargs(bind.kwargs))
  File "/home/airflow/.local/lib/python3.8/site-packages/bentoml/models.py", line 41, in get
    return _model_store.get(tag)
  File "/home/airflow/.local/lib/python3.8/site-packages/bentoml/_internal/store.py", line 137, in get
    self._recreate_latest(_tag)
  File "/home/airflow/.local/lib/python3.8/site-packages/bentoml/_internal/store.py", line 108, in _recreate_latest
    raise NotFound(
bentoml.exceptions.NotFound: no Models with name 'pik_recommender_model' exist in BentoML store <osfs '/home/airflow/bentoml/models'>
[2023-01-19T04:14:29.558+0000] {processor.py:770} WARNING - No viable dags retrieved from /opt/airflow/dags/bentoml/pik_rec_bento/bento_service_pik_rec.py
[2023-01-19T04:14:29.571+0000] {processor.py:178} INFO - Processing /opt/airflow/dags/bentoml/pik_rec_bento/bento_service_pik_rec.py took 2.389 seconds
[2023-01-19T04:15:00.051+0000] {processor.py:156} INFO - Started process (PID=4350) to work on /opt/airflow/dags/bentoml/pik_rec_bento/bento_service_pik_rec.py
[2023-01-19T04:15:00.052+0000] {processor.py:758} INFO - Processing file /opt/airflow/dags/bentoml/pik_rec_bento/bento_service_pik_rec.py for tasks to queue
[2023-01-19T04:15:00.053+0000] {logging_mixin.py:117} INFO - [2023-01-19T04:15:00.053+0000] {dagbag.py:525} INFO - Filling up the DagBag from /opt/airflow/dags/bentoml/pik_rec_bento/bento_service_pik_rec.py
[2023-01-19T04:15:02.428+0000] {logging_mixin.py:117} INFO - [2023-01-19T04:15:02.425+0000] {dagbag.py:330} ERROR - Failed to import: /opt/airflow/dags/bentoml/pik_rec_bento/bento_service_pik_rec.py
Traceback (most recent call last):
  File "/home/airflow/.local/lib/python3.8/site-packages/fs/osfs.py", line 647, in open
    return io.open(
FileNotFoundError: [Errno 2] No such file or directory: b'/home/airflow/bentoml/models/pik_recommender_model/latest'

During handling of the above exception, another exception occurred:

Traceback (most recent call last):
  File "/home/airflow/.local/lib/python3.8/site-packages/bentoml/_internal/store.py", line 132, in get
    _tag.version = self._fs.readtext(_tag.latest_path())
  File "/home/airflow/.local/lib/python3.8/site-packages/fs/base.py", line 693, in readtext
    self.open(
  File "/home/airflow/.local/lib/python3.8/site-packages/fs/osfs.py", line 647, in open
    return io.open(
  File "/home/airflow/.local/lib/python3.8/site-packages/fs/error_tools.py", line 89, in __exit__
    reraise(fserror, fserror(self._path, exc=exc_value), traceback)
  File "/home/airflow/.local/lib/python3.8/site-packages/six.py", line 718, in reraise
    raise value.with_traceback(tb)
  File "/home/airflow/.local/lib/python3.8/site-packages/fs/osfs.py", line 647, in open
    return io.open(
fs.errors.ResourceNotFound: resource 'pik_recommender_model/latest' not found

During handling of the above exception, another exception occurred:

Traceback (most recent call last):
  File "/home/airflow/.local/lib/python3.8/site-packages/bentoml/_internal/store.py", line 106, in _recreate_latest
    items = self.list(tag.name)
  File "/home/airflow/.local/lib/python3.8/site-packages/bentoml/_internal/store.py", line 83, in list
    raise NotFound(
bentoml.exceptions.NotFound: no Models with name 'pik_recommender_model' found

During handling of the above exception, another exception occurred:

Traceback (most recent call last):
  File "/home/airflow/.local/lib/python3.8/site-packages/airflow/models/dagbag.py", line 326, in parse
    loader.exec_module(new_module)
  File "<frozen importlib._bootstrap_external>", line 843, in exec_module
  File "<frozen importlib._bootstrap>", line 219, in _call_with_frames_removed
  File "/opt/airflow/dags/bentoml/pik_rec_bento/bento_service_pik_rec.py", line 31, in <module>
    runner = bentoml.transformers.get("pik_recommender_model:latest").to_runner()
  File "/home/airflow/.local/lib/python3.8/site-packages/bentoml/_internal/frameworks/transformers.py", line 151, in get
    model = bentoml.models.get(tag_like)
  File "/home/airflow/.local/lib/python3.8/site-packages/simple_di/__init__.py", line 139, in _
    return func(*_inject_args(bind.args), **_inject_kwargs(bind.kwargs))
  File "/home/airflow/.local/lib/python3.8/site-packages/bentoml/models.py", line 41, in get
    return _model_store.get(tag)
  File "/home/airflow/.local/lib/python3.8/site-packages/bentoml/_internal/store.py", line 137, in get
    self._recreate_latest(_tag)
  File "/home/airflow/.local/lib/python3.8/site-packages/bentoml/_internal/store.py", line 108, in _recreate_latest
    raise NotFound(
bentoml.exceptions.NotFound: no Models with name 'pik_recommender_model' exist in BentoML store <osfs '/home/airflow/bentoml/models'>
[2023-01-19T04:15:02.428+0000] {processor.py:770} WARNING - No viable dags retrieved from /opt/airflow/dags/bentoml/pik_rec_bento/bento_service_pik_rec.py
[2023-01-19T04:15:02.441+0000] {processor.py:178} INFO - Processing /opt/airflow/dags/bentoml/pik_rec_bento/bento_service_pik_rec.py took 2.394 seconds
[2023-01-19T04:15:32.545+0000] {processor.py:156} INFO - Started process (PID=4409) to work on /opt/airflow/dags/bentoml/pik_rec_bento/bento_service_pik_rec.py
[2023-01-19T04:15:32.546+0000] {processor.py:758} INFO - Processing file /opt/airflow/dags/bentoml/pik_rec_bento/bento_service_pik_rec.py for tasks to queue
[2023-01-19T04:15:32.547+0000] {logging_mixin.py:117} INFO - [2023-01-19T04:15:32.547+0000] {dagbag.py:525} INFO - Filling up the DagBag from /opt/airflow/dags/bentoml/pik_rec_bento/bento_service_pik_rec.py
[2023-01-19T04:15:34.723+0000] {logging_mixin.py:117} INFO - [2023-01-19T04:15:34.721+0000] {dagbag.py:330} ERROR - Failed to import: /opt/airflow/dags/bentoml/pik_rec_bento/bento_service_pik_rec.py
Traceback (most recent call last):
  File "/home/airflow/.local/lib/python3.8/site-packages/fs/osfs.py", line 647, in open
    return io.open(
FileNotFoundError: [Errno 2] No such file or directory: b'/home/airflow/bentoml/models/pik_recommender_model/latest'

During handling of the above exception, another exception occurred:

Traceback (most recent call last):
  File "/home/airflow/.local/lib/python3.8/site-packages/bentoml/_internal/store.py", line 132, in get
    _tag.version = self._fs.readtext(_tag.latest_path())
  File "/home/airflow/.local/lib/python3.8/site-packages/fs/base.py", line 693, in readtext
    self.open(
  File "/home/airflow/.local/lib/python3.8/site-packages/fs/osfs.py", line 647, in open
    return io.open(
  File "/home/airflow/.local/lib/python3.8/site-packages/fs/error_tools.py", line 89, in __exit__
    reraise(fserror, fserror(self._path, exc=exc_value), traceback)
  File "/home/airflow/.local/lib/python3.8/site-packages/six.py", line 718, in reraise
    raise value.with_traceback(tb)
  File "/home/airflow/.local/lib/python3.8/site-packages/fs/osfs.py", line 647, in open
    return io.open(
fs.errors.ResourceNotFound: resource 'pik_recommender_model/latest' not found

During handling of the above exception, another exception occurred:

Traceback (most recent call last):
  File "/home/airflow/.local/lib/python3.8/site-packages/bentoml/_internal/store.py", line 106, in _recreate_latest
    items = self.list(tag.name)
  File "/home/airflow/.local/lib/python3.8/site-packages/bentoml/_internal/store.py", line 83, in list
    raise NotFound(
bentoml.exceptions.NotFound: no Models with name 'pik_recommender_model' found

During handling of the above exception, another exception occurred:

Traceback (most recent call last):
  File "/home/airflow/.local/lib/python3.8/site-packages/airflow/models/dagbag.py", line 326, in parse
    loader.exec_module(new_module)
  File "<frozen importlib._bootstrap_external>", line 843, in exec_module
  File "<frozen importlib._bootstrap>", line 219, in _call_with_frames_removed
  File "/opt/airflow/dags/bentoml/pik_rec_bento/bento_service_pik_rec.py", line 31, in <module>
    runner = bentoml.transformers.get("pik_recommender_model:latest").to_runner()
  File "/home/airflow/.local/lib/python3.8/site-packages/bentoml/_internal/frameworks/transformers.py", line 151, in get
    model = bentoml.models.get(tag_like)
  File "/home/airflow/.local/lib/python3.8/site-packages/simple_di/__init__.py", line 139, in _
    return func(*_inject_args(bind.args), **_inject_kwargs(bind.kwargs))
  File "/home/airflow/.local/lib/python3.8/site-packages/bentoml/models.py", line 41, in get
    return _model_store.get(tag)
  File "/home/airflow/.local/lib/python3.8/site-packages/bentoml/_internal/store.py", line 137, in get
    self._recreate_latest(_tag)
  File "/home/airflow/.local/lib/python3.8/site-packages/bentoml/_internal/store.py", line 108, in _recreate_latest
    raise NotFound(
bentoml.exceptions.NotFound: no Models with name 'pik_recommender_model' exist in BentoML store <osfs '/home/airflow/bentoml/models'>
[2023-01-19T04:15:34.723+0000] {processor.py:770} WARNING - No viable dags retrieved from /opt/airflow/dags/bentoml/pik_rec_bento/bento_service_pik_rec.py
[2023-01-19T04:15:34.736+0000] {processor.py:178} INFO - Processing /opt/airflow/dags/bentoml/pik_rec_bento/bento_service_pik_rec.py took 2.194 seconds
[2023-01-19T04:16:04.945+0000] {processor.py:156} INFO - Started process (PID=4467) to work on /opt/airflow/dags/bentoml/pik_rec_bento/bento_service_pik_rec.py
[2023-01-19T04:16:04.946+0000] {processor.py:758} INFO - Processing file /opt/airflow/dags/bentoml/pik_rec_bento/bento_service_pik_rec.py for tasks to queue
[2023-01-19T04:16:04.947+0000] {logging_mixin.py:117} INFO - [2023-01-19T04:16:04.947+0000] {dagbag.py:525} INFO - Filling up the DagBag from /opt/airflow/dags/bentoml/pik_rec_bento/bento_service_pik_rec.py
[2023-01-19T04:16:07.153+0000] {logging_mixin.py:117} INFO - [2023-01-19T04:16:07.151+0000] {dagbag.py:330} ERROR - Failed to import: /opt/airflow/dags/bentoml/pik_rec_bento/bento_service_pik_rec.py
Traceback (most recent call last):
  File "/home/airflow/.local/lib/python3.8/site-packages/fs/osfs.py", line 647, in open
    return io.open(
FileNotFoundError: [Errno 2] No such file or directory: b'/home/airflow/bentoml/models/pik_recommender_model/latest'

During handling of the above exception, another exception occurred:

Traceback (most recent call last):
  File "/home/airflow/.local/lib/python3.8/site-packages/bentoml/_internal/store.py", line 132, in get
    _tag.version = self._fs.readtext(_tag.latest_path())
  File "/home/airflow/.local/lib/python3.8/site-packages/fs/base.py", line 693, in readtext
    self.open(
  File "/home/airflow/.local/lib/python3.8/site-packages/fs/osfs.py", line 647, in open
    return io.open(
  File "/home/airflow/.local/lib/python3.8/site-packages/fs/error_tools.py", line 89, in __exit__
    reraise(fserror, fserror(self._path, exc=exc_value), traceback)
  File "/home/airflow/.local/lib/python3.8/site-packages/six.py", line 718, in reraise
    raise value.with_traceback(tb)
  File "/home/airflow/.local/lib/python3.8/site-packages/fs/osfs.py", line 647, in open
    return io.open(
fs.errors.ResourceNotFound: resource 'pik_recommender_model/latest' not found

During handling of the above exception, another exception occurred:

Traceback (most recent call last):
  File "/home/airflow/.local/lib/python3.8/site-packages/bentoml/_internal/store.py", line 106, in _recreate_latest
    items = self.list(tag.name)
  File "/home/airflow/.local/lib/python3.8/site-packages/bentoml/_internal/store.py", line 83, in list
    raise NotFound(
bentoml.exceptions.NotFound: no Models with name 'pik_recommender_model' found

During handling of the above exception, another exception occurred:

Traceback (most recent call last):
  File "/home/airflow/.local/lib/python3.8/site-packages/airflow/models/dagbag.py", line 326, in parse
    loader.exec_module(new_module)
  File "<frozen importlib._bootstrap_external>", line 843, in exec_module
  File "<frozen importlib._bootstrap>", line 219, in _call_with_frames_removed
  File "/opt/airflow/dags/bentoml/pik_rec_bento/bento_service_pik_rec.py", line 31, in <module>
    runner = bentoml.transformers.get("pik_recommender_model:latest").to_runner()
  File "/home/airflow/.local/lib/python3.8/site-packages/bentoml/_internal/frameworks/transformers.py", line 151, in get
    model = bentoml.models.get(tag_like)
  File "/home/airflow/.local/lib/python3.8/site-packages/simple_di/__init__.py", line 139, in _
    return func(*_inject_args(bind.args), **_inject_kwargs(bind.kwargs))
  File "/home/airflow/.local/lib/python3.8/site-packages/bentoml/models.py", line 41, in get
    return _model_store.get(tag)
  File "/home/airflow/.local/lib/python3.8/site-packages/bentoml/_internal/store.py", line 137, in get
    self._recreate_latest(_tag)
  File "/home/airflow/.local/lib/python3.8/site-packages/bentoml/_internal/store.py", line 108, in _recreate_latest
    raise NotFound(
bentoml.exceptions.NotFound: no Models with name 'pik_recommender_model' exist in BentoML store <osfs '/home/airflow/bentoml/models'>
[2023-01-19T04:16:07.154+0000] {processor.py:770} WARNING - No viable dags retrieved from /opt/airflow/dags/bentoml/pik_rec_bento/bento_service_pik_rec.py
[2023-01-19T04:16:07.166+0000] {processor.py:178} INFO - Processing /opt/airflow/dags/bentoml/pik_rec_bento/bento_service_pik_rec.py took 2.225 seconds
[2023-01-19T04:16:37.410+0000] {processor.py:156} INFO - Started process (PID=4524) to work on /opt/airflow/dags/bentoml/pik_rec_bento/bento_service_pik_rec.py
[2023-01-19T04:16:37.411+0000] {processor.py:758} INFO - Processing file /opt/airflow/dags/bentoml/pik_rec_bento/bento_service_pik_rec.py for tasks to queue
[2023-01-19T04:16:37.412+0000] {logging_mixin.py:117} INFO - [2023-01-19T04:16:37.412+0000] {dagbag.py:525} INFO - Filling up the DagBag from /opt/airflow/dags/bentoml/pik_rec_bento/bento_service_pik_rec.py
[2023-01-19T04:16:39.616+0000] {logging_mixin.py:117} INFO - [2023-01-19T04:16:39.614+0000] {dagbag.py:330} ERROR - Failed to import: /opt/airflow/dags/bentoml/pik_rec_bento/bento_service_pik_rec.py
Traceback (most recent call last):
  File "/home/airflow/.local/lib/python3.8/site-packages/fs/osfs.py", line 647, in open
    return io.open(
FileNotFoundError: [Errno 2] No such file or directory: b'/home/airflow/bentoml/models/pik_recommender_model/latest'

During handling of the above exception, another exception occurred:

Traceback (most recent call last):
  File "/home/airflow/.local/lib/python3.8/site-packages/bentoml/_internal/store.py", line 132, in get
    _tag.version = self._fs.readtext(_tag.latest_path())
  File "/home/airflow/.local/lib/python3.8/site-packages/fs/base.py", line 693, in readtext
    self.open(
  File "/home/airflow/.local/lib/python3.8/site-packages/fs/osfs.py", line 647, in open
    return io.open(
  File "/home/airflow/.local/lib/python3.8/site-packages/fs/error_tools.py", line 89, in __exit__
    reraise(fserror, fserror(self._path, exc=exc_value), traceback)
  File "/home/airflow/.local/lib/python3.8/site-packages/six.py", line 718, in reraise
    raise value.with_traceback(tb)
  File "/home/airflow/.local/lib/python3.8/site-packages/fs/osfs.py", line 647, in open
    return io.open(
fs.errors.ResourceNotFound: resource 'pik_recommender_model/latest' not found

During handling of the above exception, another exception occurred:

Traceback (most recent call last):
  File "/home/airflow/.local/lib/python3.8/site-packages/bentoml/_internal/store.py", line 106, in _recreate_latest
    items = self.list(tag.name)
  File "/home/airflow/.local/lib/python3.8/site-packages/bentoml/_internal/store.py", line 83, in list
    raise NotFound(
bentoml.exceptions.NotFound: no Models with name 'pik_recommender_model' found

During handling of the above exception, another exception occurred:

Traceback (most recent call last):
  File "/home/airflow/.local/lib/python3.8/site-packages/airflow/models/dagbag.py", line 326, in parse
    loader.exec_module(new_module)
  File "<frozen importlib._bootstrap_external>", line 843, in exec_module
  File "<frozen importlib._bootstrap>", line 219, in _call_with_frames_removed
  File "/opt/airflow/dags/bentoml/pik_rec_bento/bento_service_pik_rec.py", line 31, in <module>
    runner = bentoml.transformers.get("pik_recommender_model:latest").to_runner()
  File "/home/airflow/.local/lib/python3.8/site-packages/bentoml/_internal/frameworks/transformers.py", line 151, in get
    model = bentoml.models.get(tag_like)
  File "/home/airflow/.local/lib/python3.8/site-packages/simple_di/__init__.py", line 139, in _
    return func(*_inject_args(bind.args), **_inject_kwargs(bind.kwargs))
  File "/home/airflow/.local/lib/python3.8/site-packages/bentoml/models.py", line 41, in get
    return _model_store.get(tag)
  File "/home/airflow/.local/lib/python3.8/site-packages/bentoml/_internal/store.py", line 137, in get
    self._recreate_latest(_tag)
  File "/home/airflow/.local/lib/python3.8/site-packages/bentoml/_internal/store.py", line 108, in _recreate_latest
    raise NotFound(
bentoml.exceptions.NotFound: no Models with name 'pik_recommender_model' exist in BentoML store <osfs '/home/airflow/bentoml/models'>
[2023-01-19T04:16:39.617+0000] {processor.py:770} WARNING - No viable dags retrieved from /opt/airflow/dags/bentoml/pik_rec_bento/bento_service_pik_rec.py
[2023-01-19T04:16:39.629+0000] {processor.py:178} INFO - Processing /opt/airflow/dags/bentoml/pik_rec_bento/bento_service_pik_rec.py took 2.223 seconds
[2023-01-19T04:17:09.965+0000] {processor.py:156} INFO - Started process (PID=4582) to work on /opt/airflow/dags/bentoml/pik_rec_bento/bento_service_pik_rec.py
[2023-01-19T04:17:09.966+0000] {processor.py:758} INFO - Processing file /opt/airflow/dags/bentoml/pik_rec_bento/bento_service_pik_rec.py for tasks to queue
[2023-01-19T04:17:09.966+0000] {logging_mixin.py:117} INFO - [2023-01-19T04:17:09.966+0000] {dagbag.py:525} INFO - Filling up the DagBag from /opt/airflow/dags/bentoml/pik_rec_bento/bento_service_pik_rec.py
[2023-01-19T04:17:12.197+0000] {logging_mixin.py:117} INFO - [2023-01-19T04:17:12.195+0000] {dagbag.py:330} ERROR - Failed to import: /opt/airflow/dags/bentoml/pik_rec_bento/bento_service_pik_rec.py
Traceback (most recent call last):
  File "/home/airflow/.local/lib/python3.8/site-packages/fs/osfs.py", line 647, in open
    return io.open(
FileNotFoundError: [Errno 2] No such file or directory: b'/home/airflow/bentoml/models/pik_recommender_model/latest'

During handling of the above exception, another exception occurred:

Traceback (most recent call last):
  File "/home/airflow/.local/lib/python3.8/site-packages/bentoml/_internal/store.py", line 132, in get
    _tag.version = self._fs.readtext(_tag.latest_path())
  File "/home/airflow/.local/lib/python3.8/site-packages/fs/base.py", line 693, in readtext
    self.open(
  File "/home/airflow/.local/lib/python3.8/site-packages/fs/osfs.py", line 647, in open
    return io.open(
  File "/home/airflow/.local/lib/python3.8/site-packages/fs/error_tools.py", line 89, in __exit__
    reraise(fserror, fserror(self._path, exc=exc_value), traceback)
  File "/home/airflow/.local/lib/python3.8/site-packages/six.py", line 718, in reraise
    raise value.with_traceback(tb)
  File "/home/airflow/.local/lib/python3.8/site-packages/fs/osfs.py", line 647, in open
    return io.open(
fs.errors.ResourceNotFound: resource 'pik_recommender_model/latest' not found

During handling of the above exception, another exception occurred:

Traceback (most recent call last):
  File "/home/airflow/.local/lib/python3.8/site-packages/bentoml/_internal/store.py", line 106, in _recreate_latest
    items = self.list(tag.name)
  File "/home/airflow/.local/lib/python3.8/site-packages/bentoml/_internal/store.py", line 83, in list
    raise NotFound(
bentoml.exceptions.NotFound: no Models with name 'pik_recommender_model' found

During handling of the above exception, another exception occurred:

Traceback (most recent call last):
  File "/home/airflow/.local/lib/python3.8/site-packages/airflow/models/dagbag.py", line 326, in parse
    loader.exec_module(new_module)
  File "<frozen importlib._bootstrap_external>", line 843, in exec_module
  File "<frozen importlib._bootstrap>", line 219, in _call_with_frames_removed
  File "/opt/airflow/dags/bentoml/pik_rec_bento/bento_service_pik_rec.py", line 31, in <module>
    runner = bentoml.transformers.get("pik_recommender_model:latest").to_runner()
  File "/home/airflow/.local/lib/python3.8/site-packages/bentoml/_internal/frameworks/transformers.py", line 151, in get
    model = bentoml.models.get(tag_like)
  File "/home/airflow/.local/lib/python3.8/site-packages/simple_di/__init__.py", line 139, in _
    return func(*_inject_args(bind.args), **_inject_kwargs(bind.kwargs))
  File "/home/airflow/.local/lib/python3.8/site-packages/bentoml/models.py", line 41, in get
    return _model_store.get(tag)
  File "/home/airflow/.local/lib/python3.8/site-packages/bentoml/_internal/store.py", line 137, in get
    self._recreate_latest(_tag)
  File "/home/airflow/.local/lib/python3.8/site-packages/bentoml/_internal/store.py", line 108, in _recreate_latest
    raise NotFound(
bentoml.exceptions.NotFound: no Models with name 'pik_recommender_model' exist in BentoML store <osfs '/home/airflow/bentoml/models'>
[2023-01-19T04:17:12.197+0000] {processor.py:770} WARNING - No viable dags retrieved from /opt/airflow/dags/bentoml/pik_rec_bento/bento_service_pik_rec.py
[2023-01-19T04:17:12.210+0000] {processor.py:178} INFO - Processing /opt/airflow/dags/bentoml/pik_rec_bento/bento_service_pik_rec.py took 2.248 seconds
[2023-01-19T04:17:42.275+0000] {processor.py:156} INFO - Started process (PID=4641) to work on /opt/airflow/dags/bentoml/pik_rec_bento/bento_service_pik_rec.py
[2023-01-19T04:17:42.276+0000] {processor.py:758} INFO - Processing file /opt/airflow/dags/bentoml/pik_rec_bento/bento_service_pik_rec.py for tasks to queue
[2023-01-19T04:17:42.276+0000] {logging_mixin.py:117} INFO - [2023-01-19T04:17:42.276+0000] {dagbag.py:525} INFO - Filling up the DagBag from /opt/airflow/dags/bentoml/pik_rec_bento/bento_service_pik_rec.py
[2023-01-19T04:17:44.419+0000] {logging_mixin.py:117} INFO - [2023-01-19T04:17:44.417+0000] {dagbag.py:330} ERROR - Failed to import: /opt/airflow/dags/bentoml/pik_rec_bento/bento_service_pik_rec.py
Traceback (most recent call last):
  File "/home/airflow/.local/lib/python3.8/site-packages/fs/osfs.py", line 647, in open
    return io.open(
FileNotFoundError: [Errno 2] No such file or directory: b'/home/airflow/bentoml/models/pik_recommender_model/latest'

During handling of the above exception, another exception occurred:

Traceback (most recent call last):
  File "/home/airflow/.local/lib/python3.8/site-packages/bentoml/_internal/store.py", line 132, in get
    _tag.version = self._fs.readtext(_tag.latest_path())
  File "/home/airflow/.local/lib/python3.8/site-packages/fs/base.py", line 693, in readtext
    self.open(
  File "/home/airflow/.local/lib/python3.8/site-packages/fs/osfs.py", line 647, in open
    return io.open(
  File "/home/airflow/.local/lib/python3.8/site-packages/fs/error_tools.py", line 89, in __exit__
    reraise(fserror, fserror(self._path, exc=exc_value), traceback)
  File "/home/airflow/.local/lib/python3.8/site-packages/six.py", line 718, in reraise
    raise value.with_traceback(tb)
  File "/home/airflow/.local/lib/python3.8/site-packages/fs/osfs.py", line 647, in open
    return io.open(
fs.errors.ResourceNotFound: resource 'pik_recommender_model/latest' not found

During handling of the above exception, another exception occurred:

Traceback (most recent call last):
  File "/home/airflow/.local/lib/python3.8/site-packages/bentoml/_internal/store.py", line 106, in _recreate_latest
    items = self.list(tag.name)
  File "/home/airflow/.local/lib/python3.8/site-packages/bentoml/_internal/store.py", line 83, in list
    raise NotFound(
bentoml.exceptions.NotFound: no Models with name 'pik_recommender_model' found

During handling of the above exception, another exception occurred:

Traceback (most recent call last):
  File "/home/airflow/.local/lib/python3.8/site-packages/airflow/models/dagbag.py", line 326, in parse
    loader.exec_module(new_module)
  File "<frozen importlib._bootstrap_external>", line 843, in exec_module
  File "<frozen importlib._bootstrap>", line 219, in _call_with_frames_removed
  File "/opt/airflow/dags/bentoml/pik_rec_bento/bento_service_pik_rec.py", line 31, in <module>
    runner = bentoml.transformers.get("pik_recommender_model:latest").to_runner()
  File "/home/airflow/.local/lib/python3.8/site-packages/bentoml/_internal/frameworks/transformers.py", line 151, in get
    model = bentoml.models.get(tag_like)
  File "/home/airflow/.local/lib/python3.8/site-packages/simple_di/__init__.py", line 139, in _
    return func(*_inject_args(bind.args), **_inject_kwargs(bind.kwargs))
  File "/home/airflow/.local/lib/python3.8/site-packages/bentoml/models.py", line 41, in get
    return _model_store.get(tag)
  File "/home/airflow/.local/lib/python3.8/site-packages/bentoml/_internal/store.py", line 137, in get
    self._recreate_latest(_tag)
  File "/home/airflow/.local/lib/python3.8/site-packages/bentoml/_internal/store.py", line 108, in _recreate_latest
    raise NotFound(
bentoml.exceptions.NotFound: no Models with name 'pik_recommender_model' exist in BentoML store <osfs '/home/airflow/bentoml/models'>
[2023-01-19T04:17:44.420+0000] {processor.py:770} WARNING - No viable dags retrieved from /opt/airflow/dags/bentoml/pik_rec_bento/bento_service_pik_rec.py
[2023-01-19T04:17:44.432+0000] {processor.py:178} INFO - Processing /opt/airflow/dags/bentoml/pik_rec_bento/bento_service_pik_rec.py took 2.161 seconds
[2023-01-19T04:18:14.807+0000] {processor.py:156} INFO - Started process (PID=4699) to work on /opt/airflow/dags/bentoml/pik_rec_bento/bento_service_pik_rec.py
[2023-01-19T04:18:14.808+0000] {processor.py:758} INFO - Processing file /opt/airflow/dags/bentoml/pik_rec_bento/bento_service_pik_rec.py for tasks to queue
[2023-01-19T04:18:14.809+0000] {logging_mixin.py:117} INFO - [2023-01-19T04:18:14.809+0000] {dagbag.py:525} INFO - Filling up the DagBag from /opt/airflow/dags/bentoml/pik_rec_bento/bento_service_pik_rec.py
[2023-01-19T04:18:16.971+0000] {logging_mixin.py:117} INFO - [2023-01-19T04:18:16.969+0000] {dagbag.py:330} ERROR - Failed to import: /opt/airflow/dags/bentoml/pik_rec_bento/bento_service_pik_rec.py
Traceback (most recent call last):
  File "/home/airflow/.local/lib/python3.8/site-packages/fs/osfs.py", line 647, in open
    return io.open(
FileNotFoundError: [Errno 2] No such file or directory: b'/home/airflow/bentoml/models/pik_recommender_model/latest'

During handling of the above exception, another exception occurred:

Traceback (most recent call last):
  File "/home/airflow/.local/lib/python3.8/site-packages/bentoml/_internal/store.py", line 132, in get
    _tag.version = self._fs.readtext(_tag.latest_path())
  File "/home/airflow/.local/lib/python3.8/site-packages/fs/base.py", line 693, in readtext
    self.open(
  File "/home/airflow/.local/lib/python3.8/site-packages/fs/osfs.py", line 647, in open
    return io.open(
  File "/home/airflow/.local/lib/python3.8/site-packages/fs/error_tools.py", line 89, in __exit__
    reraise(fserror, fserror(self._path, exc=exc_value), traceback)
  File "/home/airflow/.local/lib/python3.8/site-packages/six.py", line 718, in reraise
    raise value.with_traceback(tb)
  File "/home/airflow/.local/lib/python3.8/site-packages/fs/osfs.py", line 647, in open
    return io.open(
fs.errors.ResourceNotFound: resource 'pik_recommender_model/latest' not found

During handling of the above exception, another exception occurred:

Traceback (most recent call last):
  File "/home/airflow/.local/lib/python3.8/site-packages/bentoml/_internal/store.py", line 106, in _recreate_latest
    items = self.list(tag.name)
  File "/home/airflow/.local/lib/python3.8/site-packages/bentoml/_internal/store.py", line 83, in list
    raise NotFound(
bentoml.exceptions.NotFound: no Models with name 'pik_recommender_model' found

During handling of the above exception, another exception occurred:

Traceback (most recent call last):
  File "/home/airflow/.local/lib/python3.8/site-packages/airflow/models/dagbag.py", line 326, in parse
    loader.exec_module(new_module)
  File "<frozen importlib._bootstrap_external>", line 843, in exec_module
  File "<frozen importlib._bootstrap>", line 219, in _call_with_frames_removed
  File "/opt/airflow/dags/bentoml/pik_rec_bento/bento_service_pik_rec.py", line 31, in <module>
    runner = bentoml.transformers.get("pik_recommender_model:latest").to_runner()
  File "/home/airflow/.local/lib/python3.8/site-packages/bentoml/_internal/frameworks/transformers.py", line 151, in get
    model = bentoml.models.get(tag_like)
  File "/home/airflow/.local/lib/python3.8/site-packages/simple_di/__init__.py", line 139, in _
    return func(*_inject_args(bind.args), **_inject_kwargs(bind.kwargs))
  File "/home/airflow/.local/lib/python3.8/site-packages/bentoml/models.py", line 41, in get
    return _model_store.get(tag)
  File "/home/airflow/.local/lib/python3.8/site-packages/bentoml/_internal/store.py", line 137, in get
    self._recreate_latest(_tag)
  File "/home/airflow/.local/lib/python3.8/site-packages/bentoml/_internal/store.py", line 108, in _recreate_latest
    raise NotFound(
bentoml.exceptions.NotFound: no Models with name 'pik_recommender_model' exist in BentoML store <osfs '/home/airflow/bentoml/models'>
[2023-01-19T04:18:16.971+0000] {processor.py:770} WARNING - No viable dags retrieved from /opt/airflow/dags/bentoml/pik_rec_bento/bento_service_pik_rec.py
[2023-01-19T04:18:16.983+0000] {processor.py:178} INFO - Processing /opt/airflow/dags/bentoml/pik_rec_bento/bento_service_pik_rec.py took 2.180 seconds
[2023-01-19T04:18:47.319+0000] {processor.py:156} INFO - Started process (PID=4757) to work on /opt/airflow/dags/bentoml/pik_rec_bento/bento_service_pik_rec.py
[2023-01-19T04:18:47.320+0000] {processor.py:758} INFO - Processing file /opt/airflow/dags/bentoml/pik_rec_bento/bento_service_pik_rec.py for tasks to queue
[2023-01-19T04:18:47.320+0000] {logging_mixin.py:117} INFO - [2023-01-19T04:18:47.320+0000] {dagbag.py:525} INFO - Filling up the DagBag from /opt/airflow/dags/bentoml/pik_rec_bento/bento_service_pik_rec.py
[2023-01-19T04:18:49.482+0000] {logging_mixin.py:117} INFO - [2023-01-19T04:18:49.480+0000] {dagbag.py:330} ERROR - Failed to import: /opt/airflow/dags/bentoml/pik_rec_bento/bento_service_pik_rec.py
Traceback (most recent call last):
  File "/home/airflow/.local/lib/python3.8/site-packages/fs/osfs.py", line 647, in open
    return io.open(
FileNotFoundError: [Errno 2] No such file or directory: b'/home/airflow/bentoml/models/pik_recommender_model/latest'

During handling of the above exception, another exception occurred:

Traceback (most recent call last):
  File "/home/airflow/.local/lib/python3.8/site-packages/bentoml/_internal/store.py", line 132, in get
    _tag.version = self._fs.readtext(_tag.latest_path())
  File "/home/airflow/.local/lib/python3.8/site-packages/fs/base.py", line 693, in readtext
    self.open(
  File "/home/airflow/.local/lib/python3.8/site-packages/fs/osfs.py", line 647, in open
    return io.open(
  File "/home/airflow/.local/lib/python3.8/site-packages/fs/error_tools.py", line 89, in __exit__
    reraise(fserror, fserror(self._path, exc=exc_value), traceback)
  File "/home/airflow/.local/lib/python3.8/site-packages/six.py", line 718, in reraise
    raise value.with_traceback(tb)
  File "/home/airflow/.local/lib/python3.8/site-packages/fs/osfs.py", line 647, in open
    return io.open(
fs.errors.ResourceNotFound: resource 'pik_recommender_model/latest' not found

During handling of the above exception, another exception occurred:

Traceback (most recent call last):
  File "/home/airflow/.local/lib/python3.8/site-packages/bentoml/_internal/store.py", line 106, in _recreate_latest
    items = self.list(tag.name)
  File "/home/airflow/.local/lib/python3.8/site-packages/bentoml/_internal/store.py", line 83, in list
    raise NotFound(
bentoml.exceptions.NotFound: no Models with name 'pik_recommender_model' found

During handling of the above exception, another exception occurred:

Traceback (most recent call last):
  File "/home/airflow/.local/lib/python3.8/site-packages/airflow/models/dagbag.py", line 326, in parse
    loader.exec_module(new_module)
  File "<frozen importlib._bootstrap_external>", line 843, in exec_module
  File "<frozen importlib._bootstrap>", line 219, in _call_with_frames_removed
  File "/opt/airflow/dags/bentoml/pik_rec_bento/bento_service_pik_rec.py", line 31, in <module>
    runner = bentoml.transformers.get("pik_recommender_model:latest").to_runner()
  File "/home/airflow/.local/lib/python3.8/site-packages/bentoml/_internal/frameworks/transformers.py", line 151, in get
    model = bentoml.models.get(tag_like)
  File "/home/airflow/.local/lib/python3.8/site-packages/simple_di/__init__.py", line 139, in _
    return func(*_inject_args(bind.args), **_inject_kwargs(bind.kwargs))
  File "/home/airflow/.local/lib/python3.8/site-packages/bentoml/models.py", line 41, in get
    return _model_store.get(tag)
  File "/home/airflow/.local/lib/python3.8/site-packages/bentoml/_internal/store.py", line 137, in get
    self._recreate_latest(_tag)
  File "/home/airflow/.local/lib/python3.8/site-packages/bentoml/_internal/store.py", line 108, in _recreate_latest
    raise NotFound(
bentoml.exceptions.NotFound: no Models with name 'pik_recommender_model' exist in BentoML store <osfs '/home/airflow/bentoml/models'>
[2023-01-19T04:18:49.482+0000] {processor.py:770} WARNING - No viable dags retrieved from /opt/airflow/dags/bentoml/pik_rec_bento/bento_service_pik_rec.py
[2023-01-19T04:18:49.495+0000] {processor.py:178} INFO - Processing /opt/airflow/dags/bentoml/pik_rec_bento/bento_service_pik_rec.py took 2.179 seconds
[2023-01-19T04:19:20.108+0000] {processor.py:156} INFO - Started process (PID=4815) to work on /opt/airflow/dags/bentoml/pik_rec_bento/bento_service_pik_rec.py
[2023-01-19T04:19:20.109+0000] {processor.py:758} INFO - Processing file /opt/airflow/dags/bentoml/pik_rec_bento/bento_service_pik_rec.py for tasks to queue
[2023-01-19T04:19:20.110+0000] {logging_mixin.py:117} INFO - [2023-01-19T04:19:20.109+0000] {dagbag.py:525} INFO - Filling up the DagBag from /opt/airflow/dags/bentoml/pik_rec_bento/bento_service_pik_rec.py
[2023-01-19T04:19:22.261+0000] {logging_mixin.py:117} INFO - [2023-01-19T04:19:22.259+0000] {dagbag.py:330} ERROR - Failed to import: /opt/airflow/dags/bentoml/pik_rec_bento/bento_service_pik_rec.py
Traceback (most recent call last):
  File "/home/airflow/.local/lib/python3.8/site-packages/fs/osfs.py", line 647, in open
    return io.open(
FileNotFoundError: [Errno 2] No such file or directory: b'/home/airflow/bentoml/models/pik_recommender_model/latest'

During handling of the above exception, another exception occurred:

Traceback (most recent call last):
  File "/home/airflow/.local/lib/python3.8/site-packages/bentoml/_internal/store.py", line 132, in get
    _tag.version = self._fs.readtext(_tag.latest_path())
  File "/home/airflow/.local/lib/python3.8/site-packages/fs/base.py", line 693, in readtext
    self.open(
  File "/home/airflow/.local/lib/python3.8/site-packages/fs/osfs.py", line 647, in open
    return io.open(
  File "/home/airflow/.local/lib/python3.8/site-packages/fs/error_tools.py", line 89, in __exit__
    reraise(fserror, fserror(self._path, exc=exc_value), traceback)
  File "/home/airflow/.local/lib/python3.8/site-packages/six.py", line 718, in reraise
    raise value.with_traceback(tb)
  File "/home/airflow/.local/lib/python3.8/site-packages/fs/osfs.py", line 647, in open
    return io.open(
fs.errors.ResourceNotFound: resource 'pik_recommender_model/latest' not found

During handling of the above exception, another exception occurred:

Traceback (most recent call last):
  File "/home/airflow/.local/lib/python3.8/site-packages/bentoml/_internal/store.py", line 106, in _recreate_latest
    items = self.list(tag.name)
  File "/home/airflow/.local/lib/python3.8/site-packages/bentoml/_internal/store.py", line 83, in list
    raise NotFound(
bentoml.exceptions.NotFound: no Models with name 'pik_recommender_model' found

During handling of the above exception, another exception occurred:

Traceback (most recent call last):
  File "/home/airflow/.local/lib/python3.8/site-packages/airflow/models/dagbag.py", line 326, in parse
    loader.exec_module(new_module)
  File "<frozen importlib._bootstrap_external>", line 843, in exec_module
  File "<frozen importlib._bootstrap>", line 219, in _call_with_frames_removed
  File "/opt/airflow/dags/bentoml/pik_rec_bento/bento_service_pik_rec.py", line 31, in <module>
    runner = bentoml.transformers.get("pik_recommender_model:latest").to_runner()
  File "/home/airflow/.local/lib/python3.8/site-packages/bentoml/_internal/frameworks/transformers.py", line 151, in get
    model = bentoml.models.get(tag_like)
  File "/home/airflow/.local/lib/python3.8/site-packages/simple_di/__init__.py", line 139, in _
    return func(*_inject_args(bind.args), **_inject_kwargs(bind.kwargs))
  File "/home/airflow/.local/lib/python3.8/site-packages/bentoml/models.py", line 41, in get
    return _model_store.get(tag)
  File "/home/airflow/.local/lib/python3.8/site-packages/bentoml/_internal/store.py", line 137, in get
    self._recreate_latest(_tag)
  File "/home/airflow/.local/lib/python3.8/site-packages/bentoml/_internal/store.py", line 108, in _recreate_latest
    raise NotFound(
bentoml.exceptions.NotFound: no Models with name 'pik_recommender_model' exist in BentoML store <osfs '/home/airflow/bentoml/models'>
[2023-01-19T04:19:22.261+0000] {processor.py:770} WARNING - No viable dags retrieved from /opt/airflow/dags/bentoml/pik_rec_bento/bento_service_pik_rec.py
[2023-01-19T04:19:22.274+0000] {processor.py:178} INFO - Processing /opt/airflow/dags/bentoml/pik_rec_bento/bento_service_pik_rec.py took 2.169 seconds
