[2023-01-19T04:09:55.146+0000] {processor.py:156} INFO - Started process (PID=3811) to work on /opt/airflow/dags/bentoml/user_rec_bento/bento_service_user_rec.py
[2023-01-19T04:09:55.146+0000] {processor.py:758} INFO - Processing file /opt/airflow/dags/bentoml/user_rec_bento/bento_service_user_rec.py for tasks to queue
[2023-01-19T04:09:55.147+0000] {logging_mixin.py:117} INFO - [2023-01-19T04:09:55.147+0000] {dagbag.py:525} INFO - Filling up the DagBag from /opt/airflow/dags/bentoml/user_rec_bento/bento_service_user_rec.py
[2023-01-19T04:09:57.336+0000] {logging_mixin.py:117} INFO - [2023-01-19T04:09:57.335+0000] {dagbag.py:330} ERROR - Failed to import: /opt/airflow/dags/bentoml/user_rec_bento/bento_service_user_rec.py
Traceback (most recent call last):
  File "/home/airflow/.local/lib/python3.8/site-packages/fs/osfs.py", line 647, in open
    return io.open(
FileNotFoundError: [Errno 2] No such file or directory: b'/home/airflow/bentoml/models/user_recommender_model/latest'

During handling of the above exception, another exception occurred:

Traceback (most recent call last):
  File "/home/airflow/.local/lib/python3.8/site-packages/bentoml/_internal/store.py", line 132, in get
    _tag.version = self._fs.readtext(_tag.latest_path())
  File "/home/airflow/.local/lib/python3.8/site-packages/fs/base.py", line 693, in readtext
    self.open(
  File "/home/airflow/.local/lib/python3.8/site-packages/fs/osfs.py", line 647, in open
    return io.open(
  File "/home/airflow/.local/lib/python3.8/site-packages/fs/error_tools.py", line 89, in __exit__
    reraise(fserror, fserror(self._path, exc=exc_value), traceback)
  File "/home/airflow/.local/lib/python3.8/site-packages/six.py", line 718, in reraise
    raise value.with_traceback(tb)
  File "/home/airflow/.local/lib/python3.8/site-packages/fs/osfs.py", line 647, in open
    return io.open(
fs.errors.ResourceNotFound: resource 'user_recommender_model/latest' not found

During handling of the above exception, another exception occurred:

Traceback (most recent call last):
  File "/home/airflow/.local/lib/python3.8/site-packages/bentoml/_internal/store.py", line 106, in _recreate_latest
    items = self.list(tag.name)
  File "/home/airflow/.local/lib/python3.8/site-packages/bentoml/_internal/store.py", line 83, in list
    raise NotFound(
bentoml.exceptions.NotFound: no Models with name 'user_recommender_model' found

During handling of the above exception, another exception occurred:

Traceback (most recent call last):
  File "/home/airflow/.local/lib/python3.8/site-packages/airflow/models/dagbag.py", line 326, in parse
    loader.exec_module(new_module)
  File "<frozen importlib._bootstrap_external>", line 843, in exec_module
  File "<frozen importlib._bootstrap>", line 219, in _call_with_frames_removed
  File "/opt/airflow/dags/bentoml/user_rec_bento/bento_service_user_rec.py", line 24, in <module>
    runner = bentoml.transformers.get("user_recommender_model:latest").to_runner()
  File "/home/airflow/.local/lib/python3.8/site-packages/bentoml/_internal/frameworks/transformers.py", line 151, in get
    model = bentoml.models.get(tag_like)
  File "/home/airflow/.local/lib/python3.8/site-packages/simple_di/__init__.py", line 139, in _
    return func(*_inject_args(bind.args), **_inject_kwargs(bind.kwargs))
  File "/home/airflow/.local/lib/python3.8/site-packages/bentoml/models.py", line 41, in get
    return _model_store.get(tag)
  File "/home/airflow/.local/lib/python3.8/site-packages/bentoml/_internal/store.py", line 137, in get
    self._recreate_latest(_tag)
  File "/home/airflow/.local/lib/python3.8/site-packages/bentoml/_internal/store.py", line 108, in _recreate_latest
    raise NotFound(
bentoml.exceptions.NotFound: no Models with name 'user_recommender_model' exist in BentoML store <osfs '/home/airflow/bentoml/models'>
[2023-01-19T04:09:57.337+0000] {processor.py:770} WARNING - No viable dags retrieved from /opt/airflow/dags/bentoml/user_rec_bento/bento_service_user_rec.py
[2023-01-19T04:09:57.349+0000] {processor.py:178} INFO - Processing /opt/airflow/dags/bentoml/user_rec_bento/bento_service_user_rec.py took 2.206 seconds
[2023-01-19T04:10:27.390+0000] {processor.py:156} INFO - Started process (PID=3870) to work on /opt/airflow/dags/bentoml/user_rec_bento/bento_service_user_rec.py
[2023-01-19T04:10:27.391+0000] {processor.py:758} INFO - Processing file /opt/airflow/dags/bentoml/user_rec_bento/bento_service_user_rec.py for tasks to queue
[2023-01-19T04:10:27.391+0000] {logging_mixin.py:117} INFO - [2023-01-19T04:10:27.391+0000] {dagbag.py:525} INFO - Filling up the DagBag from /opt/airflow/dags/bentoml/user_rec_bento/bento_service_user_rec.py
[2023-01-19T04:10:29.553+0000] {logging_mixin.py:117} INFO - [2023-01-19T04:10:29.551+0000] {dagbag.py:330} ERROR - Failed to import: /opt/airflow/dags/bentoml/user_rec_bento/bento_service_user_rec.py
Traceback (most recent call last):
  File "/home/airflow/.local/lib/python3.8/site-packages/fs/osfs.py", line 647, in open
    return io.open(
FileNotFoundError: [Errno 2] No such file or directory: b'/home/airflow/bentoml/models/user_recommender_model/latest'

During handling of the above exception, another exception occurred:

Traceback (most recent call last):
  File "/home/airflow/.local/lib/python3.8/site-packages/bentoml/_internal/store.py", line 132, in get
    _tag.version = self._fs.readtext(_tag.latest_path())
  File "/home/airflow/.local/lib/python3.8/site-packages/fs/base.py", line 693, in readtext
    self.open(
  File "/home/airflow/.local/lib/python3.8/site-packages/fs/osfs.py", line 647, in open
    return io.open(
  File "/home/airflow/.local/lib/python3.8/site-packages/fs/error_tools.py", line 89, in __exit__
    reraise(fserror, fserror(self._path, exc=exc_value), traceback)
  File "/home/airflow/.local/lib/python3.8/site-packages/six.py", line 718, in reraise
    raise value.with_traceback(tb)
  File "/home/airflow/.local/lib/python3.8/site-packages/fs/osfs.py", line 647, in open
    return io.open(
fs.errors.ResourceNotFound: resource 'user_recommender_model/latest' not found

During handling of the above exception, another exception occurred:

Traceback (most recent call last):
  File "/home/airflow/.local/lib/python3.8/site-packages/bentoml/_internal/store.py", line 106, in _recreate_latest
    items = self.list(tag.name)
  File "/home/airflow/.local/lib/python3.8/site-packages/bentoml/_internal/store.py", line 83, in list
    raise NotFound(
bentoml.exceptions.NotFound: no Models with name 'user_recommender_model' found

During handling of the above exception, another exception occurred:

Traceback (most recent call last):
  File "/home/airflow/.local/lib/python3.8/site-packages/airflow/models/dagbag.py", line 326, in parse
    loader.exec_module(new_module)
  File "<frozen importlib._bootstrap_external>", line 843, in exec_module
  File "<frozen importlib._bootstrap>", line 219, in _call_with_frames_removed
  File "/opt/airflow/dags/bentoml/user_rec_bento/bento_service_user_rec.py", line 24, in <module>
    runner = bentoml.transformers.get("user_recommender_model:latest").to_runner()
  File "/home/airflow/.local/lib/python3.8/site-packages/bentoml/_internal/frameworks/transformers.py", line 151, in get
    model = bentoml.models.get(tag_like)
  File "/home/airflow/.local/lib/python3.8/site-packages/simple_di/__init__.py", line 139, in _
    return func(*_inject_args(bind.args), **_inject_kwargs(bind.kwargs))
  File "/home/airflow/.local/lib/python3.8/site-packages/bentoml/models.py", line 41, in get
    return _model_store.get(tag)
  File "/home/airflow/.local/lib/python3.8/site-packages/bentoml/_internal/store.py", line 137, in get
    self._recreate_latest(_tag)
  File "/home/airflow/.local/lib/python3.8/site-packages/bentoml/_internal/store.py", line 108, in _recreate_latest
    raise NotFound(
bentoml.exceptions.NotFound: no Models with name 'user_recommender_model' exist in BentoML store <osfs '/home/airflow/bentoml/models'>
[2023-01-19T04:10:29.554+0000] {processor.py:770} WARNING - No viable dags retrieved from /opt/airflow/dags/bentoml/user_rec_bento/bento_service_user_rec.py
[2023-01-19T04:10:29.567+0000] {processor.py:178} INFO - Processing /opt/airflow/dags/bentoml/user_rec_bento/bento_service_user_rec.py took 2.180 seconds
[2023-01-19T04:10:59.791+0000] {processor.py:156} INFO - Started process (PID=3928) to work on /opt/airflow/dags/bentoml/user_rec_bento/bento_service_user_rec.py
[2023-01-19T04:10:59.792+0000] {processor.py:758} INFO - Processing file /opt/airflow/dags/bentoml/user_rec_bento/bento_service_user_rec.py for tasks to queue
[2023-01-19T04:10:59.792+0000] {logging_mixin.py:117} INFO - [2023-01-19T04:10:59.792+0000] {dagbag.py:525} INFO - Filling up the DagBag from /opt/airflow/dags/bentoml/user_rec_bento/bento_service_user_rec.py
[2023-01-19T04:11:01.996+0000] {logging_mixin.py:117} INFO - [2023-01-19T04:11:01.994+0000] {dagbag.py:330} ERROR - Failed to import: /opt/airflow/dags/bentoml/user_rec_bento/bento_service_user_rec.py
Traceback (most recent call last):
  File "/home/airflow/.local/lib/python3.8/site-packages/fs/osfs.py", line 647, in open
    return io.open(
FileNotFoundError: [Errno 2] No such file or directory: b'/home/airflow/bentoml/models/user_recommender_model/latest'

During handling of the above exception, another exception occurred:

Traceback (most recent call last):
  File "/home/airflow/.local/lib/python3.8/site-packages/bentoml/_internal/store.py", line 132, in get
    _tag.version = self._fs.readtext(_tag.latest_path())
  File "/home/airflow/.local/lib/python3.8/site-packages/fs/base.py", line 693, in readtext
    self.open(
  File "/home/airflow/.local/lib/python3.8/site-packages/fs/osfs.py", line 647, in open
    return io.open(
  File "/home/airflow/.local/lib/python3.8/site-packages/fs/error_tools.py", line 89, in __exit__
    reraise(fserror, fserror(self._path, exc=exc_value), traceback)
  File "/home/airflow/.local/lib/python3.8/site-packages/six.py", line 718, in reraise
    raise value.with_traceback(tb)
  File "/home/airflow/.local/lib/python3.8/site-packages/fs/osfs.py", line 647, in open
    return io.open(
fs.errors.ResourceNotFound: resource 'user_recommender_model/latest' not found

During handling of the above exception, another exception occurred:

Traceback (most recent call last):
  File "/home/airflow/.local/lib/python3.8/site-packages/bentoml/_internal/store.py", line 106, in _recreate_latest
    items = self.list(tag.name)
  File "/home/airflow/.local/lib/python3.8/site-packages/bentoml/_internal/store.py", line 83, in list
    raise NotFound(
bentoml.exceptions.NotFound: no Models with name 'user_recommender_model' found

During handling of the above exception, another exception occurred:

Traceback (most recent call last):
  File "/home/airflow/.local/lib/python3.8/site-packages/airflow/models/dagbag.py", line 326, in parse
    loader.exec_module(new_module)
  File "<frozen importlib._bootstrap_external>", line 843, in exec_module
  File "<frozen importlib._bootstrap>", line 219, in _call_with_frames_removed
  File "/opt/airflow/dags/bentoml/user_rec_bento/bento_service_user_rec.py", line 24, in <module>
    runner = bentoml.transformers.get("user_recommender_model:latest").to_runner()
  File "/home/airflow/.local/lib/python3.8/site-packages/bentoml/_internal/frameworks/transformers.py", line 151, in get
    model = bentoml.models.get(tag_like)
  File "/home/airflow/.local/lib/python3.8/site-packages/simple_di/__init__.py", line 139, in _
    return func(*_inject_args(bind.args), **_inject_kwargs(bind.kwargs))
  File "/home/airflow/.local/lib/python3.8/site-packages/bentoml/models.py", line 41, in get
    return _model_store.get(tag)
  File "/home/airflow/.local/lib/python3.8/site-packages/bentoml/_internal/store.py", line 137, in get
    self._recreate_latest(_tag)
  File "/home/airflow/.local/lib/python3.8/site-packages/bentoml/_internal/store.py", line 108, in _recreate_latest
    raise NotFound(
bentoml.exceptions.NotFound: no Models with name 'user_recommender_model' exist in BentoML store <osfs '/home/airflow/bentoml/models'>
[2023-01-19T04:11:01.996+0000] {processor.py:770} WARNING - No viable dags retrieved from /opt/airflow/dags/bentoml/user_rec_bento/bento_service_user_rec.py
[2023-01-19T04:11:02.009+0000] {processor.py:178} INFO - Processing /opt/airflow/dags/bentoml/user_rec_bento/bento_service_user_rec.py took 2.221 seconds
[2023-01-19T04:11:32.936+0000] {processor.py:156} INFO - Started process (PID=3985) to work on /opt/airflow/dags/bentoml/user_rec_bento/bento_service_user_rec.py
[2023-01-19T04:11:32.937+0000] {processor.py:758} INFO - Processing file /opt/airflow/dags/bentoml/user_rec_bento/bento_service_user_rec.py for tasks to queue
[2023-01-19T04:11:32.937+0000] {logging_mixin.py:117} INFO - [2023-01-19T04:11:32.937+0000] {dagbag.py:525} INFO - Filling up the DagBag from /opt/airflow/dags/bentoml/user_rec_bento/bento_service_user_rec.py
[2023-01-19T04:11:35.103+0000] {logging_mixin.py:117} INFO - [2023-01-19T04:11:35.101+0000] {dagbag.py:330} ERROR - Failed to import: /opt/airflow/dags/bentoml/user_rec_bento/bento_service_user_rec.py
Traceback (most recent call last):
  File "/home/airflow/.local/lib/python3.8/site-packages/fs/osfs.py", line 647, in open
    return io.open(
FileNotFoundError: [Errno 2] No such file or directory: b'/home/airflow/bentoml/models/user_recommender_model/latest'

During handling of the above exception, another exception occurred:

Traceback (most recent call last):
  File "/home/airflow/.local/lib/python3.8/site-packages/bentoml/_internal/store.py", line 132, in get
    _tag.version = self._fs.readtext(_tag.latest_path())
  File "/home/airflow/.local/lib/python3.8/site-packages/fs/base.py", line 693, in readtext
    self.open(
  File "/home/airflow/.local/lib/python3.8/site-packages/fs/osfs.py", line 647, in open
    return io.open(
  File "/home/airflow/.local/lib/python3.8/site-packages/fs/error_tools.py", line 89, in __exit__
    reraise(fserror, fserror(self._path, exc=exc_value), traceback)
  File "/home/airflow/.local/lib/python3.8/site-packages/six.py", line 718, in reraise
    raise value.with_traceback(tb)
  File "/home/airflow/.local/lib/python3.8/site-packages/fs/osfs.py", line 647, in open
    return io.open(
fs.errors.ResourceNotFound: resource 'user_recommender_model/latest' not found

During handling of the above exception, another exception occurred:

Traceback (most recent call last):
  File "/home/airflow/.local/lib/python3.8/site-packages/bentoml/_internal/store.py", line 106, in _recreate_latest
    items = self.list(tag.name)
  File "/home/airflow/.local/lib/python3.8/site-packages/bentoml/_internal/store.py", line 83, in list
    raise NotFound(
bentoml.exceptions.NotFound: no Models with name 'user_recommender_model' found

During handling of the above exception, another exception occurred:

Traceback (most recent call last):
  File "/home/airflow/.local/lib/python3.8/site-packages/airflow/models/dagbag.py", line 326, in parse
    loader.exec_module(new_module)
  File "<frozen importlib._bootstrap_external>", line 843, in exec_module
  File "<frozen importlib._bootstrap>", line 219, in _call_with_frames_removed
  File "/opt/airflow/dags/bentoml/user_rec_bento/bento_service_user_rec.py", line 24, in <module>
    runner = bentoml.transformers.get("user_recommender_model:latest").to_runner()
  File "/home/airflow/.local/lib/python3.8/site-packages/bentoml/_internal/frameworks/transformers.py", line 151, in get
    model = bentoml.models.get(tag_like)
  File "/home/airflow/.local/lib/python3.8/site-packages/simple_di/__init__.py", line 139, in _
    return func(*_inject_args(bind.args), **_inject_kwargs(bind.kwargs))
  File "/home/airflow/.local/lib/python3.8/site-packages/bentoml/models.py", line 41, in get
    return _model_store.get(tag)
  File "/home/airflow/.local/lib/python3.8/site-packages/bentoml/_internal/store.py", line 137, in get
    self._recreate_latest(_tag)
  File "/home/airflow/.local/lib/python3.8/site-packages/bentoml/_internal/store.py", line 108, in _recreate_latest
    raise NotFound(
bentoml.exceptions.NotFound: no Models with name 'user_recommender_model' exist in BentoML store <osfs '/home/airflow/bentoml/models'>
[2023-01-19T04:11:35.103+0000] {processor.py:770} WARNING - No viable dags retrieved from /opt/airflow/dags/bentoml/user_rec_bento/bento_service_user_rec.py
[2023-01-19T04:11:35.116+0000] {processor.py:178} INFO - Processing /opt/airflow/dags/bentoml/user_rec_bento/bento_service_user_rec.py took 2.183 seconds
[2023-01-19T04:12:05.510+0000] {processor.py:156} INFO - Started process (PID=4043) to work on /opt/airflow/dags/bentoml/user_rec_bento/bento_service_user_rec.py
[2023-01-19T04:12:05.510+0000] {processor.py:758} INFO - Processing file /opt/airflow/dags/bentoml/user_rec_bento/bento_service_user_rec.py for tasks to queue
[2023-01-19T04:12:05.511+0000] {logging_mixin.py:117} INFO - [2023-01-19T04:12:05.511+0000] {dagbag.py:525} INFO - Filling up the DagBag from /opt/airflow/dags/bentoml/user_rec_bento/bento_service_user_rec.py
[2023-01-19T04:12:07.698+0000] {logging_mixin.py:117} INFO - [2023-01-19T04:12:07.696+0000] {dagbag.py:330} ERROR - Failed to import: /opt/airflow/dags/bentoml/user_rec_bento/bento_service_user_rec.py
Traceback (most recent call last):
  File "/home/airflow/.local/lib/python3.8/site-packages/fs/osfs.py", line 647, in open
    return io.open(
FileNotFoundError: [Errno 2] No such file or directory: b'/home/airflow/bentoml/models/user_recommender_model/latest'

During handling of the above exception, another exception occurred:

Traceback (most recent call last):
  File "/home/airflow/.local/lib/python3.8/site-packages/bentoml/_internal/store.py", line 132, in get
    _tag.version = self._fs.readtext(_tag.latest_path())
  File "/home/airflow/.local/lib/python3.8/site-packages/fs/base.py", line 693, in readtext
    self.open(
  File "/home/airflow/.local/lib/python3.8/site-packages/fs/osfs.py", line 647, in open
    return io.open(
  File "/home/airflow/.local/lib/python3.8/site-packages/fs/error_tools.py", line 89, in __exit__
    reraise(fserror, fserror(self._path, exc=exc_value), traceback)
  File "/home/airflow/.local/lib/python3.8/site-packages/six.py", line 718, in reraise
    raise value.with_traceback(tb)
  File "/home/airflow/.local/lib/python3.8/site-packages/fs/osfs.py", line 647, in open
    return io.open(
fs.errors.ResourceNotFound: resource 'user_recommender_model/latest' not found

During handling of the above exception, another exception occurred:

Traceback (most recent call last):
  File "/home/airflow/.local/lib/python3.8/site-packages/bentoml/_internal/store.py", line 106, in _recreate_latest
    items = self.list(tag.name)
  File "/home/airflow/.local/lib/python3.8/site-packages/bentoml/_internal/store.py", line 83, in list
    raise NotFound(
bentoml.exceptions.NotFound: no Models with name 'user_recommender_model' found

During handling of the above exception, another exception occurred:

Traceback (most recent call last):
  File "/home/airflow/.local/lib/python3.8/site-packages/airflow/models/dagbag.py", line 326, in parse
    loader.exec_module(new_module)
  File "<frozen importlib._bootstrap_external>", line 843, in exec_module
  File "<frozen importlib._bootstrap>", line 219, in _call_with_frames_removed
  File "/opt/airflow/dags/bentoml/user_rec_bento/bento_service_user_rec.py", line 24, in <module>
    runner = bentoml.transformers.get("user_recommender_model:latest").to_runner()
  File "/home/airflow/.local/lib/python3.8/site-packages/bentoml/_internal/frameworks/transformers.py", line 151, in get
    model = bentoml.models.get(tag_like)
  File "/home/airflow/.local/lib/python3.8/site-packages/simple_di/__init__.py", line 139, in _
    return func(*_inject_args(bind.args), **_inject_kwargs(bind.kwargs))
  File "/home/airflow/.local/lib/python3.8/site-packages/bentoml/models.py", line 41, in get
    return _model_store.get(tag)
  File "/home/airflow/.local/lib/python3.8/site-packages/bentoml/_internal/store.py", line 137, in get
    self._recreate_latest(_tag)
  File "/home/airflow/.local/lib/python3.8/site-packages/bentoml/_internal/store.py", line 108, in _recreate_latest
    raise NotFound(
bentoml.exceptions.NotFound: no Models with name 'user_recommender_model' exist in BentoML store <osfs '/home/airflow/bentoml/models'>
[2023-01-19T04:12:07.698+0000] {processor.py:770} WARNING - No viable dags retrieved from /opt/airflow/dags/bentoml/user_rec_bento/bento_service_user_rec.py
[2023-01-19T04:12:07.711+0000] {processor.py:178} INFO - Processing /opt/airflow/dags/bentoml/user_rec_bento/bento_service_user_rec.py took 2.204 seconds
[2023-01-19T04:12:38.020+0000] {processor.py:156} INFO - Started process (PID=4101) to work on /opt/airflow/dags/bentoml/user_rec_bento/bento_service_user_rec.py
[2023-01-19T04:12:38.022+0000] {processor.py:758} INFO - Processing file /opt/airflow/dags/bentoml/user_rec_bento/bento_service_user_rec.py for tasks to queue
[2023-01-19T04:12:38.022+0000] {logging_mixin.py:117} INFO - [2023-01-19T04:12:38.022+0000] {dagbag.py:525} INFO - Filling up the DagBag from /opt/airflow/dags/bentoml/user_rec_bento/bento_service_user_rec.py
[2023-01-19T04:12:40.179+0000] {logging_mixin.py:117} INFO - [2023-01-19T04:12:40.177+0000] {dagbag.py:330} ERROR - Failed to import: /opt/airflow/dags/bentoml/user_rec_bento/bento_service_user_rec.py
Traceback (most recent call last):
  File "/home/airflow/.local/lib/python3.8/site-packages/fs/osfs.py", line 647, in open
    return io.open(
FileNotFoundError: [Errno 2] No such file or directory: b'/home/airflow/bentoml/models/user_recommender_model/latest'

During handling of the above exception, another exception occurred:

Traceback (most recent call last):
  File "/home/airflow/.local/lib/python3.8/site-packages/bentoml/_internal/store.py", line 132, in get
    _tag.version = self._fs.readtext(_tag.latest_path())
  File "/home/airflow/.local/lib/python3.8/site-packages/fs/base.py", line 693, in readtext
    self.open(
  File "/home/airflow/.local/lib/python3.8/site-packages/fs/osfs.py", line 647, in open
    return io.open(
  File "/home/airflow/.local/lib/python3.8/site-packages/fs/error_tools.py", line 89, in __exit__
    reraise(fserror, fserror(self._path, exc=exc_value), traceback)
  File "/home/airflow/.local/lib/python3.8/site-packages/six.py", line 718, in reraise
    raise value.with_traceback(tb)
  File "/home/airflow/.local/lib/python3.8/site-packages/fs/osfs.py", line 647, in open
    return io.open(
fs.errors.ResourceNotFound: resource 'user_recommender_model/latest' not found

During handling of the above exception, another exception occurred:

Traceback (most recent call last):
  File "/home/airflow/.local/lib/python3.8/site-packages/bentoml/_internal/store.py", line 106, in _recreate_latest
    items = self.list(tag.name)
  File "/home/airflow/.local/lib/python3.8/site-packages/bentoml/_internal/store.py", line 83, in list
    raise NotFound(
bentoml.exceptions.NotFound: no Models with name 'user_recommender_model' found

During handling of the above exception, another exception occurred:

Traceback (most recent call last):
  File "/home/airflow/.local/lib/python3.8/site-packages/airflow/models/dagbag.py", line 326, in parse
    loader.exec_module(new_module)
  File "<frozen importlib._bootstrap_external>", line 843, in exec_module
  File "<frozen importlib._bootstrap>", line 219, in _call_with_frames_removed
  File "/opt/airflow/dags/bentoml/user_rec_bento/bento_service_user_rec.py", line 24, in <module>
    runner = bentoml.transformers.get("user_recommender_model:latest").to_runner()
  File "/home/airflow/.local/lib/python3.8/site-packages/bentoml/_internal/frameworks/transformers.py", line 151, in get
    model = bentoml.models.get(tag_like)
  File "/home/airflow/.local/lib/python3.8/site-packages/simple_di/__init__.py", line 139, in _
    return func(*_inject_args(bind.args), **_inject_kwargs(bind.kwargs))
  File "/home/airflow/.local/lib/python3.8/site-packages/bentoml/models.py", line 41, in get
    return _model_store.get(tag)
  File "/home/airflow/.local/lib/python3.8/site-packages/bentoml/_internal/store.py", line 137, in get
    self._recreate_latest(_tag)
  File "/home/airflow/.local/lib/python3.8/site-packages/bentoml/_internal/store.py", line 108, in _recreate_latest
    raise NotFound(
bentoml.exceptions.NotFound: no Models with name 'user_recommender_model' exist in BentoML store <osfs '/home/airflow/bentoml/models'>
[2023-01-19T04:12:40.179+0000] {processor.py:770} WARNING - No viable dags retrieved from /opt/airflow/dags/bentoml/user_rec_bento/bento_service_user_rec.py
[2023-01-19T04:12:40.192+0000] {processor.py:178} INFO - Processing /opt/airflow/dags/bentoml/user_rec_bento/bento_service_user_rec.py took 2.174 seconds
[2023-01-19T04:13:10.720+0000] {processor.py:156} INFO - Started process (PID=4159) to work on /opt/airflow/dags/bentoml/user_rec_bento/bento_service_user_rec.py
[2023-01-19T04:13:10.721+0000] {processor.py:758} INFO - Processing file /opt/airflow/dags/bentoml/user_rec_bento/bento_service_user_rec.py for tasks to queue
[2023-01-19T04:13:10.722+0000] {logging_mixin.py:117} INFO - [2023-01-19T04:13:10.722+0000] {dagbag.py:525} INFO - Filling up the DagBag from /opt/airflow/dags/bentoml/user_rec_bento/bento_service_user_rec.py
[2023-01-19T04:13:12.917+0000] {logging_mixin.py:117} INFO - [2023-01-19T04:13:12.915+0000] {dagbag.py:330} ERROR - Failed to import: /opt/airflow/dags/bentoml/user_rec_bento/bento_service_user_rec.py
Traceback (most recent call last):
  File "/home/airflow/.local/lib/python3.8/site-packages/fs/osfs.py", line 647, in open
    return io.open(
FileNotFoundError: [Errno 2] No such file or directory: b'/home/airflow/bentoml/models/user_recommender_model/latest'

During handling of the above exception, another exception occurred:

Traceback (most recent call last):
  File "/home/airflow/.local/lib/python3.8/site-packages/bentoml/_internal/store.py", line 132, in get
    _tag.version = self._fs.readtext(_tag.latest_path())
  File "/home/airflow/.local/lib/python3.8/site-packages/fs/base.py", line 693, in readtext
    self.open(
  File "/home/airflow/.local/lib/python3.8/site-packages/fs/osfs.py", line 647, in open
    return io.open(
  File "/home/airflow/.local/lib/python3.8/site-packages/fs/error_tools.py", line 89, in __exit__
    reraise(fserror, fserror(self._path, exc=exc_value), traceback)
  File "/home/airflow/.local/lib/python3.8/site-packages/six.py", line 718, in reraise
    raise value.with_traceback(tb)
  File "/home/airflow/.local/lib/python3.8/site-packages/fs/osfs.py", line 647, in open
    return io.open(
fs.errors.ResourceNotFound: resource 'user_recommender_model/latest' not found

During handling of the above exception, another exception occurred:

Traceback (most recent call last):
  File "/home/airflow/.local/lib/python3.8/site-packages/bentoml/_internal/store.py", line 106, in _recreate_latest
    items = self.list(tag.name)
  File "/home/airflow/.local/lib/python3.8/site-packages/bentoml/_internal/store.py", line 83, in list
    raise NotFound(
bentoml.exceptions.NotFound: no Models with name 'user_recommender_model' found

During handling of the above exception, another exception occurred:

Traceback (most recent call last):
  File "/home/airflow/.local/lib/python3.8/site-packages/airflow/models/dagbag.py", line 326, in parse
    loader.exec_module(new_module)
  File "<frozen importlib._bootstrap_external>", line 843, in exec_module
  File "<frozen importlib._bootstrap>", line 219, in _call_with_frames_removed
  File "/opt/airflow/dags/bentoml/user_rec_bento/bento_service_user_rec.py", line 24, in <module>
    runner = bentoml.transformers.get("user_recommender_model:latest").to_runner()
  File "/home/airflow/.local/lib/python3.8/site-packages/bentoml/_internal/frameworks/transformers.py", line 151, in get
    model = bentoml.models.get(tag_like)
  File "/home/airflow/.local/lib/python3.8/site-packages/simple_di/__init__.py", line 139, in _
    return func(*_inject_args(bind.args), **_inject_kwargs(bind.kwargs))
  File "/home/airflow/.local/lib/python3.8/site-packages/bentoml/models.py", line 41, in get
    return _model_store.get(tag)
  File "/home/airflow/.local/lib/python3.8/site-packages/bentoml/_internal/store.py", line 137, in get
    self._recreate_latest(_tag)
  File "/home/airflow/.local/lib/python3.8/site-packages/bentoml/_internal/store.py", line 108, in _recreate_latest
    raise NotFound(
bentoml.exceptions.NotFound: no Models with name 'user_recommender_model' exist in BentoML store <osfs '/home/airflow/bentoml/models'>
[2023-01-19T04:13:12.917+0000] {processor.py:770} WARNING - No viable dags retrieved from /opt/airflow/dags/bentoml/user_rec_bento/bento_service_user_rec.py
[2023-01-19T04:13:12.932+0000] {processor.py:178} INFO - Processing /opt/airflow/dags/bentoml/user_rec_bento/bento_service_user_rec.py took 2.215 seconds
[2023-01-19T04:13:43.912+0000] {processor.py:156} INFO - Started process (PID=4217) to work on /opt/airflow/dags/bentoml/user_rec_bento/bento_service_user_rec.py
[2023-01-19T04:13:43.913+0000] {processor.py:758} INFO - Processing file /opt/airflow/dags/bentoml/user_rec_bento/bento_service_user_rec.py for tasks to queue
[2023-01-19T04:13:43.914+0000] {logging_mixin.py:117} INFO - [2023-01-19T04:13:43.913+0000] {dagbag.py:525} INFO - Filling up the DagBag from /opt/airflow/dags/bentoml/user_rec_bento/bento_service_user_rec.py
[2023-01-19T04:13:46.130+0000] {logging_mixin.py:117} INFO - [2023-01-19T04:13:46.128+0000] {dagbag.py:330} ERROR - Failed to import: /opt/airflow/dags/bentoml/user_rec_bento/bento_service_user_rec.py
Traceback (most recent call last):
  File "/home/airflow/.local/lib/python3.8/site-packages/fs/osfs.py", line 647, in open
    return io.open(
FileNotFoundError: [Errno 2] No such file or directory: b'/home/airflow/bentoml/models/user_recommender_model/latest'

During handling of the above exception, another exception occurred:

Traceback (most recent call last):
  File "/home/airflow/.local/lib/python3.8/site-packages/bentoml/_internal/store.py", line 132, in get
    _tag.version = self._fs.readtext(_tag.latest_path())
  File "/home/airflow/.local/lib/python3.8/site-packages/fs/base.py", line 693, in readtext
    self.open(
  File "/home/airflow/.local/lib/python3.8/site-packages/fs/osfs.py", line 647, in open
    return io.open(
  File "/home/airflow/.local/lib/python3.8/site-packages/fs/error_tools.py", line 89, in __exit__
    reraise(fserror, fserror(self._path, exc=exc_value), traceback)
  File "/home/airflow/.local/lib/python3.8/site-packages/six.py", line 718, in reraise
    raise value.with_traceback(tb)
  File "/home/airflow/.local/lib/python3.8/site-packages/fs/osfs.py", line 647, in open
    return io.open(
fs.errors.ResourceNotFound: resource 'user_recommender_model/latest' not found

During handling of the above exception, another exception occurred:

Traceback (most recent call last):
  File "/home/airflow/.local/lib/python3.8/site-packages/bentoml/_internal/store.py", line 106, in _recreate_latest
    items = self.list(tag.name)
  File "/home/airflow/.local/lib/python3.8/site-packages/bentoml/_internal/store.py", line 83, in list
    raise NotFound(
bentoml.exceptions.NotFound: no Models with name 'user_recommender_model' found

During handling of the above exception, another exception occurred:

Traceback (most recent call last):
  File "/home/airflow/.local/lib/python3.8/site-packages/airflow/models/dagbag.py", line 326, in parse
    loader.exec_module(new_module)
  File "<frozen importlib._bootstrap_external>", line 843, in exec_module
  File "<frozen importlib._bootstrap>", line 219, in _call_with_frames_removed
  File "/opt/airflow/dags/bentoml/user_rec_bento/bento_service_user_rec.py", line 24, in <module>
    runner = bentoml.transformers.get("user_recommender_model:latest").to_runner()
  File "/home/airflow/.local/lib/python3.8/site-packages/bentoml/_internal/frameworks/transformers.py", line 151, in get
    model = bentoml.models.get(tag_like)
  File "/home/airflow/.local/lib/python3.8/site-packages/simple_di/__init__.py", line 139, in _
    return func(*_inject_args(bind.args), **_inject_kwargs(bind.kwargs))
  File "/home/airflow/.local/lib/python3.8/site-packages/bentoml/models.py", line 41, in get
    return _model_store.get(tag)
  File "/home/airflow/.local/lib/python3.8/site-packages/bentoml/_internal/store.py", line 137, in get
    self._recreate_latest(_tag)
  File "/home/airflow/.local/lib/python3.8/site-packages/bentoml/_internal/store.py", line 108, in _recreate_latest
    raise NotFound(
bentoml.exceptions.NotFound: no Models with name 'user_recommender_model' exist in BentoML store <osfs '/home/airflow/bentoml/models'>
[2023-01-19T04:13:46.130+0000] {processor.py:770} WARNING - No viable dags retrieved from /opt/airflow/dags/bentoml/user_rec_bento/bento_service_user_rec.py
[2023-01-19T04:13:46.143+0000] {processor.py:178} INFO - Processing /opt/airflow/dags/bentoml/user_rec_bento/bento_service_user_rec.py took 2.234 seconds
[2023-01-19T04:14:17.128+0000] {processor.py:156} INFO - Started process (PID=4278) to work on /opt/airflow/dags/bentoml/user_rec_bento/bento_service_user_rec.py
[2023-01-19T04:14:17.129+0000] {processor.py:758} INFO - Processing file /opt/airflow/dags/bentoml/user_rec_bento/bento_service_user_rec.py for tasks to queue
[2023-01-19T04:14:17.129+0000] {logging_mixin.py:117} INFO - [2023-01-19T04:14:17.129+0000] {dagbag.py:525} INFO - Filling up the DagBag from /opt/airflow/dags/bentoml/user_rec_bento/bento_service_user_rec.py
[2023-01-19T04:14:19.365+0000] {logging_mixin.py:117} INFO - [2023-01-19T04:14:19.363+0000] {dagbag.py:330} ERROR - Failed to import: /opt/airflow/dags/bentoml/user_rec_bento/bento_service_user_rec.py
Traceback (most recent call last):
  File "/home/airflow/.local/lib/python3.8/site-packages/fs/osfs.py", line 647, in open
    return io.open(
FileNotFoundError: [Errno 2] No such file or directory: b'/home/airflow/bentoml/models/user_recommender_model/latest'

During handling of the above exception, another exception occurred:

Traceback (most recent call last):
  File "/home/airflow/.local/lib/python3.8/site-packages/bentoml/_internal/store.py", line 132, in get
    _tag.version = self._fs.readtext(_tag.latest_path())
  File "/home/airflow/.local/lib/python3.8/site-packages/fs/base.py", line 693, in readtext
    self.open(
  File "/home/airflow/.local/lib/python3.8/site-packages/fs/osfs.py", line 647, in open
    return io.open(
  File "/home/airflow/.local/lib/python3.8/site-packages/fs/error_tools.py", line 89, in __exit__
    reraise(fserror, fserror(self._path, exc=exc_value), traceback)
  File "/home/airflow/.local/lib/python3.8/site-packages/six.py", line 718, in reraise
    raise value.with_traceback(tb)
  File "/home/airflow/.local/lib/python3.8/site-packages/fs/osfs.py", line 647, in open
    return io.open(
fs.errors.ResourceNotFound: resource 'user_recommender_model/latest' not found

During handling of the above exception, another exception occurred:

Traceback (most recent call last):
  File "/home/airflow/.local/lib/python3.8/site-packages/bentoml/_internal/store.py", line 106, in _recreate_latest
    items = self.list(tag.name)
  File "/home/airflow/.local/lib/python3.8/site-packages/bentoml/_internal/store.py", line 83, in list
    raise NotFound(
bentoml.exceptions.NotFound: no Models with name 'user_recommender_model' found

During handling of the above exception, another exception occurred:

Traceback (most recent call last):
  File "/home/airflow/.local/lib/python3.8/site-packages/airflow/models/dagbag.py", line 326, in parse
    loader.exec_module(new_module)
  File "<frozen importlib._bootstrap_external>", line 843, in exec_module
  File "<frozen importlib._bootstrap>", line 219, in _call_with_frames_removed
  File "/opt/airflow/dags/bentoml/user_rec_bento/bento_service_user_rec.py", line 24, in <module>
    runner = bentoml.transformers.get("user_recommender_model:latest").to_runner()
  File "/home/airflow/.local/lib/python3.8/site-packages/bentoml/_internal/frameworks/transformers.py", line 151, in get
    model = bentoml.models.get(tag_like)
  File "/home/airflow/.local/lib/python3.8/site-packages/simple_di/__init__.py", line 139, in _
    return func(*_inject_args(bind.args), **_inject_kwargs(bind.kwargs))
  File "/home/airflow/.local/lib/python3.8/site-packages/bentoml/models.py", line 41, in get
    return _model_store.get(tag)
  File "/home/airflow/.local/lib/python3.8/site-packages/bentoml/_internal/store.py", line 137, in get
    self._recreate_latest(_tag)
  File "/home/airflow/.local/lib/python3.8/site-packages/bentoml/_internal/store.py", line 108, in _recreate_latest
    raise NotFound(
bentoml.exceptions.NotFound: no Models with name 'user_recommender_model' exist in BentoML store <osfs '/home/airflow/bentoml/models'>
[2023-01-19T04:14:19.365+0000] {processor.py:770} WARNING - No viable dags retrieved from /opt/airflow/dags/bentoml/user_rec_bento/bento_service_user_rec.py
[2023-01-19T04:14:19.380+0000] {processor.py:178} INFO - Processing /opt/airflow/dags/bentoml/user_rec_bento/bento_service_user_rec.py took 2.256 seconds
[2023-01-19T04:14:49.551+0000] {processor.py:156} INFO - Started process (PID=4336) to work on /opt/airflow/dags/bentoml/user_rec_bento/bento_service_user_rec.py
[2023-01-19T04:14:49.552+0000] {processor.py:758} INFO - Processing file /opt/airflow/dags/bentoml/user_rec_bento/bento_service_user_rec.py for tasks to queue
[2023-01-19T04:14:49.552+0000] {logging_mixin.py:117} INFO - [2023-01-19T04:14:49.552+0000] {dagbag.py:525} INFO - Filling up the DagBag from /opt/airflow/dags/bentoml/user_rec_bento/bento_service_user_rec.py
[2023-01-19T04:14:51.918+0000] {logging_mixin.py:117} INFO - [2023-01-19T04:14:51.916+0000] {dagbag.py:330} ERROR - Failed to import: /opt/airflow/dags/bentoml/user_rec_bento/bento_service_user_rec.py
Traceback (most recent call last):
  File "/home/airflow/.local/lib/python3.8/site-packages/fs/osfs.py", line 647, in open
    return io.open(
FileNotFoundError: [Errno 2] No such file or directory: b'/home/airflow/bentoml/models/user_recommender_model/latest'

During handling of the above exception, another exception occurred:

Traceback (most recent call last):
  File "/home/airflow/.local/lib/python3.8/site-packages/bentoml/_internal/store.py", line 132, in get
    _tag.version = self._fs.readtext(_tag.latest_path())
  File "/home/airflow/.local/lib/python3.8/site-packages/fs/base.py", line 693, in readtext
    self.open(
  File "/home/airflow/.local/lib/python3.8/site-packages/fs/osfs.py", line 647, in open
    return io.open(
  File "/home/airflow/.local/lib/python3.8/site-packages/fs/error_tools.py", line 89, in __exit__
    reraise(fserror, fserror(self._path, exc=exc_value), traceback)
  File "/home/airflow/.local/lib/python3.8/site-packages/six.py", line 718, in reraise
    raise value.with_traceback(tb)
  File "/home/airflow/.local/lib/python3.8/site-packages/fs/osfs.py", line 647, in open
    return io.open(
fs.errors.ResourceNotFound: resource 'user_recommender_model/latest' not found

During handling of the above exception, another exception occurred:

Traceback (most recent call last):
  File "/home/airflow/.local/lib/python3.8/site-packages/bentoml/_internal/store.py", line 106, in _recreate_latest
    items = self.list(tag.name)
  File "/home/airflow/.local/lib/python3.8/site-packages/bentoml/_internal/store.py", line 83, in list
    raise NotFound(
bentoml.exceptions.NotFound: no Models with name 'user_recommender_model' found

During handling of the above exception, another exception occurred:

Traceback (most recent call last):
  File "/home/airflow/.local/lib/python3.8/site-packages/airflow/models/dagbag.py", line 326, in parse
    loader.exec_module(new_module)
  File "<frozen importlib._bootstrap_external>", line 843, in exec_module
  File "<frozen importlib._bootstrap>", line 219, in _call_with_frames_removed
  File "/opt/airflow/dags/bentoml/user_rec_bento/bento_service_user_rec.py", line 24, in <module>
    runner = bentoml.transformers.get("user_recommender_model:latest").to_runner()
  File "/home/airflow/.local/lib/python3.8/site-packages/bentoml/_internal/frameworks/transformers.py", line 151, in get
    model = bentoml.models.get(tag_like)
  File "/home/airflow/.local/lib/python3.8/site-packages/simple_di/__init__.py", line 139, in _
    return func(*_inject_args(bind.args), **_inject_kwargs(bind.kwargs))
  File "/home/airflow/.local/lib/python3.8/site-packages/bentoml/models.py", line 41, in get
    return _model_store.get(tag)
  File "/home/airflow/.local/lib/python3.8/site-packages/bentoml/_internal/store.py", line 137, in get
    self._recreate_latest(_tag)
  File "/home/airflow/.local/lib/python3.8/site-packages/bentoml/_internal/store.py", line 108, in _recreate_latest
    raise NotFound(
bentoml.exceptions.NotFound: no Models with name 'user_recommender_model' exist in BentoML store <osfs '/home/airflow/bentoml/models'>
[2023-01-19T04:14:51.918+0000] {processor.py:770} WARNING - No viable dags retrieved from /opt/airflow/dags/bentoml/user_rec_bento/bento_service_user_rec.py
[2023-01-19T04:14:51.933+0000] {processor.py:178} INFO - Processing /opt/airflow/dags/bentoml/user_rec_bento/bento_service_user_rec.py took 2.386 seconds
[2023-01-19T04:15:22.041+0000] {processor.py:156} INFO - Started process (PID=4391) to work on /opt/airflow/dags/bentoml/user_rec_bento/bento_service_user_rec.py
[2023-01-19T04:15:22.042+0000] {processor.py:758} INFO - Processing file /opt/airflow/dags/bentoml/user_rec_bento/bento_service_user_rec.py for tasks to queue
[2023-01-19T04:15:22.042+0000] {logging_mixin.py:117} INFO - [2023-01-19T04:15:22.042+0000] {dagbag.py:525} INFO - Filling up the DagBag from /opt/airflow/dags/bentoml/user_rec_bento/bento_service_user_rec.py
[2023-01-19T04:15:24.335+0000] {logging_mixin.py:117} INFO - [2023-01-19T04:15:24.333+0000] {dagbag.py:330} ERROR - Failed to import: /opt/airflow/dags/bentoml/user_rec_bento/bento_service_user_rec.py
Traceback (most recent call last):
  File "/home/airflow/.local/lib/python3.8/site-packages/fs/osfs.py", line 647, in open
    return io.open(
FileNotFoundError: [Errno 2] No such file or directory: b'/home/airflow/bentoml/models/user_recommender_model/latest'

During handling of the above exception, another exception occurred:

Traceback (most recent call last):
  File "/home/airflow/.local/lib/python3.8/site-packages/bentoml/_internal/store.py", line 132, in get
    _tag.version = self._fs.readtext(_tag.latest_path())
  File "/home/airflow/.local/lib/python3.8/site-packages/fs/base.py", line 693, in readtext
    self.open(
  File "/home/airflow/.local/lib/python3.8/site-packages/fs/osfs.py", line 647, in open
    return io.open(
  File "/home/airflow/.local/lib/python3.8/site-packages/fs/error_tools.py", line 89, in __exit__
    reraise(fserror, fserror(self._path, exc=exc_value), traceback)
  File "/home/airflow/.local/lib/python3.8/site-packages/six.py", line 718, in reraise
    raise value.with_traceback(tb)
  File "/home/airflow/.local/lib/python3.8/site-packages/fs/osfs.py", line 647, in open
    return io.open(
fs.errors.ResourceNotFound: resource 'user_recommender_model/latest' not found

During handling of the above exception, another exception occurred:

Traceback (most recent call last):
  File "/home/airflow/.local/lib/python3.8/site-packages/bentoml/_internal/store.py", line 106, in _recreate_latest
    items = self.list(tag.name)
  File "/home/airflow/.local/lib/python3.8/site-packages/bentoml/_internal/store.py", line 83, in list
    raise NotFound(
bentoml.exceptions.NotFound: no Models with name 'user_recommender_model' found

During handling of the above exception, another exception occurred:

Traceback (most recent call last):
  File "/home/airflow/.local/lib/python3.8/site-packages/airflow/models/dagbag.py", line 326, in parse
    loader.exec_module(new_module)
  File "<frozen importlib._bootstrap_external>", line 843, in exec_module
  File "<frozen importlib._bootstrap>", line 219, in _call_with_frames_removed
  File "/opt/airflow/dags/bentoml/user_rec_bento/bento_service_user_rec.py", line 24, in <module>
    runner = bentoml.transformers.get("user_recommender_model:latest").to_runner()
  File "/home/airflow/.local/lib/python3.8/site-packages/bentoml/_internal/frameworks/transformers.py", line 151, in get
    model = bentoml.models.get(tag_like)
  File "/home/airflow/.local/lib/python3.8/site-packages/simple_di/__init__.py", line 139, in _
    return func(*_inject_args(bind.args), **_inject_kwargs(bind.kwargs))
  File "/home/airflow/.local/lib/python3.8/site-packages/bentoml/models.py", line 41, in get
    return _model_store.get(tag)
  File "/home/airflow/.local/lib/python3.8/site-packages/bentoml/_internal/store.py", line 137, in get
    self._recreate_latest(_tag)
  File "/home/airflow/.local/lib/python3.8/site-packages/bentoml/_internal/store.py", line 108, in _recreate_latest
    raise NotFound(
bentoml.exceptions.NotFound: no Models with name 'user_recommender_model' exist in BentoML store <osfs '/home/airflow/bentoml/models'>
[2023-01-19T04:15:24.335+0000] {processor.py:770} WARNING - No viable dags retrieved from /opt/airflow/dags/bentoml/user_rec_bento/bento_service_user_rec.py
[2023-01-19T04:15:24.348+0000] {processor.py:178} INFO - Processing /opt/airflow/dags/bentoml/user_rec_bento/bento_service_user_rec.py took 2.310 seconds
[2023-01-19T04:15:54.553+0000] {processor.py:156} INFO - Started process (PID=4449) to work on /opt/airflow/dags/bentoml/user_rec_bento/bento_service_user_rec.py
[2023-01-19T04:15:54.554+0000] {processor.py:758} INFO - Processing file /opt/airflow/dags/bentoml/user_rec_bento/bento_service_user_rec.py for tasks to queue
[2023-01-19T04:15:54.554+0000] {logging_mixin.py:117} INFO - [2023-01-19T04:15:54.554+0000] {dagbag.py:525} INFO - Filling up the DagBag from /opt/airflow/dags/bentoml/user_rec_bento/bento_service_user_rec.py
[2023-01-19T04:15:56.843+0000] {logging_mixin.py:117} INFO - [2023-01-19T04:15:56.841+0000] {dagbag.py:330} ERROR - Failed to import: /opt/airflow/dags/bentoml/user_rec_bento/bento_service_user_rec.py
Traceback (most recent call last):
  File "/home/airflow/.local/lib/python3.8/site-packages/fs/osfs.py", line 647, in open
    return io.open(
FileNotFoundError: [Errno 2] No such file or directory: b'/home/airflow/bentoml/models/user_recommender_model/latest'

During handling of the above exception, another exception occurred:

Traceback (most recent call last):
  File "/home/airflow/.local/lib/python3.8/site-packages/bentoml/_internal/store.py", line 132, in get
    _tag.version = self._fs.readtext(_tag.latest_path())
  File "/home/airflow/.local/lib/python3.8/site-packages/fs/base.py", line 693, in readtext
    self.open(
  File "/home/airflow/.local/lib/python3.8/site-packages/fs/osfs.py", line 647, in open
    return io.open(
  File "/home/airflow/.local/lib/python3.8/site-packages/fs/error_tools.py", line 89, in __exit__
    reraise(fserror, fserror(self._path, exc=exc_value), traceback)
  File "/home/airflow/.local/lib/python3.8/site-packages/six.py", line 718, in reraise
    raise value.with_traceback(tb)
  File "/home/airflow/.local/lib/python3.8/site-packages/fs/osfs.py", line 647, in open
    return io.open(
fs.errors.ResourceNotFound: resource 'user_recommender_model/latest' not found

During handling of the above exception, another exception occurred:

Traceback (most recent call last):
  File "/home/airflow/.local/lib/python3.8/site-packages/bentoml/_internal/store.py", line 106, in _recreate_latest
    items = self.list(tag.name)
  File "/home/airflow/.local/lib/python3.8/site-packages/bentoml/_internal/store.py", line 83, in list
    raise NotFound(
bentoml.exceptions.NotFound: no Models with name 'user_recommender_model' found

During handling of the above exception, another exception occurred:

Traceback (most recent call last):
  File "/home/airflow/.local/lib/python3.8/site-packages/airflow/models/dagbag.py", line 326, in parse
    loader.exec_module(new_module)
  File "<frozen importlib._bootstrap_external>", line 843, in exec_module
  File "<frozen importlib._bootstrap>", line 219, in _call_with_frames_removed
  File "/opt/airflow/dags/bentoml/user_rec_bento/bento_service_user_rec.py", line 24, in <module>
    runner = bentoml.transformers.get("user_recommender_model:latest").to_runner()
  File "/home/airflow/.local/lib/python3.8/site-packages/bentoml/_internal/frameworks/transformers.py", line 151, in get
    model = bentoml.models.get(tag_like)
  File "/home/airflow/.local/lib/python3.8/site-packages/simple_di/__init__.py", line 139, in _
    return func(*_inject_args(bind.args), **_inject_kwargs(bind.kwargs))
  File "/home/airflow/.local/lib/python3.8/site-packages/bentoml/models.py", line 41, in get
    return _model_store.get(tag)
  File "/home/airflow/.local/lib/python3.8/site-packages/bentoml/_internal/store.py", line 137, in get
    self._recreate_latest(_tag)
  File "/home/airflow/.local/lib/python3.8/site-packages/bentoml/_internal/store.py", line 108, in _recreate_latest
    raise NotFound(
bentoml.exceptions.NotFound: no Models with name 'user_recommender_model' exist in BentoML store <osfs '/home/airflow/bentoml/models'>
[2023-01-19T04:15:56.844+0000] {processor.py:770} WARNING - No viable dags retrieved from /opt/airflow/dags/bentoml/user_rec_bento/bento_service_user_rec.py
[2023-01-19T04:15:56.857+0000] {processor.py:178} INFO - Processing /opt/airflow/dags/bentoml/user_rec_bento/bento_service_user_rec.py took 2.307 seconds
[2023-01-19T04:16:26.933+0000] {processor.py:156} INFO - Started process (PID=4507) to work on /opt/airflow/dags/bentoml/user_rec_bento/bento_service_user_rec.py
[2023-01-19T04:16:26.935+0000] {processor.py:758} INFO - Processing file /opt/airflow/dags/bentoml/user_rec_bento/bento_service_user_rec.py for tasks to queue
[2023-01-19T04:16:26.935+0000] {logging_mixin.py:117} INFO - [2023-01-19T04:16:26.935+0000] {dagbag.py:525} INFO - Filling up the DagBag from /opt/airflow/dags/bentoml/user_rec_bento/bento_service_user_rec.py
[2023-01-19T04:16:29.409+0000] {logging_mixin.py:117} INFO - [2023-01-19T04:16:29.407+0000] {dagbag.py:330} ERROR - Failed to import: /opt/airflow/dags/bentoml/user_rec_bento/bento_service_user_rec.py
Traceback (most recent call last):
  File "/home/airflow/.local/lib/python3.8/site-packages/fs/osfs.py", line 647, in open
    return io.open(
FileNotFoundError: [Errno 2] No such file or directory: b'/home/airflow/bentoml/models/user_recommender_model/latest'

During handling of the above exception, another exception occurred:

Traceback (most recent call last):
  File "/home/airflow/.local/lib/python3.8/site-packages/bentoml/_internal/store.py", line 132, in get
    _tag.version = self._fs.readtext(_tag.latest_path())
  File "/home/airflow/.local/lib/python3.8/site-packages/fs/base.py", line 693, in readtext
    self.open(
  File "/home/airflow/.local/lib/python3.8/site-packages/fs/osfs.py", line 647, in open
    return io.open(
  File "/home/airflow/.local/lib/python3.8/site-packages/fs/error_tools.py", line 89, in __exit__
    reraise(fserror, fserror(self._path, exc=exc_value), traceback)
  File "/home/airflow/.local/lib/python3.8/site-packages/six.py", line 718, in reraise
    raise value.with_traceback(tb)
  File "/home/airflow/.local/lib/python3.8/site-packages/fs/osfs.py", line 647, in open
    return io.open(
fs.errors.ResourceNotFound: resource 'user_recommender_model/latest' not found

During handling of the above exception, another exception occurred:

Traceback (most recent call last):
  File "/home/airflow/.local/lib/python3.8/site-packages/bentoml/_internal/store.py", line 106, in _recreate_latest
    items = self.list(tag.name)
  File "/home/airflow/.local/lib/python3.8/site-packages/bentoml/_internal/store.py", line 83, in list
    raise NotFound(
bentoml.exceptions.NotFound: no Models with name 'user_recommender_model' found

During handling of the above exception, another exception occurred:

Traceback (most recent call last):
  File "/home/airflow/.local/lib/python3.8/site-packages/airflow/models/dagbag.py", line 326, in parse
    loader.exec_module(new_module)
  File "<frozen importlib._bootstrap_external>", line 843, in exec_module
  File "<frozen importlib._bootstrap>", line 219, in _call_with_frames_removed
  File "/opt/airflow/dags/bentoml/user_rec_bento/bento_service_user_rec.py", line 24, in <module>
    runner = bentoml.transformers.get("user_recommender_model:latest").to_runner()
  File "/home/airflow/.local/lib/python3.8/site-packages/bentoml/_internal/frameworks/transformers.py", line 151, in get
    model = bentoml.models.get(tag_like)
  File "/home/airflow/.local/lib/python3.8/site-packages/simple_di/__init__.py", line 139, in _
    return func(*_inject_args(bind.args), **_inject_kwargs(bind.kwargs))
  File "/home/airflow/.local/lib/python3.8/site-packages/bentoml/models.py", line 41, in get
    return _model_store.get(tag)
  File "/home/airflow/.local/lib/python3.8/site-packages/bentoml/_internal/store.py", line 137, in get
    self._recreate_latest(_tag)
  File "/home/airflow/.local/lib/python3.8/site-packages/bentoml/_internal/store.py", line 108, in _recreate_latest
    raise NotFound(
bentoml.exceptions.NotFound: no Models with name 'user_recommender_model' exist in BentoML store <osfs '/home/airflow/bentoml/models'>
[2023-01-19T04:16:29.409+0000] {processor.py:770} WARNING - No viable dags retrieved from /opt/airflow/dags/bentoml/user_rec_bento/bento_service_user_rec.py
[2023-01-19T04:16:29.423+0000] {processor.py:178} INFO - Processing /opt/airflow/dags/bentoml/user_rec_bento/bento_service_user_rec.py took 2.493 seconds
[2023-01-19T04:16:59.539+0000] {processor.py:156} INFO - Started process (PID=4565) to work on /opt/airflow/dags/bentoml/user_rec_bento/bento_service_user_rec.py
[2023-01-19T04:16:59.539+0000] {processor.py:758} INFO - Processing file /opt/airflow/dags/bentoml/user_rec_bento/bento_service_user_rec.py for tasks to queue
[2023-01-19T04:16:59.540+0000] {logging_mixin.py:117} INFO - [2023-01-19T04:16:59.540+0000] {dagbag.py:525} INFO - Filling up the DagBag from /opt/airflow/dags/bentoml/user_rec_bento/bento_service_user_rec.py
[2023-01-19T04:17:01.878+0000] {logging_mixin.py:117} INFO - [2023-01-19T04:17:01.876+0000] {dagbag.py:330} ERROR - Failed to import: /opt/airflow/dags/bentoml/user_rec_bento/bento_service_user_rec.py
Traceback (most recent call last):
  File "/home/airflow/.local/lib/python3.8/site-packages/fs/osfs.py", line 647, in open
    return io.open(
FileNotFoundError: [Errno 2] No such file or directory: b'/home/airflow/bentoml/models/user_recommender_model/latest'

During handling of the above exception, another exception occurred:

Traceback (most recent call last):
  File "/home/airflow/.local/lib/python3.8/site-packages/bentoml/_internal/store.py", line 132, in get
    _tag.version = self._fs.readtext(_tag.latest_path())
  File "/home/airflow/.local/lib/python3.8/site-packages/fs/base.py", line 693, in readtext
    self.open(
  File "/home/airflow/.local/lib/python3.8/site-packages/fs/osfs.py", line 647, in open
    return io.open(
  File "/home/airflow/.local/lib/python3.8/site-packages/fs/error_tools.py", line 89, in __exit__
    reraise(fserror, fserror(self._path, exc=exc_value), traceback)
  File "/home/airflow/.local/lib/python3.8/site-packages/six.py", line 718, in reraise
    raise value.with_traceback(tb)
  File "/home/airflow/.local/lib/python3.8/site-packages/fs/osfs.py", line 647, in open
    return io.open(
fs.errors.ResourceNotFound: resource 'user_recommender_model/latest' not found

During handling of the above exception, another exception occurred:

Traceback (most recent call last):
  File "/home/airflow/.local/lib/python3.8/site-packages/bentoml/_internal/store.py", line 106, in _recreate_latest
    items = self.list(tag.name)
  File "/home/airflow/.local/lib/python3.8/site-packages/bentoml/_internal/store.py", line 83, in list
    raise NotFound(
bentoml.exceptions.NotFound: no Models with name 'user_recommender_model' found

During handling of the above exception, another exception occurred:

Traceback (most recent call last):
  File "/home/airflow/.local/lib/python3.8/site-packages/airflow/models/dagbag.py", line 326, in parse
    loader.exec_module(new_module)
  File "<frozen importlib._bootstrap_external>", line 843, in exec_module
  File "<frozen importlib._bootstrap>", line 219, in _call_with_frames_removed
  File "/opt/airflow/dags/bentoml/user_rec_bento/bento_service_user_rec.py", line 24, in <module>
    runner = bentoml.transformers.get("user_recommender_model:latest").to_runner()
  File "/home/airflow/.local/lib/python3.8/site-packages/bentoml/_internal/frameworks/transformers.py", line 151, in get
    model = bentoml.models.get(tag_like)
  File "/home/airflow/.local/lib/python3.8/site-packages/simple_di/__init__.py", line 139, in _
    return func(*_inject_args(bind.args), **_inject_kwargs(bind.kwargs))
  File "/home/airflow/.local/lib/python3.8/site-packages/bentoml/models.py", line 41, in get
    return _model_store.get(tag)
  File "/home/airflow/.local/lib/python3.8/site-packages/bentoml/_internal/store.py", line 137, in get
    self._recreate_latest(_tag)
  File "/home/airflow/.local/lib/python3.8/site-packages/bentoml/_internal/store.py", line 108, in _recreate_latest
    raise NotFound(
bentoml.exceptions.NotFound: no Models with name 'user_recommender_model' exist in BentoML store <osfs '/home/airflow/bentoml/models'>
[2023-01-19T04:17:01.878+0000] {processor.py:770} WARNING - No viable dags retrieved from /opt/airflow/dags/bentoml/user_rec_bento/bento_service_user_rec.py
[2023-01-19T04:17:01.891+0000] {processor.py:178} INFO - Processing /opt/airflow/dags/bentoml/user_rec_bento/bento_service_user_rec.py took 2.356 seconds
[2023-01-19T04:17:32.159+0000] {processor.py:156} INFO - Started process (PID=4623) to work on /opt/airflow/dags/bentoml/user_rec_bento/bento_service_user_rec.py
[2023-01-19T04:17:32.159+0000] {processor.py:758} INFO - Processing file /opt/airflow/dags/bentoml/user_rec_bento/bento_service_user_rec.py for tasks to queue
[2023-01-19T04:17:32.160+0000] {logging_mixin.py:117} INFO - [2023-01-19T04:17:32.160+0000] {dagbag.py:525} INFO - Filling up the DagBag from /opt/airflow/dags/bentoml/user_rec_bento/bento_service_user_rec.py
[2023-01-19T04:17:34.441+0000] {logging_mixin.py:117} INFO - [2023-01-19T04:17:34.439+0000] {dagbag.py:330} ERROR - Failed to import: /opt/airflow/dags/bentoml/user_rec_bento/bento_service_user_rec.py
Traceback (most recent call last):
  File "/home/airflow/.local/lib/python3.8/site-packages/fs/osfs.py", line 647, in open
    return io.open(
FileNotFoundError: [Errno 2] No such file or directory: b'/home/airflow/bentoml/models/user_recommender_model/latest'

During handling of the above exception, another exception occurred:

Traceback (most recent call last):
  File "/home/airflow/.local/lib/python3.8/site-packages/bentoml/_internal/store.py", line 132, in get
    _tag.version = self._fs.readtext(_tag.latest_path())
  File "/home/airflow/.local/lib/python3.8/site-packages/fs/base.py", line 693, in readtext
    self.open(
  File "/home/airflow/.local/lib/python3.8/site-packages/fs/osfs.py", line 647, in open
    return io.open(
  File "/home/airflow/.local/lib/python3.8/site-packages/fs/error_tools.py", line 89, in __exit__
    reraise(fserror, fserror(self._path, exc=exc_value), traceback)
  File "/home/airflow/.local/lib/python3.8/site-packages/six.py", line 718, in reraise
    raise value.with_traceback(tb)
  File "/home/airflow/.local/lib/python3.8/site-packages/fs/osfs.py", line 647, in open
    return io.open(
fs.errors.ResourceNotFound: resource 'user_recommender_model/latest' not found

During handling of the above exception, another exception occurred:

Traceback (most recent call last):
  File "/home/airflow/.local/lib/python3.8/site-packages/bentoml/_internal/store.py", line 106, in _recreate_latest
    items = self.list(tag.name)
  File "/home/airflow/.local/lib/python3.8/site-packages/bentoml/_internal/store.py", line 83, in list
    raise NotFound(
bentoml.exceptions.NotFound: no Models with name 'user_recommender_model' found

During handling of the above exception, another exception occurred:

Traceback (most recent call last):
  File "/home/airflow/.local/lib/python3.8/site-packages/airflow/models/dagbag.py", line 326, in parse
    loader.exec_module(new_module)
  File "<frozen importlib._bootstrap_external>", line 843, in exec_module
  File "<frozen importlib._bootstrap>", line 219, in _call_with_frames_removed
  File "/opt/airflow/dags/bentoml/user_rec_bento/bento_service_user_rec.py", line 24, in <module>
    runner = bentoml.transformers.get("user_recommender_model:latest").to_runner()
  File "/home/airflow/.local/lib/python3.8/site-packages/bentoml/_internal/frameworks/transformers.py", line 151, in get
    model = bentoml.models.get(tag_like)
  File "/home/airflow/.local/lib/python3.8/site-packages/simple_di/__init__.py", line 139, in _
    return func(*_inject_args(bind.args), **_inject_kwargs(bind.kwargs))
  File "/home/airflow/.local/lib/python3.8/site-packages/bentoml/models.py", line 41, in get
    return _model_store.get(tag)
  File "/home/airflow/.local/lib/python3.8/site-packages/bentoml/_internal/store.py", line 137, in get
    self._recreate_latest(_tag)
  File "/home/airflow/.local/lib/python3.8/site-packages/bentoml/_internal/store.py", line 108, in _recreate_latest
    raise NotFound(
bentoml.exceptions.NotFound: no Models with name 'user_recommender_model' exist in BentoML store <osfs '/home/airflow/bentoml/models'>
[2023-01-19T04:17:34.442+0000] {processor.py:770} WARNING - No viable dags retrieved from /opt/airflow/dags/bentoml/user_rec_bento/bento_service_user_rec.py
[2023-01-19T04:17:34.458+0000] {processor.py:178} INFO - Processing /opt/airflow/dags/bentoml/user_rec_bento/bento_service_user_rec.py took 2.303 seconds
[2023-01-19T04:18:04.716+0000] {processor.py:156} INFO - Started process (PID=4681) to work on /opt/airflow/dags/bentoml/user_rec_bento/bento_service_user_rec.py
[2023-01-19T04:18:04.717+0000] {processor.py:758} INFO - Processing file /opt/airflow/dags/bentoml/user_rec_bento/bento_service_user_rec.py for tasks to queue
[2023-01-19T04:18:04.718+0000] {logging_mixin.py:117} INFO - [2023-01-19T04:18:04.717+0000] {dagbag.py:525} INFO - Filling up the DagBag from /opt/airflow/dags/bentoml/user_rec_bento/bento_service_user_rec.py
[2023-01-19T04:18:06.968+0000] {logging_mixin.py:117} INFO - [2023-01-19T04:18:06.966+0000] {dagbag.py:330} ERROR - Failed to import: /opt/airflow/dags/bentoml/user_rec_bento/bento_service_user_rec.py
Traceback (most recent call last):
  File "/home/airflow/.local/lib/python3.8/site-packages/fs/osfs.py", line 647, in open
    return io.open(
FileNotFoundError: [Errno 2] No such file or directory: b'/home/airflow/bentoml/models/user_recommender_model/latest'

During handling of the above exception, another exception occurred:

Traceback (most recent call last):
  File "/home/airflow/.local/lib/python3.8/site-packages/bentoml/_internal/store.py", line 132, in get
    _tag.version = self._fs.readtext(_tag.latest_path())
  File "/home/airflow/.local/lib/python3.8/site-packages/fs/base.py", line 693, in readtext
    self.open(
  File "/home/airflow/.local/lib/python3.8/site-packages/fs/osfs.py", line 647, in open
    return io.open(
  File "/home/airflow/.local/lib/python3.8/site-packages/fs/error_tools.py", line 89, in __exit__
    reraise(fserror, fserror(self._path, exc=exc_value), traceback)
  File "/home/airflow/.local/lib/python3.8/site-packages/six.py", line 718, in reraise
    raise value.with_traceback(tb)
  File "/home/airflow/.local/lib/python3.8/site-packages/fs/osfs.py", line 647, in open
    return io.open(
fs.errors.ResourceNotFound: resource 'user_recommender_model/latest' not found

During handling of the above exception, another exception occurred:

Traceback (most recent call last):
  File "/home/airflow/.local/lib/python3.8/site-packages/bentoml/_internal/store.py", line 106, in _recreate_latest
    items = self.list(tag.name)
  File "/home/airflow/.local/lib/python3.8/site-packages/bentoml/_internal/store.py", line 83, in list
    raise NotFound(
bentoml.exceptions.NotFound: no Models with name 'user_recommender_model' found

During handling of the above exception, another exception occurred:

Traceback (most recent call last):
  File "/home/airflow/.local/lib/python3.8/site-packages/airflow/models/dagbag.py", line 326, in parse
    loader.exec_module(new_module)
  File "<frozen importlib._bootstrap_external>", line 843, in exec_module
  File "<frozen importlib._bootstrap>", line 219, in _call_with_frames_removed
  File "/opt/airflow/dags/bentoml/user_rec_bento/bento_service_user_rec.py", line 24, in <module>
    runner = bentoml.transformers.get("user_recommender_model:latest").to_runner()
  File "/home/airflow/.local/lib/python3.8/site-packages/bentoml/_internal/frameworks/transformers.py", line 151, in get
    model = bentoml.models.get(tag_like)
  File "/home/airflow/.local/lib/python3.8/site-packages/simple_di/__init__.py", line 139, in _
    return func(*_inject_args(bind.args), **_inject_kwargs(bind.kwargs))
  File "/home/airflow/.local/lib/python3.8/site-packages/bentoml/models.py", line 41, in get
    return _model_store.get(tag)
  File "/home/airflow/.local/lib/python3.8/site-packages/bentoml/_internal/store.py", line 137, in get
    self._recreate_latest(_tag)
  File "/home/airflow/.local/lib/python3.8/site-packages/bentoml/_internal/store.py", line 108, in _recreate_latest
    raise NotFound(
bentoml.exceptions.NotFound: no Models with name 'user_recommender_model' exist in BentoML store <osfs '/home/airflow/bentoml/models'>
[2023-01-19T04:18:06.969+0000] {processor.py:770} WARNING - No viable dags retrieved from /opt/airflow/dags/bentoml/user_rec_bento/bento_service_user_rec.py
[2023-01-19T04:18:06.981+0000] {processor.py:178} INFO - Processing /opt/airflow/dags/bentoml/user_rec_bento/bento_service_user_rec.py took 2.269 seconds
[2023-01-19T04:18:37.120+0000] {processor.py:156} INFO - Started process (PID=4739) to work on /opt/airflow/dags/bentoml/user_rec_bento/bento_service_user_rec.py
[2023-01-19T04:18:37.120+0000] {processor.py:758} INFO - Processing file /opt/airflow/dags/bentoml/user_rec_bento/bento_service_user_rec.py for tasks to queue
[2023-01-19T04:18:37.121+0000] {logging_mixin.py:117} INFO - [2023-01-19T04:18:37.121+0000] {dagbag.py:525} INFO - Filling up the DagBag from /opt/airflow/dags/bentoml/user_rec_bento/bento_service_user_rec.py
[2023-01-19T04:18:39.480+0000] {logging_mixin.py:117} INFO - [2023-01-19T04:18:39.479+0000] {dagbag.py:330} ERROR - Failed to import: /opt/airflow/dags/bentoml/user_rec_bento/bento_service_user_rec.py
Traceback (most recent call last):
  File "/home/airflow/.local/lib/python3.8/site-packages/fs/osfs.py", line 647, in open
    return io.open(
FileNotFoundError: [Errno 2] No such file or directory: b'/home/airflow/bentoml/models/user_recommender_model/latest'

During handling of the above exception, another exception occurred:

Traceback (most recent call last):
  File "/home/airflow/.local/lib/python3.8/site-packages/bentoml/_internal/store.py", line 132, in get
    _tag.version = self._fs.readtext(_tag.latest_path())
  File "/home/airflow/.local/lib/python3.8/site-packages/fs/base.py", line 693, in readtext
    self.open(
  File "/home/airflow/.local/lib/python3.8/site-packages/fs/osfs.py", line 647, in open
    return io.open(
  File "/home/airflow/.local/lib/python3.8/site-packages/fs/error_tools.py", line 89, in __exit__
    reraise(fserror, fserror(self._path, exc=exc_value), traceback)
  File "/home/airflow/.local/lib/python3.8/site-packages/six.py", line 718, in reraise
    raise value.with_traceback(tb)
  File "/home/airflow/.local/lib/python3.8/site-packages/fs/osfs.py", line 647, in open
    return io.open(
fs.errors.ResourceNotFound: resource 'user_recommender_model/latest' not found

During handling of the above exception, another exception occurred:

Traceback (most recent call last):
  File "/home/airflow/.local/lib/python3.8/site-packages/bentoml/_internal/store.py", line 106, in _recreate_latest
    items = self.list(tag.name)
  File "/home/airflow/.local/lib/python3.8/site-packages/bentoml/_internal/store.py", line 83, in list
    raise NotFound(
bentoml.exceptions.NotFound: no Models with name 'user_recommender_model' found

During handling of the above exception, another exception occurred:

Traceback (most recent call last):
  File "/home/airflow/.local/lib/python3.8/site-packages/airflow/models/dagbag.py", line 326, in parse
    loader.exec_module(new_module)
  File "<frozen importlib._bootstrap_external>", line 843, in exec_module
  File "<frozen importlib._bootstrap>", line 219, in _call_with_frames_removed
  File "/opt/airflow/dags/bentoml/user_rec_bento/bento_service_user_rec.py", line 24, in <module>
    runner = bentoml.transformers.get("user_recommender_model:latest").to_runner()
  File "/home/airflow/.local/lib/python3.8/site-packages/bentoml/_internal/frameworks/transformers.py", line 151, in get
    model = bentoml.models.get(tag_like)
  File "/home/airflow/.local/lib/python3.8/site-packages/simple_di/__init__.py", line 139, in _
    return func(*_inject_args(bind.args), **_inject_kwargs(bind.kwargs))
  File "/home/airflow/.local/lib/python3.8/site-packages/bentoml/models.py", line 41, in get
    return _model_store.get(tag)
  File "/home/airflow/.local/lib/python3.8/site-packages/bentoml/_internal/store.py", line 137, in get
    self._recreate_latest(_tag)
  File "/home/airflow/.local/lib/python3.8/site-packages/bentoml/_internal/store.py", line 108, in _recreate_latest
    raise NotFound(
bentoml.exceptions.NotFound: no Models with name 'user_recommender_model' exist in BentoML store <osfs '/home/airflow/bentoml/models'>
[2023-01-19T04:18:39.481+0000] {processor.py:770} WARNING - No viable dags retrieved from /opt/airflow/dags/bentoml/user_rec_bento/bento_service_user_rec.py
[2023-01-19T04:18:39.496+0000] {processor.py:178} INFO - Processing /opt/airflow/dags/bentoml/user_rec_bento/bento_service_user_rec.py took 2.379 seconds
[2023-01-19T04:19:09.609+0000] {processor.py:156} INFO - Started process (PID=4795) to work on /opt/airflow/dags/bentoml/user_rec_bento/bento_service_user_rec.py
[2023-01-19T04:19:09.610+0000] {processor.py:758} INFO - Processing file /opt/airflow/dags/bentoml/user_rec_bento/bento_service_user_rec.py for tasks to queue
[2023-01-19T04:19:09.610+0000] {logging_mixin.py:117} INFO - [2023-01-19T04:19:09.610+0000] {dagbag.py:525} INFO - Filling up the DagBag from /opt/airflow/dags/bentoml/user_rec_bento/bento_service_user_rec.py
[2023-01-19T04:19:11.886+0000] {logging_mixin.py:117} INFO - [2023-01-19T04:19:11.884+0000] {dagbag.py:330} ERROR - Failed to import: /opt/airflow/dags/bentoml/user_rec_bento/bento_service_user_rec.py
Traceback (most recent call last):
  File "/home/airflow/.local/lib/python3.8/site-packages/fs/osfs.py", line 647, in open
    return io.open(
FileNotFoundError: [Errno 2] No such file or directory: b'/home/airflow/bentoml/models/user_recommender_model/latest'

During handling of the above exception, another exception occurred:

Traceback (most recent call last):
  File "/home/airflow/.local/lib/python3.8/site-packages/bentoml/_internal/store.py", line 132, in get
    _tag.version = self._fs.readtext(_tag.latest_path())
  File "/home/airflow/.local/lib/python3.8/site-packages/fs/base.py", line 693, in readtext
    self.open(
  File "/home/airflow/.local/lib/python3.8/site-packages/fs/osfs.py", line 647, in open
    return io.open(
  File "/home/airflow/.local/lib/python3.8/site-packages/fs/error_tools.py", line 89, in __exit__
    reraise(fserror, fserror(self._path, exc=exc_value), traceback)
  File "/home/airflow/.local/lib/python3.8/site-packages/six.py", line 718, in reraise
    raise value.with_traceback(tb)
  File "/home/airflow/.local/lib/python3.8/site-packages/fs/osfs.py", line 647, in open
    return io.open(
fs.errors.ResourceNotFound: resource 'user_recommender_model/latest' not found

During handling of the above exception, another exception occurred:

Traceback (most recent call last):
  File "/home/airflow/.local/lib/python3.8/site-packages/bentoml/_internal/store.py", line 106, in _recreate_latest
    items = self.list(tag.name)
  File "/home/airflow/.local/lib/python3.8/site-packages/bentoml/_internal/store.py", line 83, in list
    raise NotFound(
bentoml.exceptions.NotFound: no Models with name 'user_recommender_model' found

During handling of the above exception, another exception occurred:

Traceback (most recent call last):
  File "/home/airflow/.local/lib/python3.8/site-packages/airflow/models/dagbag.py", line 326, in parse
    loader.exec_module(new_module)
  File "<frozen importlib._bootstrap_external>", line 843, in exec_module
  File "<frozen importlib._bootstrap>", line 219, in _call_with_frames_removed
  File "/opt/airflow/dags/bentoml/user_rec_bento/bento_service_user_rec.py", line 24, in <module>
    runner = bentoml.transformers.get("user_recommender_model:latest").to_runner()
  File "/home/airflow/.local/lib/python3.8/site-packages/bentoml/_internal/frameworks/transformers.py", line 151, in get
    model = bentoml.models.get(tag_like)
  File "/home/airflow/.local/lib/python3.8/site-packages/simple_di/__init__.py", line 139, in _
    return func(*_inject_args(bind.args), **_inject_kwargs(bind.kwargs))
  File "/home/airflow/.local/lib/python3.8/site-packages/bentoml/models.py", line 41, in get
    return _model_store.get(tag)
  File "/home/airflow/.local/lib/python3.8/site-packages/bentoml/_internal/store.py", line 137, in get
    self._recreate_latest(_tag)
  File "/home/airflow/.local/lib/python3.8/site-packages/bentoml/_internal/store.py", line 108, in _recreate_latest
    raise NotFound(
bentoml.exceptions.NotFound: no Models with name 'user_recommender_model' exist in BentoML store <osfs '/home/airflow/bentoml/models'>
[2023-01-19T04:19:11.887+0000] {processor.py:770} WARNING - No viable dags retrieved from /opt/airflow/dags/bentoml/user_rec_bento/bento_service_user_rec.py
[2023-01-19T04:19:11.902+0000] {processor.py:178} INFO - Processing /opt/airflow/dags/bentoml/user_rec_bento/bento_service_user_rec.py took 2.295 seconds
