[2023-01-19T04:10:10.815+0000] {processor.py:156} INFO - Started process (PID=3834) to work on /opt/airflow/dags/bentoml/user_to_pik_rec_bento/bento_service_user_to_pik_rec.py
[2023-01-19T04:10:10.815+0000] {processor.py:758} INFO - Processing file /opt/airflow/dags/bentoml/user_to_pik_rec_bento/bento_service_user_to_pik_rec.py for tasks to queue
[2023-01-19T04:10:10.816+0000] {logging_mixin.py:117} INFO - [2023-01-19T04:10:10.816+0000] {dagbag.py:525} INFO - Filling up the DagBag from /opt/airflow/dags/bentoml/user_to_pik_rec_bento/bento_service_user_to_pik_rec.py
[2023-01-19T04:10:13.120+0000] {logging_mixin.py:117} INFO - [2023-01-19T04:10:13.119+0000] {dagbag.py:330} ERROR - Failed to import: /opt/airflow/dags/bentoml/user_to_pik_rec_bento/bento_service_user_to_pik_rec.py
Traceback (most recent call last):
  File "/home/airflow/.local/lib/python3.8/site-packages/fs/osfs.py", line 647, in open
    return io.open(
FileNotFoundError: [Errno 2] No such file or directory: b'/home/airflow/bentoml/models/user_to_pik_recommender_model/latest'

During handling of the above exception, another exception occurred:

Traceback (most recent call last):
  File "/home/airflow/.local/lib/python3.8/site-packages/bentoml/_internal/store.py", line 132, in get
    _tag.version = self._fs.readtext(_tag.latest_path())
  File "/home/airflow/.local/lib/python3.8/site-packages/fs/base.py", line 693, in readtext
    self.open(
  File "/home/airflow/.local/lib/python3.8/site-packages/fs/osfs.py", line 647, in open
    return io.open(
  File "/home/airflow/.local/lib/python3.8/site-packages/fs/error_tools.py", line 89, in __exit__
    reraise(fserror, fserror(self._path, exc=exc_value), traceback)
  File "/home/airflow/.local/lib/python3.8/site-packages/six.py", line 718, in reraise
    raise value.with_traceback(tb)
  File "/home/airflow/.local/lib/python3.8/site-packages/fs/osfs.py", line 647, in open
    return io.open(
fs.errors.ResourceNotFound: resource 'user_to_pik_recommender_model/latest' not found

During handling of the above exception, another exception occurred:

Traceback (most recent call last):
  File "/home/airflow/.local/lib/python3.8/site-packages/bentoml/_internal/store.py", line 106, in _recreate_latest
    items = self.list(tag.name)
  File "/home/airflow/.local/lib/python3.8/site-packages/bentoml/_internal/store.py", line 83, in list
    raise NotFound(
bentoml.exceptions.NotFound: no Models with name 'user_to_pik_recommender_model' found

During handling of the above exception, another exception occurred:

Traceback (most recent call last):
  File "/home/airflow/.local/lib/python3.8/site-packages/airflow/models/dagbag.py", line 326, in parse
    loader.exec_module(new_module)
  File "<frozen importlib._bootstrap_external>", line 843, in exec_module
  File "<frozen importlib._bootstrap>", line 219, in _call_with_frames_removed
  File "/opt/airflow/dags/bentoml/user_to_pik_rec_bento/bento_service_user_to_pik_rec.py", line 24, in <module>
    runner = bentoml.transformers.get("user_to_pik_recommender_model:latest").to_runner()
  File "/home/airflow/.local/lib/python3.8/site-packages/bentoml/_internal/frameworks/transformers.py", line 151, in get
    model = bentoml.models.get(tag_like)
  File "/home/airflow/.local/lib/python3.8/site-packages/simple_di/__init__.py", line 139, in _
    return func(*_inject_args(bind.args), **_inject_kwargs(bind.kwargs))
  File "/home/airflow/.local/lib/python3.8/site-packages/bentoml/models.py", line 41, in get
    return _model_store.get(tag)
  File "/home/airflow/.local/lib/python3.8/site-packages/bentoml/_internal/store.py", line 137, in get
    self._recreate_latest(_tag)
  File "/home/airflow/.local/lib/python3.8/site-packages/bentoml/_internal/store.py", line 108, in _recreate_latest
    raise NotFound(
bentoml.exceptions.NotFound: no Models with name 'user_to_pik_recommender_model' exist in BentoML store <osfs '/home/airflow/bentoml/models'>
[2023-01-19T04:10:13.121+0000] {processor.py:770} WARNING - No viable dags retrieved from /opt/airflow/dags/bentoml/user_to_pik_rec_bento/bento_service_user_to_pik_rec.py
[2023-01-19T04:10:13.135+0000] {processor.py:178} INFO - Processing /opt/airflow/dags/bentoml/user_to_pik_rec_bento/bento_service_user_to_pik_rec.py took 2.323 seconds
[2023-01-19T04:10:43.273+0000] {processor.py:156} INFO - Started process (PID=3892) to work on /opt/airflow/dags/bentoml/user_to_pik_rec_bento/bento_service_user_to_pik_rec.py
[2023-01-19T04:10:43.274+0000] {processor.py:758} INFO - Processing file /opt/airflow/dags/bentoml/user_to_pik_rec_bento/bento_service_user_to_pik_rec.py for tasks to queue
[2023-01-19T04:10:43.274+0000] {logging_mixin.py:117} INFO - [2023-01-19T04:10:43.274+0000] {dagbag.py:525} INFO - Filling up the DagBag from /opt/airflow/dags/bentoml/user_to_pik_rec_bento/bento_service_user_to_pik_rec.py
[2023-01-19T04:10:45.599+0000] {logging_mixin.py:117} INFO - [2023-01-19T04:10:45.597+0000] {dagbag.py:330} ERROR - Failed to import: /opt/airflow/dags/bentoml/user_to_pik_rec_bento/bento_service_user_to_pik_rec.py
Traceback (most recent call last):
  File "/home/airflow/.local/lib/python3.8/site-packages/fs/osfs.py", line 647, in open
    return io.open(
FileNotFoundError: [Errno 2] No such file or directory: b'/home/airflow/bentoml/models/user_to_pik_recommender_model/latest'

During handling of the above exception, another exception occurred:

Traceback (most recent call last):
  File "/home/airflow/.local/lib/python3.8/site-packages/bentoml/_internal/store.py", line 132, in get
    _tag.version = self._fs.readtext(_tag.latest_path())
  File "/home/airflow/.local/lib/python3.8/site-packages/fs/base.py", line 693, in readtext
    self.open(
  File "/home/airflow/.local/lib/python3.8/site-packages/fs/osfs.py", line 647, in open
    return io.open(
  File "/home/airflow/.local/lib/python3.8/site-packages/fs/error_tools.py", line 89, in __exit__
    reraise(fserror, fserror(self._path, exc=exc_value), traceback)
  File "/home/airflow/.local/lib/python3.8/site-packages/six.py", line 718, in reraise
    raise value.with_traceback(tb)
  File "/home/airflow/.local/lib/python3.8/site-packages/fs/osfs.py", line 647, in open
    return io.open(
fs.errors.ResourceNotFound: resource 'user_to_pik_recommender_model/latest' not found

During handling of the above exception, another exception occurred:

Traceback (most recent call last):
  File "/home/airflow/.local/lib/python3.8/site-packages/bentoml/_internal/store.py", line 106, in _recreate_latest
    items = self.list(tag.name)
  File "/home/airflow/.local/lib/python3.8/site-packages/bentoml/_internal/store.py", line 83, in list
    raise NotFound(
bentoml.exceptions.NotFound: no Models with name 'user_to_pik_recommender_model' found

During handling of the above exception, another exception occurred:

Traceback (most recent call last):
  File "/home/airflow/.local/lib/python3.8/site-packages/airflow/models/dagbag.py", line 326, in parse
    loader.exec_module(new_module)
  File "<frozen importlib._bootstrap_external>", line 843, in exec_module
  File "<frozen importlib._bootstrap>", line 219, in _call_with_frames_removed
  File "/opt/airflow/dags/bentoml/user_to_pik_rec_bento/bento_service_user_to_pik_rec.py", line 24, in <module>
    runner = bentoml.transformers.get("user_to_pik_recommender_model:latest").to_runner()
  File "/home/airflow/.local/lib/python3.8/site-packages/bentoml/_internal/frameworks/transformers.py", line 151, in get
    model = bentoml.models.get(tag_like)
  File "/home/airflow/.local/lib/python3.8/site-packages/simple_di/__init__.py", line 139, in _
    return func(*_inject_args(bind.args), **_inject_kwargs(bind.kwargs))
  File "/home/airflow/.local/lib/python3.8/site-packages/bentoml/models.py", line 41, in get
    return _model_store.get(tag)
  File "/home/airflow/.local/lib/python3.8/site-packages/bentoml/_internal/store.py", line 137, in get
    self._recreate_latest(_tag)
  File "/home/airflow/.local/lib/python3.8/site-packages/bentoml/_internal/store.py", line 108, in _recreate_latest
    raise NotFound(
bentoml.exceptions.NotFound: no Models with name 'user_to_pik_recommender_model' exist in BentoML store <osfs '/home/airflow/bentoml/models'>
[2023-01-19T04:10:45.600+0000] {processor.py:770} WARNING - No viable dags retrieved from /opt/airflow/dags/bentoml/user_to_pik_rec_bento/bento_service_user_to_pik_rec.py
[2023-01-19T04:10:45.613+0000] {processor.py:178} INFO - Processing /opt/airflow/dags/bentoml/user_to_pik_rec_bento/bento_service_user_to_pik_rec.py took 2.343 seconds
[2023-01-19T04:11:16.331+0000] {processor.py:156} INFO - Started process (PID=3950) to work on /opt/airflow/dags/bentoml/user_to_pik_rec_bento/bento_service_user_to_pik_rec.py
[2023-01-19T04:11:16.331+0000] {processor.py:758} INFO - Processing file /opt/airflow/dags/bentoml/user_to_pik_rec_bento/bento_service_user_to_pik_rec.py for tasks to queue
[2023-01-19T04:11:16.332+0000] {logging_mixin.py:117} INFO - [2023-01-19T04:11:16.332+0000] {dagbag.py:525} INFO - Filling up the DagBag from /opt/airflow/dags/bentoml/user_to_pik_rec_bento/bento_service_user_to_pik_rec.py
[2023-01-19T04:11:18.696+0000] {logging_mixin.py:117} INFO - [2023-01-19T04:11:18.694+0000] {dagbag.py:330} ERROR - Failed to import: /opt/airflow/dags/bentoml/user_to_pik_rec_bento/bento_service_user_to_pik_rec.py
Traceback (most recent call last):
  File "/home/airflow/.local/lib/python3.8/site-packages/fs/osfs.py", line 647, in open
    return io.open(
FileNotFoundError: [Errno 2] No such file or directory: b'/home/airflow/bentoml/models/user_to_pik_recommender_model/latest'

During handling of the above exception, another exception occurred:

Traceback (most recent call last):
  File "/home/airflow/.local/lib/python3.8/site-packages/bentoml/_internal/store.py", line 132, in get
    _tag.version = self._fs.readtext(_tag.latest_path())
  File "/home/airflow/.local/lib/python3.8/site-packages/fs/base.py", line 693, in readtext
    self.open(
  File "/home/airflow/.local/lib/python3.8/site-packages/fs/osfs.py", line 647, in open
    return io.open(
  File "/home/airflow/.local/lib/python3.8/site-packages/fs/error_tools.py", line 89, in __exit__
    reraise(fserror, fserror(self._path, exc=exc_value), traceback)
  File "/home/airflow/.local/lib/python3.8/site-packages/six.py", line 718, in reraise
    raise value.with_traceback(tb)
  File "/home/airflow/.local/lib/python3.8/site-packages/fs/osfs.py", line 647, in open
    return io.open(
fs.errors.ResourceNotFound: resource 'user_to_pik_recommender_model/latest' not found

During handling of the above exception, another exception occurred:

Traceback (most recent call last):
  File "/home/airflow/.local/lib/python3.8/site-packages/bentoml/_internal/store.py", line 106, in _recreate_latest
    items = self.list(tag.name)
  File "/home/airflow/.local/lib/python3.8/site-packages/bentoml/_internal/store.py", line 83, in list
    raise NotFound(
bentoml.exceptions.NotFound: no Models with name 'user_to_pik_recommender_model' found

During handling of the above exception, another exception occurred:

Traceback (most recent call last):
  File "/home/airflow/.local/lib/python3.8/site-packages/airflow/models/dagbag.py", line 326, in parse
    loader.exec_module(new_module)
  File "<frozen importlib._bootstrap_external>", line 843, in exec_module
  File "<frozen importlib._bootstrap>", line 219, in _call_with_frames_removed
  File "/opt/airflow/dags/bentoml/user_to_pik_rec_bento/bento_service_user_to_pik_rec.py", line 24, in <module>
    runner = bentoml.transformers.get("user_to_pik_recommender_model:latest").to_runner()
  File "/home/airflow/.local/lib/python3.8/site-packages/bentoml/_internal/frameworks/transformers.py", line 151, in get
    model = bentoml.models.get(tag_like)
  File "/home/airflow/.local/lib/python3.8/site-packages/simple_di/__init__.py", line 139, in _
    return func(*_inject_args(bind.args), **_inject_kwargs(bind.kwargs))
  File "/home/airflow/.local/lib/python3.8/site-packages/bentoml/models.py", line 41, in get
    return _model_store.get(tag)
  File "/home/airflow/.local/lib/python3.8/site-packages/bentoml/_internal/store.py", line 137, in get
    self._recreate_latest(_tag)
  File "/home/airflow/.local/lib/python3.8/site-packages/bentoml/_internal/store.py", line 108, in _recreate_latest
    raise NotFound(
bentoml.exceptions.NotFound: no Models with name 'user_to_pik_recommender_model' exist in BentoML store <osfs '/home/airflow/bentoml/models'>
[2023-01-19T04:11:18.697+0000] {processor.py:770} WARNING - No viable dags retrieved from /opt/airflow/dags/bentoml/user_to_pik_rec_bento/bento_service_user_to_pik_rec.py
[2023-01-19T04:11:18.712+0000] {processor.py:178} INFO - Processing /opt/airflow/dags/bentoml/user_to_pik_rec_bento/bento_service_user_to_pik_rec.py took 2.384 seconds
[2023-01-19T04:11:49.464+0000] {processor.py:156} INFO - Started process (PID=4008) to work on /opt/airflow/dags/bentoml/user_to_pik_rec_bento/bento_service_user_to_pik_rec.py
[2023-01-19T04:11:49.465+0000] {processor.py:758} INFO - Processing file /opt/airflow/dags/bentoml/user_to_pik_rec_bento/bento_service_user_to_pik_rec.py for tasks to queue
[2023-01-19T04:11:49.466+0000] {logging_mixin.py:117} INFO - [2023-01-19T04:11:49.465+0000] {dagbag.py:525} INFO - Filling up the DagBag from /opt/airflow/dags/bentoml/user_to_pik_rec_bento/bento_service_user_to_pik_rec.py
[2023-01-19T04:11:51.843+0000] {logging_mixin.py:117} INFO - [2023-01-19T04:11:51.841+0000] {dagbag.py:330} ERROR - Failed to import: /opt/airflow/dags/bentoml/user_to_pik_rec_bento/bento_service_user_to_pik_rec.py
Traceback (most recent call last):
  File "/home/airflow/.local/lib/python3.8/site-packages/fs/osfs.py", line 647, in open
    return io.open(
FileNotFoundError: [Errno 2] No such file or directory: b'/home/airflow/bentoml/models/user_to_pik_recommender_model/latest'

During handling of the above exception, another exception occurred:

Traceback (most recent call last):
  File "/home/airflow/.local/lib/python3.8/site-packages/bentoml/_internal/store.py", line 132, in get
    _tag.version = self._fs.readtext(_tag.latest_path())
  File "/home/airflow/.local/lib/python3.8/site-packages/fs/base.py", line 693, in readtext
    self.open(
  File "/home/airflow/.local/lib/python3.8/site-packages/fs/osfs.py", line 647, in open
    return io.open(
  File "/home/airflow/.local/lib/python3.8/site-packages/fs/error_tools.py", line 89, in __exit__
    reraise(fserror, fserror(self._path, exc=exc_value), traceback)
  File "/home/airflow/.local/lib/python3.8/site-packages/six.py", line 718, in reraise
    raise value.with_traceback(tb)
  File "/home/airflow/.local/lib/python3.8/site-packages/fs/osfs.py", line 647, in open
    return io.open(
fs.errors.ResourceNotFound: resource 'user_to_pik_recommender_model/latest' not found

During handling of the above exception, another exception occurred:

Traceback (most recent call last):
  File "/home/airflow/.local/lib/python3.8/site-packages/bentoml/_internal/store.py", line 106, in _recreate_latest
    items = self.list(tag.name)
  File "/home/airflow/.local/lib/python3.8/site-packages/bentoml/_internal/store.py", line 83, in list
    raise NotFound(
bentoml.exceptions.NotFound: no Models with name 'user_to_pik_recommender_model' found

During handling of the above exception, another exception occurred:

Traceback (most recent call last):
  File "/home/airflow/.local/lib/python3.8/site-packages/airflow/models/dagbag.py", line 326, in parse
    loader.exec_module(new_module)
  File "<frozen importlib._bootstrap_external>", line 843, in exec_module
  File "<frozen importlib._bootstrap>", line 219, in _call_with_frames_removed
  File "/opt/airflow/dags/bentoml/user_to_pik_rec_bento/bento_service_user_to_pik_rec.py", line 24, in <module>
    runner = bentoml.transformers.get("user_to_pik_recommender_model:latest").to_runner()
  File "/home/airflow/.local/lib/python3.8/site-packages/bentoml/_internal/frameworks/transformers.py", line 151, in get
    model = bentoml.models.get(tag_like)
  File "/home/airflow/.local/lib/python3.8/site-packages/simple_di/__init__.py", line 139, in _
    return func(*_inject_args(bind.args), **_inject_kwargs(bind.kwargs))
  File "/home/airflow/.local/lib/python3.8/site-packages/bentoml/models.py", line 41, in get
    return _model_store.get(tag)
  File "/home/airflow/.local/lib/python3.8/site-packages/bentoml/_internal/store.py", line 137, in get
    self._recreate_latest(_tag)
  File "/home/airflow/.local/lib/python3.8/site-packages/bentoml/_internal/store.py", line 108, in _recreate_latest
    raise NotFound(
bentoml.exceptions.NotFound: no Models with name 'user_to_pik_recommender_model' exist in BentoML store <osfs '/home/airflow/bentoml/models'>
[2023-01-19T04:11:51.843+0000] {processor.py:770} WARNING - No viable dags retrieved from /opt/airflow/dags/bentoml/user_to_pik_rec_bento/bento_service_user_to_pik_rec.py
[2023-01-19T04:11:51.859+0000] {processor.py:178} INFO - Processing /opt/airflow/dags/bentoml/user_to_pik_rec_bento/bento_service_user_to_pik_rec.py took 2.398 seconds
[2023-01-19T04:12:21.953+0000] {processor.py:156} INFO - Started process (PID=4066) to work on /opt/airflow/dags/bentoml/user_to_pik_rec_bento/bento_service_user_to_pik_rec.py
[2023-01-19T04:12:21.954+0000] {processor.py:758} INFO - Processing file /opt/airflow/dags/bentoml/user_to_pik_rec_bento/bento_service_user_to_pik_rec.py for tasks to queue
[2023-01-19T04:12:21.954+0000] {logging_mixin.py:117} INFO - [2023-01-19T04:12:21.954+0000] {dagbag.py:525} INFO - Filling up the DagBag from /opt/airflow/dags/bentoml/user_to_pik_rec_bento/bento_service_user_to_pik_rec.py
[2023-01-19T04:12:24.289+0000] {logging_mixin.py:117} INFO - [2023-01-19T04:12:24.287+0000] {dagbag.py:330} ERROR - Failed to import: /opt/airflow/dags/bentoml/user_to_pik_rec_bento/bento_service_user_to_pik_rec.py
Traceback (most recent call last):
  File "/home/airflow/.local/lib/python3.8/site-packages/fs/osfs.py", line 647, in open
    return io.open(
FileNotFoundError: [Errno 2] No such file or directory: b'/home/airflow/bentoml/models/user_to_pik_recommender_model/latest'

During handling of the above exception, another exception occurred:

Traceback (most recent call last):
  File "/home/airflow/.local/lib/python3.8/site-packages/bentoml/_internal/store.py", line 132, in get
    _tag.version = self._fs.readtext(_tag.latest_path())
  File "/home/airflow/.local/lib/python3.8/site-packages/fs/base.py", line 693, in readtext
    self.open(
  File "/home/airflow/.local/lib/python3.8/site-packages/fs/osfs.py", line 647, in open
    return io.open(
  File "/home/airflow/.local/lib/python3.8/site-packages/fs/error_tools.py", line 89, in __exit__
    reraise(fserror, fserror(self._path, exc=exc_value), traceback)
  File "/home/airflow/.local/lib/python3.8/site-packages/six.py", line 718, in reraise
    raise value.with_traceback(tb)
  File "/home/airflow/.local/lib/python3.8/site-packages/fs/osfs.py", line 647, in open
    return io.open(
fs.errors.ResourceNotFound: resource 'user_to_pik_recommender_model/latest' not found

During handling of the above exception, another exception occurred:

Traceback (most recent call last):
  File "/home/airflow/.local/lib/python3.8/site-packages/bentoml/_internal/store.py", line 106, in _recreate_latest
    items = self.list(tag.name)
  File "/home/airflow/.local/lib/python3.8/site-packages/bentoml/_internal/store.py", line 83, in list
    raise NotFound(
bentoml.exceptions.NotFound: no Models with name 'user_to_pik_recommender_model' found

During handling of the above exception, another exception occurred:

Traceback (most recent call last):
  File "/home/airflow/.local/lib/python3.8/site-packages/airflow/models/dagbag.py", line 326, in parse
    loader.exec_module(new_module)
  File "<frozen importlib._bootstrap_external>", line 843, in exec_module
  File "<frozen importlib._bootstrap>", line 219, in _call_with_frames_removed
  File "/opt/airflow/dags/bentoml/user_to_pik_rec_bento/bento_service_user_to_pik_rec.py", line 24, in <module>
    runner = bentoml.transformers.get("user_to_pik_recommender_model:latest").to_runner()
  File "/home/airflow/.local/lib/python3.8/site-packages/bentoml/_internal/frameworks/transformers.py", line 151, in get
    model = bentoml.models.get(tag_like)
  File "/home/airflow/.local/lib/python3.8/site-packages/simple_di/__init__.py", line 139, in _
    return func(*_inject_args(bind.args), **_inject_kwargs(bind.kwargs))
  File "/home/airflow/.local/lib/python3.8/site-packages/bentoml/models.py", line 41, in get
    return _model_store.get(tag)
  File "/home/airflow/.local/lib/python3.8/site-packages/bentoml/_internal/store.py", line 137, in get
    self._recreate_latest(_tag)
  File "/home/airflow/.local/lib/python3.8/site-packages/bentoml/_internal/store.py", line 108, in _recreate_latest
    raise NotFound(
bentoml.exceptions.NotFound: no Models with name 'user_to_pik_recommender_model' exist in BentoML store <osfs '/home/airflow/bentoml/models'>
[2023-01-19T04:12:24.289+0000] {processor.py:770} WARNING - No viable dags retrieved from /opt/airflow/dags/bentoml/user_to_pik_rec_bento/bento_service_user_to_pik_rec.py
[2023-01-19T04:12:24.304+0000] {processor.py:178} INFO - Processing /opt/airflow/dags/bentoml/user_to_pik_rec_bento/bento_service_user_to_pik_rec.py took 2.354 seconds
[2023-01-19T04:12:54.507+0000] {processor.py:156} INFO - Started process (PID=4124) to work on /opt/airflow/dags/bentoml/user_to_pik_rec_bento/bento_service_user_to_pik_rec.py
[2023-01-19T04:12:54.507+0000] {processor.py:758} INFO - Processing file /opt/airflow/dags/bentoml/user_to_pik_rec_bento/bento_service_user_to_pik_rec.py for tasks to queue
[2023-01-19T04:12:54.508+0000] {logging_mixin.py:117} INFO - [2023-01-19T04:12:54.508+0000] {dagbag.py:525} INFO - Filling up the DagBag from /opt/airflow/dags/bentoml/user_to_pik_rec_bento/bento_service_user_to_pik_rec.py
[2023-01-19T04:12:56.838+0000] {logging_mixin.py:117} INFO - [2023-01-19T04:12:56.835+0000] {dagbag.py:330} ERROR - Failed to import: /opt/airflow/dags/bentoml/user_to_pik_rec_bento/bento_service_user_to_pik_rec.py
Traceback (most recent call last):
  File "/home/airflow/.local/lib/python3.8/site-packages/fs/osfs.py", line 647, in open
    return io.open(
FileNotFoundError: [Errno 2] No such file or directory: b'/home/airflow/bentoml/models/user_to_pik_recommender_model/latest'

During handling of the above exception, another exception occurred:

Traceback (most recent call last):
  File "/home/airflow/.local/lib/python3.8/site-packages/bentoml/_internal/store.py", line 132, in get
    _tag.version = self._fs.readtext(_tag.latest_path())
  File "/home/airflow/.local/lib/python3.8/site-packages/fs/base.py", line 693, in readtext
    self.open(
  File "/home/airflow/.local/lib/python3.8/site-packages/fs/osfs.py", line 647, in open
    return io.open(
  File "/home/airflow/.local/lib/python3.8/site-packages/fs/error_tools.py", line 89, in __exit__
    reraise(fserror, fserror(self._path, exc=exc_value), traceback)
  File "/home/airflow/.local/lib/python3.8/site-packages/six.py", line 718, in reraise
    raise value.with_traceback(tb)
  File "/home/airflow/.local/lib/python3.8/site-packages/fs/osfs.py", line 647, in open
    return io.open(
fs.errors.ResourceNotFound: resource 'user_to_pik_recommender_model/latest' not found

During handling of the above exception, another exception occurred:

Traceback (most recent call last):
  File "/home/airflow/.local/lib/python3.8/site-packages/bentoml/_internal/store.py", line 106, in _recreate_latest
    items = self.list(tag.name)
  File "/home/airflow/.local/lib/python3.8/site-packages/bentoml/_internal/store.py", line 83, in list
    raise NotFound(
bentoml.exceptions.NotFound: no Models with name 'user_to_pik_recommender_model' found

During handling of the above exception, another exception occurred:

Traceback (most recent call last):
  File "/home/airflow/.local/lib/python3.8/site-packages/airflow/models/dagbag.py", line 326, in parse
    loader.exec_module(new_module)
  File "<frozen importlib._bootstrap_external>", line 843, in exec_module
  File "<frozen importlib._bootstrap>", line 219, in _call_with_frames_removed
  File "/opt/airflow/dags/bentoml/user_to_pik_rec_bento/bento_service_user_to_pik_rec.py", line 24, in <module>
    runner = bentoml.transformers.get("user_to_pik_recommender_model:latest").to_runner()
  File "/home/airflow/.local/lib/python3.8/site-packages/bentoml/_internal/frameworks/transformers.py", line 151, in get
    model = bentoml.models.get(tag_like)
  File "/home/airflow/.local/lib/python3.8/site-packages/simple_di/__init__.py", line 139, in _
    return func(*_inject_args(bind.args), **_inject_kwargs(bind.kwargs))
  File "/home/airflow/.local/lib/python3.8/site-packages/bentoml/models.py", line 41, in get
    return _model_store.get(tag)
  File "/home/airflow/.local/lib/python3.8/site-packages/bentoml/_internal/store.py", line 137, in get
    self._recreate_latest(_tag)
  File "/home/airflow/.local/lib/python3.8/site-packages/bentoml/_internal/store.py", line 108, in _recreate_latest
    raise NotFound(
bentoml.exceptions.NotFound: no Models with name 'user_to_pik_recommender_model' exist in BentoML store <osfs '/home/airflow/bentoml/models'>
[2023-01-19T04:12:56.839+0000] {processor.py:770} WARNING - No viable dags retrieved from /opt/airflow/dags/bentoml/user_to_pik_rec_bento/bento_service_user_to_pik_rec.py
[2023-01-19T04:12:56.854+0000] {processor.py:178} INFO - Processing /opt/airflow/dags/bentoml/user_to_pik_rec_bento/bento_service_user_to_pik_rec.py took 2.350 seconds
[2023-01-19T04:13:27.391+0000] {processor.py:156} INFO - Started process (PID=4182) to work on /opt/airflow/dags/bentoml/user_to_pik_rec_bento/bento_service_user_to_pik_rec.py
[2023-01-19T04:13:27.392+0000] {processor.py:758} INFO - Processing file /opt/airflow/dags/bentoml/user_to_pik_rec_bento/bento_service_user_to_pik_rec.py for tasks to queue
[2023-01-19T04:13:27.392+0000] {logging_mixin.py:117} INFO - [2023-01-19T04:13:27.392+0000] {dagbag.py:525} INFO - Filling up the DagBag from /opt/airflow/dags/bentoml/user_to_pik_rec_bento/bento_service_user_to_pik_rec.py
[2023-01-19T04:13:29.699+0000] {logging_mixin.py:117} INFO - [2023-01-19T04:13:29.697+0000] {dagbag.py:330} ERROR - Failed to import: /opt/airflow/dags/bentoml/user_to_pik_rec_bento/bento_service_user_to_pik_rec.py
Traceback (most recent call last):
  File "/home/airflow/.local/lib/python3.8/site-packages/fs/osfs.py", line 647, in open
    return io.open(
FileNotFoundError: [Errno 2] No such file or directory: b'/home/airflow/bentoml/models/user_to_pik_recommender_model/latest'

During handling of the above exception, another exception occurred:

Traceback (most recent call last):
  File "/home/airflow/.local/lib/python3.8/site-packages/bentoml/_internal/store.py", line 132, in get
    _tag.version = self._fs.readtext(_tag.latest_path())
  File "/home/airflow/.local/lib/python3.8/site-packages/fs/base.py", line 693, in readtext
    self.open(
  File "/home/airflow/.local/lib/python3.8/site-packages/fs/osfs.py", line 647, in open
    return io.open(
  File "/home/airflow/.local/lib/python3.8/site-packages/fs/error_tools.py", line 89, in __exit__
    reraise(fserror, fserror(self._path, exc=exc_value), traceback)
  File "/home/airflow/.local/lib/python3.8/site-packages/six.py", line 718, in reraise
    raise value.with_traceback(tb)
  File "/home/airflow/.local/lib/python3.8/site-packages/fs/osfs.py", line 647, in open
    return io.open(
fs.errors.ResourceNotFound: resource 'user_to_pik_recommender_model/latest' not found

During handling of the above exception, another exception occurred:

Traceback (most recent call last):
  File "/home/airflow/.local/lib/python3.8/site-packages/bentoml/_internal/store.py", line 106, in _recreate_latest
    items = self.list(tag.name)
  File "/home/airflow/.local/lib/python3.8/site-packages/bentoml/_internal/store.py", line 83, in list
    raise NotFound(
bentoml.exceptions.NotFound: no Models with name 'user_to_pik_recommender_model' found

During handling of the above exception, another exception occurred:

Traceback (most recent call last):
  File "/home/airflow/.local/lib/python3.8/site-packages/airflow/models/dagbag.py", line 326, in parse
    loader.exec_module(new_module)
  File "<frozen importlib._bootstrap_external>", line 843, in exec_module
  File "<frozen importlib._bootstrap>", line 219, in _call_with_frames_removed
  File "/opt/airflow/dags/bentoml/user_to_pik_rec_bento/bento_service_user_to_pik_rec.py", line 24, in <module>
    runner = bentoml.transformers.get("user_to_pik_recommender_model:latest").to_runner()
  File "/home/airflow/.local/lib/python3.8/site-packages/bentoml/_internal/frameworks/transformers.py", line 151, in get
    model = bentoml.models.get(tag_like)
  File "/home/airflow/.local/lib/python3.8/site-packages/simple_di/__init__.py", line 139, in _
    return func(*_inject_args(bind.args), **_inject_kwargs(bind.kwargs))
  File "/home/airflow/.local/lib/python3.8/site-packages/bentoml/models.py", line 41, in get
    return _model_store.get(tag)
  File "/home/airflow/.local/lib/python3.8/site-packages/bentoml/_internal/store.py", line 137, in get
    self._recreate_latest(_tag)
  File "/home/airflow/.local/lib/python3.8/site-packages/bentoml/_internal/store.py", line 108, in _recreate_latest
    raise NotFound(
bentoml.exceptions.NotFound: no Models with name 'user_to_pik_recommender_model' exist in BentoML store <osfs '/home/airflow/bentoml/models'>
[2023-01-19T04:13:29.700+0000] {processor.py:770} WARNING - No viable dags retrieved from /opt/airflow/dags/bentoml/user_to_pik_rec_bento/bento_service_user_to_pik_rec.py
[2023-01-19T04:13:29.714+0000] {processor.py:178} INFO - Processing /opt/airflow/dags/bentoml/user_to_pik_rec_bento/bento_service_user_to_pik_rec.py took 2.326 seconds
[2023-01-19T04:14:00.444+0000] {processor.py:156} INFO - Started process (PID=4240) to work on /opt/airflow/dags/bentoml/user_to_pik_rec_bento/bento_service_user_to_pik_rec.py
[2023-01-19T04:14:00.445+0000] {processor.py:758} INFO - Processing file /opt/airflow/dags/bentoml/user_to_pik_rec_bento/bento_service_user_to_pik_rec.py for tasks to queue
[2023-01-19T04:14:00.446+0000] {logging_mixin.py:117} INFO - [2023-01-19T04:14:00.446+0000] {dagbag.py:525} INFO - Filling up the DagBag from /opt/airflow/dags/bentoml/user_to_pik_rec_bento/bento_service_user_to_pik_rec.py
[2023-01-19T04:14:02.795+0000] {logging_mixin.py:117} INFO - [2023-01-19T04:14:02.793+0000] {dagbag.py:330} ERROR - Failed to import: /opt/airflow/dags/bentoml/user_to_pik_rec_bento/bento_service_user_to_pik_rec.py
Traceback (most recent call last):
  File "/home/airflow/.local/lib/python3.8/site-packages/fs/osfs.py", line 647, in open
    return io.open(
FileNotFoundError: [Errno 2] No such file or directory: b'/home/airflow/bentoml/models/user_to_pik_recommender_model/latest'

During handling of the above exception, another exception occurred:

Traceback (most recent call last):
  File "/home/airflow/.local/lib/python3.8/site-packages/bentoml/_internal/store.py", line 132, in get
    _tag.version = self._fs.readtext(_tag.latest_path())
  File "/home/airflow/.local/lib/python3.8/site-packages/fs/base.py", line 693, in readtext
    self.open(
  File "/home/airflow/.local/lib/python3.8/site-packages/fs/osfs.py", line 647, in open
    return io.open(
  File "/home/airflow/.local/lib/python3.8/site-packages/fs/error_tools.py", line 89, in __exit__
    reraise(fserror, fserror(self._path, exc=exc_value), traceback)
  File "/home/airflow/.local/lib/python3.8/site-packages/six.py", line 718, in reraise
    raise value.with_traceback(tb)
  File "/home/airflow/.local/lib/python3.8/site-packages/fs/osfs.py", line 647, in open
    return io.open(
fs.errors.ResourceNotFound: resource 'user_to_pik_recommender_model/latest' not found

During handling of the above exception, another exception occurred:

Traceback (most recent call last):
  File "/home/airflow/.local/lib/python3.8/site-packages/bentoml/_internal/store.py", line 106, in _recreate_latest
    items = self.list(tag.name)
  File "/home/airflow/.local/lib/python3.8/site-packages/bentoml/_internal/store.py", line 83, in list
    raise NotFound(
bentoml.exceptions.NotFound: no Models with name 'user_to_pik_recommender_model' found

During handling of the above exception, another exception occurred:

Traceback (most recent call last):
  File "/home/airflow/.local/lib/python3.8/site-packages/airflow/models/dagbag.py", line 326, in parse
    loader.exec_module(new_module)
  File "<frozen importlib._bootstrap_external>", line 843, in exec_module
  File "<frozen importlib._bootstrap>", line 219, in _call_with_frames_removed
  File "/opt/airflow/dags/bentoml/user_to_pik_rec_bento/bento_service_user_to_pik_rec.py", line 24, in <module>
    runner = bentoml.transformers.get("user_to_pik_recommender_model:latest").to_runner()
  File "/home/airflow/.local/lib/python3.8/site-packages/bentoml/_internal/frameworks/transformers.py", line 151, in get
    model = bentoml.models.get(tag_like)
  File "/home/airflow/.local/lib/python3.8/site-packages/simple_di/__init__.py", line 139, in _
    return func(*_inject_args(bind.args), **_inject_kwargs(bind.kwargs))
  File "/home/airflow/.local/lib/python3.8/site-packages/bentoml/models.py", line 41, in get
    return _model_store.get(tag)
  File "/home/airflow/.local/lib/python3.8/site-packages/bentoml/_internal/store.py", line 137, in get
    self._recreate_latest(_tag)
  File "/home/airflow/.local/lib/python3.8/site-packages/bentoml/_internal/store.py", line 108, in _recreate_latest
    raise NotFound(
bentoml.exceptions.NotFound: no Models with name 'user_to_pik_recommender_model' exist in BentoML store <osfs '/home/airflow/bentoml/models'>
[2023-01-19T04:14:02.795+0000] {processor.py:770} WARNING - No viable dags retrieved from /opt/airflow/dags/bentoml/user_to_pik_rec_bento/bento_service_user_to_pik_rec.py
[2023-01-19T04:14:02.813+0000] {processor.py:178} INFO - Processing /opt/airflow/dags/bentoml/user_to_pik_rec_bento/bento_service_user_to_pik_rec.py took 2.373 seconds
[2023-01-19T04:14:33.568+0000] {processor.py:156} INFO - Started process (PID=4298) to work on /opt/airflow/dags/bentoml/user_to_pik_rec_bento/bento_service_user_to_pik_rec.py
[2023-01-19T04:14:33.569+0000] {processor.py:758} INFO - Processing file /opt/airflow/dags/bentoml/user_to_pik_rec_bento/bento_service_user_to_pik_rec.py for tasks to queue
[2023-01-19T04:14:33.570+0000] {logging_mixin.py:117} INFO - [2023-01-19T04:14:33.569+0000] {dagbag.py:525} INFO - Filling up the DagBag from /opt/airflow/dags/bentoml/user_to_pik_rec_bento/bento_service_user_to_pik_rec.py
[2023-01-19T04:14:36.086+0000] {logging_mixin.py:117} INFO - [2023-01-19T04:14:36.083+0000] {dagbag.py:330} ERROR - Failed to import: /opt/airflow/dags/bentoml/user_to_pik_rec_bento/bento_service_user_to_pik_rec.py
Traceback (most recent call last):
  File "/home/airflow/.local/lib/python3.8/site-packages/fs/osfs.py", line 647, in open
    return io.open(
FileNotFoundError: [Errno 2] No such file or directory: b'/home/airflow/bentoml/models/user_to_pik_recommender_model/latest'

During handling of the above exception, another exception occurred:

Traceback (most recent call last):
  File "/home/airflow/.local/lib/python3.8/site-packages/bentoml/_internal/store.py", line 132, in get
    _tag.version = self._fs.readtext(_tag.latest_path())
  File "/home/airflow/.local/lib/python3.8/site-packages/fs/base.py", line 693, in readtext
    self.open(
  File "/home/airflow/.local/lib/python3.8/site-packages/fs/osfs.py", line 647, in open
    return io.open(
  File "/home/airflow/.local/lib/python3.8/site-packages/fs/error_tools.py", line 89, in __exit__
    reraise(fserror, fserror(self._path, exc=exc_value), traceback)
  File "/home/airflow/.local/lib/python3.8/site-packages/six.py", line 718, in reraise
    raise value.with_traceback(tb)
  File "/home/airflow/.local/lib/python3.8/site-packages/fs/osfs.py", line 647, in open
    return io.open(
fs.errors.ResourceNotFound: resource 'user_to_pik_recommender_model/latest' not found

During handling of the above exception, another exception occurred:

Traceback (most recent call last):
  File "/home/airflow/.local/lib/python3.8/site-packages/bentoml/_internal/store.py", line 106, in _recreate_latest
    items = self.list(tag.name)
  File "/home/airflow/.local/lib/python3.8/site-packages/bentoml/_internal/store.py", line 83, in list
    raise NotFound(
bentoml.exceptions.NotFound: no Models with name 'user_to_pik_recommender_model' found

During handling of the above exception, another exception occurred:

Traceback (most recent call last):
  File "/home/airflow/.local/lib/python3.8/site-packages/airflow/models/dagbag.py", line 326, in parse
    loader.exec_module(new_module)
  File "<frozen importlib._bootstrap_external>", line 843, in exec_module
  File "<frozen importlib._bootstrap>", line 219, in _call_with_frames_removed
  File "/opt/airflow/dags/bentoml/user_to_pik_rec_bento/bento_service_user_to_pik_rec.py", line 24, in <module>
    runner = bentoml.transformers.get("user_to_pik_recommender_model:latest").to_runner()
  File "/home/airflow/.local/lib/python3.8/site-packages/bentoml/_internal/frameworks/transformers.py", line 151, in get
    model = bentoml.models.get(tag_like)
  File "/home/airflow/.local/lib/python3.8/site-packages/simple_di/__init__.py", line 139, in _
    return func(*_inject_args(bind.args), **_inject_kwargs(bind.kwargs))
  File "/home/airflow/.local/lib/python3.8/site-packages/bentoml/models.py", line 41, in get
    return _model_store.get(tag)
  File "/home/airflow/.local/lib/python3.8/site-packages/bentoml/_internal/store.py", line 137, in get
    self._recreate_latest(_tag)
  File "/home/airflow/.local/lib/python3.8/site-packages/bentoml/_internal/store.py", line 108, in _recreate_latest
    raise NotFound(
bentoml.exceptions.NotFound: no Models with name 'user_to_pik_recommender_model' exist in BentoML store <osfs '/home/airflow/bentoml/models'>
[2023-01-19T04:14:36.087+0000] {processor.py:770} WARNING - No viable dags retrieved from /opt/airflow/dags/bentoml/user_to_pik_rec_bento/bento_service_user_to_pik_rec.py
[2023-01-19T04:14:36.103+0000] {processor.py:178} INFO - Processing /opt/airflow/dags/bentoml/user_to_pik_rec_bento/bento_service_user_to_pik_rec.py took 2.538 seconds
[2023-01-19T04:15:06.327+0000] {processor.py:156} INFO - Started process (PID=4356) to work on /opt/airflow/dags/bentoml/user_to_pik_rec_bento/bento_service_user_to_pik_rec.py
[2023-01-19T04:15:06.328+0000] {processor.py:758} INFO - Processing file /opt/airflow/dags/bentoml/user_to_pik_rec_bento/bento_service_user_to_pik_rec.py for tasks to queue
[2023-01-19T04:15:06.328+0000] {logging_mixin.py:117} INFO - [2023-01-19T04:15:06.328+0000] {dagbag.py:525} INFO - Filling up the DagBag from /opt/airflow/dags/bentoml/user_to_pik_rec_bento/bento_service_user_to_pik_rec.py
[2023-01-19T04:15:08.684+0000] {logging_mixin.py:117} INFO - [2023-01-19T04:15:08.682+0000] {dagbag.py:330} ERROR - Failed to import: /opt/airflow/dags/bentoml/user_to_pik_rec_bento/bento_service_user_to_pik_rec.py
Traceback (most recent call last):
  File "/home/airflow/.local/lib/python3.8/site-packages/fs/osfs.py", line 647, in open
    return io.open(
FileNotFoundError: [Errno 2] No such file or directory: b'/home/airflow/bentoml/models/user_to_pik_recommender_model/latest'

During handling of the above exception, another exception occurred:

Traceback (most recent call last):
  File "/home/airflow/.local/lib/python3.8/site-packages/bentoml/_internal/store.py", line 132, in get
    _tag.version = self._fs.readtext(_tag.latest_path())
  File "/home/airflow/.local/lib/python3.8/site-packages/fs/base.py", line 693, in readtext
    self.open(
  File "/home/airflow/.local/lib/python3.8/site-packages/fs/osfs.py", line 647, in open
    return io.open(
  File "/home/airflow/.local/lib/python3.8/site-packages/fs/error_tools.py", line 89, in __exit__
    reraise(fserror, fserror(self._path, exc=exc_value), traceback)
  File "/home/airflow/.local/lib/python3.8/site-packages/six.py", line 718, in reraise
    raise value.with_traceback(tb)
  File "/home/airflow/.local/lib/python3.8/site-packages/fs/osfs.py", line 647, in open
    return io.open(
fs.errors.ResourceNotFound: resource 'user_to_pik_recommender_model/latest' not found

During handling of the above exception, another exception occurred:

Traceback (most recent call last):
  File "/home/airflow/.local/lib/python3.8/site-packages/bentoml/_internal/store.py", line 106, in _recreate_latest
    items = self.list(tag.name)
  File "/home/airflow/.local/lib/python3.8/site-packages/bentoml/_internal/store.py", line 83, in list
    raise NotFound(
bentoml.exceptions.NotFound: no Models with name 'user_to_pik_recommender_model' found

During handling of the above exception, another exception occurred:

Traceback (most recent call last):
  File "/home/airflow/.local/lib/python3.8/site-packages/airflow/models/dagbag.py", line 326, in parse
    loader.exec_module(new_module)
  File "<frozen importlib._bootstrap_external>", line 843, in exec_module
  File "<frozen importlib._bootstrap>", line 219, in _call_with_frames_removed
  File "/opt/airflow/dags/bentoml/user_to_pik_rec_bento/bento_service_user_to_pik_rec.py", line 24, in <module>
    runner = bentoml.transformers.get("user_to_pik_recommender_model:latest").to_runner()
  File "/home/airflow/.local/lib/python3.8/site-packages/bentoml/_internal/frameworks/transformers.py", line 151, in get
    model = bentoml.models.get(tag_like)
  File "/home/airflow/.local/lib/python3.8/site-packages/simple_di/__init__.py", line 139, in _
    return func(*_inject_args(bind.args), **_inject_kwargs(bind.kwargs))
  File "/home/airflow/.local/lib/python3.8/site-packages/bentoml/models.py", line 41, in get
    return _model_store.get(tag)
  File "/home/airflow/.local/lib/python3.8/site-packages/bentoml/_internal/store.py", line 137, in get
    self._recreate_latest(_tag)
  File "/home/airflow/.local/lib/python3.8/site-packages/bentoml/_internal/store.py", line 108, in _recreate_latest
    raise NotFound(
bentoml.exceptions.NotFound: no Models with name 'user_to_pik_recommender_model' exist in BentoML store <osfs '/home/airflow/bentoml/models'>
[2023-01-19T04:15:08.685+0000] {processor.py:770} WARNING - No viable dags retrieved from /opt/airflow/dags/bentoml/user_to_pik_rec_bento/bento_service_user_to_pik_rec.py
[2023-01-19T04:15:08.700+0000] {processor.py:178} INFO - Processing /opt/airflow/dags/bentoml/user_to_pik_rec_bento/bento_service_user_to_pik_rec.py took 2.376 seconds
[2023-01-19T04:15:38.783+0000] {processor.py:156} INFO - Started process (PID=4414) to work on /opt/airflow/dags/bentoml/user_to_pik_rec_bento/bento_service_user_to_pik_rec.py
[2023-01-19T04:15:38.784+0000] {processor.py:758} INFO - Processing file /opt/airflow/dags/bentoml/user_to_pik_rec_bento/bento_service_user_to_pik_rec.py for tasks to queue
[2023-01-19T04:15:38.784+0000] {logging_mixin.py:117} INFO - [2023-01-19T04:15:38.784+0000] {dagbag.py:525} INFO - Filling up the DagBag from /opt/airflow/dags/bentoml/user_to_pik_rec_bento/bento_service_user_to_pik_rec.py
[2023-01-19T04:15:41.074+0000] {logging_mixin.py:117} INFO - [2023-01-19T04:15:41.072+0000] {dagbag.py:330} ERROR - Failed to import: /opt/airflow/dags/bentoml/user_to_pik_rec_bento/bento_service_user_to_pik_rec.py
Traceback (most recent call last):
  File "/home/airflow/.local/lib/python3.8/site-packages/fs/osfs.py", line 647, in open
    return io.open(
FileNotFoundError: [Errno 2] No such file or directory: b'/home/airflow/bentoml/models/user_to_pik_recommender_model/latest'

During handling of the above exception, another exception occurred:

Traceback (most recent call last):
  File "/home/airflow/.local/lib/python3.8/site-packages/bentoml/_internal/store.py", line 132, in get
    _tag.version = self._fs.readtext(_tag.latest_path())
  File "/home/airflow/.local/lib/python3.8/site-packages/fs/base.py", line 693, in readtext
    self.open(
  File "/home/airflow/.local/lib/python3.8/site-packages/fs/osfs.py", line 647, in open
    return io.open(
  File "/home/airflow/.local/lib/python3.8/site-packages/fs/error_tools.py", line 89, in __exit__
    reraise(fserror, fserror(self._path, exc=exc_value), traceback)
  File "/home/airflow/.local/lib/python3.8/site-packages/six.py", line 718, in reraise
    raise value.with_traceback(tb)
  File "/home/airflow/.local/lib/python3.8/site-packages/fs/osfs.py", line 647, in open
    return io.open(
fs.errors.ResourceNotFound: resource 'user_to_pik_recommender_model/latest' not found

During handling of the above exception, another exception occurred:

Traceback (most recent call last):
  File "/home/airflow/.local/lib/python3.8/site-packages/bentoml/_internal/store.py", line 106, in _recreate_latest
    items = self.list(tag.name)
  File "/home/airflow/.local/lib/python3.8/site-packages/bentoml/_internal/store.py", line 83, in list
    raise NotFound(
bentoml.exceptions.NotFound: no Models with name 'user_to_pik_recommender_model' found

During handling of the above exception, another exception occurred:

Traceback (most recent call last):
  File "/home/airflow/.local/lib/python3.8/site-packages/airflow/models/dagbag.py", line 326, in parse
    loader.exec_module(new_module)
  File "<frozen importlib._bootstrap_external>", line 843, in exec_module
  File "<frozen importlib._bootstrap>", line 219, in _call_with_frames_removed
  File "/opt/airflow/dags/bentoml/user_to_pik_rec_bento/bento_service_user_to_pik_rec.py", line 24, in <module>
    runner = bentoml.transformers.get("user_to_pik_recommender_model:latest").to_runner()
  File "/home/airflow/.local/lib/python3.8/site-packages/bentoml/_internal/frameworks/transformers.py", line 151, in get
    model = bentoml.models.get(tag_like)
  File "/home/airflow/.local/lib/python3.8/site-packages/simple_di/__init__.py", line 139, in _
    return func(*_inject_args(bind.args), **_inject_kwargs(bind.kwargs))
  File "/home/airflow/.local/lib/python3.8/site-packages/bentoml/models.py", line 41, in get
    return _model_store.get(tag)
  File "/home/airflow/.local/lib/python3.8/site-packages/bentoml/_internal/store.py", line 137, in get
    self._recreate_latest(_tag)
  File "/home/airflow/.local/lib/python3.8/site-packages/bentoml/_internal/store.py", line 108, in _recreate_latest
    raise NotFound(
bentoml.exceptions.NotFound: no Models with name 'user_to_pik_recommender_model' exist in BentoML store <osfs '/home/airflow/bentoml/models'>
[2023-01-19T04:15:41.075+0000] {processor.py:770} WARNING - No viable dags retrieved from /opt/airflow/dags/bentoml/user_to_pik_rec_bento/bento_service_user_to_pik_rec.py
[2023-01-19T04:15:41.087+0000] {processor.py:178} INFO - Processing /opt/airflow/dags/bentoml/user_to_pik_rec_bento/bento_service_user_to_pik_rec.py took 2.307 seconds
[2023-01-19T04:16:11.213+0000] {processor.py:156} INFO - Started process (PID=4472) to work on /opt/airflow/dags/bentoml/user_to_pik_rec_bento/bento_service_user_to_pik_rec.py
[2023-01-19T04:16:11.214+0000] {processor.py:758} INFO - Processing file /opt/airflow/dags/bentoml/user_to_pik_rec_bento/bento_service_user_to_pik_rec.py for tasks to queue
[2023-01-19T04:16:11.214+0000] {logging_mixin.py:117} INFO - [2023-01-19T04:16:11.214+0000] {dagbag.py:525} INFO - Filling up the DagBag from /opt/airflow/dags/bentoml/user_to_pik_rec_bento/bento_service_user_to_pik_rec.py
[2023-01-19T04:16:13.427+0000] {logging_mixin.py:117} INFO - [2023-01-19T04:16:13.425+0000] {dagbag.py:330} ERROR - Failed to import: /opt/airflow/dags/bentoml/user_to_pik_rec_bento/bento_service_user_to_pik_rec.py
Traceback (most recent call last):
  File "/home/airflow/.local/lib/python3.8/site-packages/fs/osfs.py", line 647, in open
    return io.open(
FileNotFoundError: [Errno 2] No such file or directory: b'/home/airflow/bentoml/models/user_to_pik_recommender_model/latest'

During handling of the above exception, another exception occurred:

Traceback (most recent call last):
  File "/home/airflow/.local/lib/python3.8/site-packages/bentoml/_internal/store.py", line 132, in get
    _tag.version = self._fs.readtext(_tag.latest_path())
  File "/home/airflow/.local/lib/python3.8/site-packages/fs/base.py", line 693, in readtext
    self.open(
  File "/home/airflow/.local/lib/python3.8/site-packages/fs/osfs.py", line 647, in open
    return io.open(
  File "/home/airflow/.local/lib/python3.8/site-packages/fs/error_tools.py", line 89, in __exit__
    reraise(fserror, fserror(self._path, exc=exc_value), traceback)
  File "/home/airflow/.local/lib/python3.8/site-packages/six.py", line 718, in reraise
    raise value.with_traceback(tb)
  File "/home/airflow/.local/lib/python3.8/site-packages/fs/osfs.py", line 647, in open
    return io.open(
fs.errors.ResourceNotFound: resource 'user_to_pik_recommender_model/latest' not found

During handling of the above exception, another exception occurred:

Traceback (most recent call last):
  File "/home/airflow/.local/lib/python3.8/site-packages/bentoml/_internal/store.py", line 106, in _recreate_latest
    items = self.list(tag.name)
  File "/home/airflow/.local/lib/python3.8/site-packages/bentoml/_internal/store.py", line 83, in list
    raise NotFound(
bentoml.exceptions.NotFound: no Models with name 'user_to_pik_recommender_model' found

During handling of the above exception, another exception occurred:

Traceback (most recent call last):
  File "/home/airflow/.local/lib/python3.8/site-packages/airflow/models/dagbag.py", line 326, in parse
    loader.exec_module(new_module)
  File "<frozen importlib._bootstrap_external>", line 843, in exec_module
  File "<frozen importlib._bootstrap>", line 219, in _call_with_frames_removed
  File "/opt/airflow/dags/bentoml/user_to_pik_rec_bento/bento_service_user_to_pik_rec.py", line 24, in <module>
    runner = bentoml.transformers.get("user_to_pik_recommender_model:latest").to_runner()
  File "/home/airflow/.local/lib/python3.8/site-packages/bentoml/_internal/frameworks/transformers.py", line 151, in get
    model = bentoml.models.get(tag_like)
  File "/home/airflow/.local/lib/python3.8/site-packages/simple_di/__init__.py", line 139, in _
    return func(*_inject_args(bind.args), **_inject_kwargs(bind.kwargs))
  File "/home/airflow/.local/lib/python3.8/site-packages/bentoml/models.py", line 41, in get
    return _model_store.get(tag)
  File "/home/airflow/.local/lib/python3.8/site-packages/bentoml/_internal/store.py", line 137, in get
    self._recreate_latest(_tag)
  File "/home/airflow/.local/lib/python3.8/site-packages/bentoml/_internal/store.py", line 108, in _recreate_latest
    raise NotFound(
bentoml.exceptions.NotFound: no Models with name 'user_to_pik_recommender_model' exist in BentoML store <osfs '/home/airflow/bentoml/models'>
[2023-01-19T04:16:13.428+0000] {processor.py:770} WARNING - No viable dags retrieved from /opt/airflow/dags/bentoml/user_to_pik_rec_bento/bento_service_user_to_pik_rec.py
[2023-01-19T04:16:13.444+0000] {processor.py:178} INFO - Processing /opt/airflow/dags/bentoml/user_to_pik_rec_bento/bento_service_user_to_pik_rec.py took 2.234 seconds
[2023-01-19T04:16:43.677+0000] {processor.py:156} INFO - Started process (PID=4530) to work on /opt/airflow/dags/bentoml/user_to_pik_rec_bento/bento_service_user_to_pik_rec.py
[2023-01-19T04:16:43.678+0000] {processor.py:758} INFO - Processing file /opt/airflow/dags/bentoml/user_to_pik_rec_bento/bento_service_user_to_pik_rec.py for tasks to queue
[2023-01-19T04:16:43.679+0000] {logging_mixin.py:117} INFO - [2023-01-19T04:16:43.678+0000] {dagbag.py:525} INFO - Filling up the DagBag from /opt/airflow/dags/bentoml/user_to_pik_rec_bento/bento_service_user_to_pik_rec.py
[2023-01-19T04:16:45.889+0000] {logging_mixin.py:117} INFO - [2023-01-19T04:16:45.887+0000] {dagbag.py:330} ERROR - Failed to import: /opt/airflow/dags/bentoml/user_to_pik_rec_bento/bento_service_user_to_pik_rec.py
Traceback (most recent call last):
  File "/home/airflow/.local/lib/python3.8/site-packages/fs/osfs.py", line 647, in open
    return io.open(
FileNotFoundError: [Errno 2] No such file or directory: b'/home/airflow/bentoml/models/user_to_pik_recommender_model/latest'

During handling of the above exception, another exception occurred:

Traceback (most recent call last):
  File "/home/airflow/.local/lib/python3.8/site-packages/bentoml/_internal/store.py", line 132, in get
    _tag.version = self._fs.readtext(_tag.latest_path())
  File "/home/airflow/.local/lib/python3.8/site-packages/fs/base.py", line 693, in readtext
    self.open(
  File "/home/airflow/.local/lib/python3.8/site-packages/fs/osfs.py", line 647, in open
    return io.open(
  File "/home/airflow/.local/lib/python3.8/site-packages/fs/error_tools.py", line 89, in __exit__
    reraise(fserror, fserror(self._path, exc=exc_value), traceback)
  File "/home/airflow/.local/lib/python3.8/site-packages/six.py", line 718, in reraise
    raise value.with_traceback(tb)
  File "/home/airflow/.local/lib/python3.8/site-packages/fs/osfs.py", line 647, in open
    return io.open(
fs.errors.ResourceNotFound: resource 'user_to_pik_recommender_model/latest' not found

During handling of the above exception, another exception occurred:

Traceback (most recent call last):
  File "/home/airflow/.local/lib/python3.8/site-packages/bentoml/_internal/store.py", line 106, in _recreate_latest
    items = self.list(tag.name)
  File "/home/airflow/.local/lib/python3.8/site-packages/bentoml/_internal/store.py", line 83, in list
    raise NotFound(
bentoml.exceptions.NotFound: no Models with name 'user_to_pik_recommender_model' found

During handling of the above exception, another exception occurred:

Traceback (most recent call last):
  File "/home/airflow/.local/lib/python3.8/site-packages/airflow/models/dagbag.py", line 326, in parse
    loader.exec_module(new_module)
  File "<frozen importlib._bootstrap_external>", line 843, in exec_module
  File "<frozen importlib._bootstrap>", line 219, in _call_with_frames_removed
  File "/opt/airflow/dags/bentoml/user_to_pik_rec_bento/bento_service_user_to_pik_rec.py", line 24, in <module>
    runner = bentoml.transformers.get("user_to_pik_recommender_model:latest").to_runner()
  File "/home/airflow/.local/lib/python3.8/site-packages/bentoml/_internal/frameworks/transformers.py", line 151, in get
    model = bentoml.models.get(tag_like)
  File "/home/airflow/.local/lib/python3.8/site-packages/simple_di/__init__.py", line 139, in _
    return func(*_inject_args(bind.args), **_inject_kwargs(bind.kwargs))
  File "/home/airflow/.local/lib/python3.8/site-packages/bentoml/models.py", line 41, in get
    return _model_store.get(tag)
  File "/home/airflow/.local/lib/python3.8/site-packages/bentoml/_internal/store.py", line 137, in get
    self._recreate_latest(_tag)
  File "/home/airflow/.local/lib/python3.8/site-packages/bentoml/_internal/store.py", line 108, in _recreate_latest
    raise NotFound(
bentoml.exceptions.NotFound: no Models with name 'user_to_pik_recommender_model' exist in BentoML store <osfs '/home/airflow/bentoml/models'>
[2023-01-19T04:16:45.890+0000] {processor.py:770} WARNING - No viable dags retrieved from /opt/airflow/dags/bentoml/user_to_pik_rec_bento/bento_service_user_to_pik_rec.py
[2023-01-19T04:16:45.906+0000] {processor.py:178} INFO - Processing /opt/airflow/dags/bentoml/user_to_pik_rec_bento/bento_service_user_to_pik_rec.py took 2.232 seconds
[2023-01-19T04:17:15.995+0000] {processor.py:156} INFO - Started process (PID=4588) to work on /opt/airflow/dags/bentoml/user_to_pik_rec_bento/bento_service_user_to_pik_rec.py
[2023-01-19T04:17:15.995+0000] {processor.py:758} INFO - Processing file /opt/airflow/dags/bentoml/user_to_pik_rec_bento/bento_service_user_to_pik_rec.py for tasks to queue
[2023-01-19T04:17:15.996+0000] {logging_mixin.py:117} INFO - [2023-01-19T04:17:15.996+0000] {dagbag.py:525} INFO - Filling up the DagBag from /opt/airflow/dags/bentoml/user_to_pik_rec_bento/bento_service_user_to_pik_rec.py
[2023-01-19T04:17:18.179+0000] {logging_mixin.py:117} INFO - [2023-01-19T04:17:18.177+0000] {dagbag.py:330} ERROR - Failed to import: /opt/airflow/dags/bentoml/user_to_pik_rec_bento/bento_service_user_to_pik_rec.py
Traceback (most recent call last):
  File "/home/airflow/.local/lib/python3.8/site-packages/fs/osfs.py", line 647, in open
    return io.open(
FileNotFoundError: [Errno 2] No such file or directory: b'/home/airflow/bentoml/models/user_to_pik_recommender_model/latest'

During handling of the above exception, another exception occurred:

Traceback (most recent call last):
  File "/home/airflow/.local/lib/python3.8/site-packages/bentoml/_internal/store.py", line 132, in get
    _tag.version = self._fs.readtext(_tag.latest_path())
  File "/home/airflow/.local/lib/python3.8/site-packages/fs/base.py", line 693, in readtext
    self.open(
  File "/home/airflow/.local/lib/python3.8/site-packages/fs/osfs.py", line 647, in open
    return io.open(
  File "/home/airflow/.local/lib/python3.8/site-packages/fs/error_tools.py", line 89, in __exit__
    reraise(fserror, fserror(self._path, exc=exc_value), traceback)
  File "/home/airflow/.local/lib/python3.8/site-packages/six.py", line 718, in reraise
    raise value.with_traceback(tb)
  File "/home/airflow/.local/lib/python3.8/site-packages/fs/osfs.py", line 647, in open
    return io.open(
fs.errors.ResourceNotFound: resource 'user_to_pik_recommender_model/latest' not found

During handling of the above exception, another exception occurred:

Traceback (most recent call last):
  File "/home/airflow/.local/lib/python3.8/site-packages/bentoml/_internal/store.py", line 106, in _recreate_latest
    items = self.list(tag.name)
  File "/home/airflow/.local/lib/python3.8/site-packages/bentoml/_internal/store.py", line 83, in list
    raise NotFound(
bentoml.exceptions.NotFound: no Models with name 'user_to_pik_recommender_model' found

During handling of the above exception, another exception occurred:

Traceback (most recent call last):
  File "/home/airflow/.local/lib/python3.8/site-packages/airflow/models/dagbag.py", line 326, in parse
    loader.exec_module(new_module)
  File "<frozen importlib._bootstrap_external>", line 843, in exec_module
  File "<frozen importlib._bootstrap>", line 219, in _call_with_frames_removed
  File "/opt/airflow/dags/bentoml/user_to_pik_rec_bento/bento_service_user_to_pik_rec.py", line 24, in <module>
    runner = bentoml.transformers.get("user_to_pik_recommender_model:latest").to_runner()
  File "/home/airflow/.local/lib/python3.8/site-packages/bentoml/_internal/frameworks/transformers.py", line 151, in get
    model = bentoml.models.get(tag_like)
  File "/home/airflow/.local/lib/python3.8/site-packages/simple_di/__init__.py", line 139, in _
    return func(*_inject_args(bind.args), **_inject_kwargs(bind.kwargs))
  File "/home/airflow/.local/lib/python3.8/site-packages/bentoml/models.py", line 41, in get
    return _model_store.get(tag)
  File "/home/airflow/.local/lib/python3.8/site-packages/bentoml/_internal/store.py", line 137, in get
    self._recreate_latest(_tag)
  File "/home/airflow/.local/lib/python3.8/site-packages/bentoml/_internal/store.py", line 108, in _recreate_latest
    raise NotFound(
bentoml.exceptions.NotFound: no Models with name 'user_to_pik_recommender_model' exist in BentoML store <osfs '/home/airflow/bentoml/models'>
[2023-01-19T04:17:18.179+0000] {processor.py:770} WARNING - No viable dags retrieved from /opt/airflow/dags/bentoml/user_to_pik_rec_bento/bento_service_user_to_pik_rec.py
[2023-01-19T04:17:18.195+0000] {processor.py:178} INFO - Processing /opt/airflow/dags/bentoml/user_to_pik_rec_bento/bento_service_user_to_pik_rec.py took 2.203 seconds
[2023-01-19T04:17:48.482+0000] {processor.py:156} INFO - Started process (PID=4646) to work on /opt/airflow/dags/bentoml/user_to_pik_rec_bento/bento_service_user_to_pik_rec.py
[2023-01-19T04:17:48.483+0000] {processor.py:758} INFO - Processing file /opt/airflow/dags/bentoml/user_to_pik_rec_bento/bento_service_user_to_pik_rec.py for tasks to queue
[2023-01-19T04:17:48.484+0000] {logging_mixin.py:117} INFO - [2023-01-19T04:17:48.483+0000] {dagbag.py:525} INFO - Filling up the DagBag from /opt/airflow/dags/bentoml/user_to_pik_rec_bento/bento_service_user_to_pik_rec.py
[2023-01-19T04:17:50.677+0000] {logging_mixin.py:117} INFO - [2023-01-19T04:17:50.676+0000] {dagbag.py:330} ERROR - Failed to import: /opt/airflow/dags/bentoml/user_to_pik_rec_bento/bento_service_user_to_pik_rec.py
Traceback (most recent call last):
  File "/home/airflow/.local/lib/python3.8/site-packages/fs/osfs.py", line 647, in open
    return io.open(
FileNotFoundError: [Errno 2] No such file or directory: b'/home/airflow/bentoml/models/user_to_pik_recommender_model/latest'

During handling of the above exception, another exception occurred:

Traceback (most recent call last):
  File "/home/airflow/.local/lib/python3.8/site-packages/bentoml/_internal/store.py", line 132, in get
    _tag.version = self._fs.readtext(_tag.latest_path())
  File "/home/airflow/.local/lib/python3.8/site-packages/fs/base.py", line 693, in readtext
    self.open(
  File "/home/airflow/.local/lib/python3.8/site-packages/fs/osfs.py", line 647, in open
    return io.open(
  File "/home/airflow/.local/lib/python3.8/site-packages/fs/error_tools.py", line 89, in __exit__
    reraise(fserror, fserror(self._path, exc=exc_value), traceback)
  File "/home/airflow/.local/lib/python3.8/site-packages/six.py", line 718, in reraise
    raise value.with_traceback(tb)
  File "/home/airflow/.local/lib/python3.8/site-packages/fs/osfs.py", line 647, in open
    return io.open(
fs.errors.ResourceNotFound: resource 'user_to_pik_recommender_model/latest' not found

During handling of the above exception, another exception occurred:

Traceback (most recent call last):
  File "/home/airflow/.local/lib/python3.8/site-packages/bentoml/_internal/store.py", line 106, in _recreate_latest
    items = self.list(tag.name)
  File "/home/airflow/.local/lib/python3.8/site-packages/bentoml/_internal/store.py", line 83, in list
    raise NotFound(
bentoml.exceptions.NotFound: no Models with name 'user_to_pik_recommender_model' found

During handling of the above exception, another exception occurred:

Traceback (most recent call last):
  File "/home/airflow/.local/lib/python3.8/site-packages/airflow/models/dagbag.py", line 326, in parse
    loader.exec_module(new_module)
  File "<frozen importlib._bootstrap_external>", line 843, in exec_module
  File "<frozen importlib._bootstrap>", line 219, in _call_with_frames_removed
  File "/opt/airflow/dags/bentoml/user_to_pik_rec_bento/bento_service_user_to_pik_rec.py", line 24, in <module>
    runner = bentoml.transformers.get("user_to_pik_recommender_model:latest").to_runner()
  File "/home/airflow/.local/lib/python3.8/site-packages/bentoml/_internal/frameworks/transformers.py", line 151, in get
    model = bentoml.models.get(tag_like)
  File "/home/airflow/.local/lib/python3.8/site-packages/simple_di/__init__.py", line 139, in _
    return func(*_inject_args(bind.args), **_inject_kwargs(bind.kwargs))
  File "/home/airflow/.local/lib/python3.8/site-packages/bentoml/models.py", line 41, in get
    return _model_store.get(tag)
  File "/home/airflow/.local/lib/python3.8/site-packages/bentoml/_internal/store.py", line 137, in get
    self._recreate_latest(_tag)
  File "/home/airflow/.local/lib/python3.8/site-packages/bentoml/_internal/store.py", line 108, in _recreate_latest
    raise NotFound(
bentoml.exceptions.NotFound: no Models with name 'user_to_pik_recommender_model' exist in BentoML store <osfs '/home/airflow/bentoml/models'>
[2023-01-19T04:17:50.678+0000] {processor.py:770} WARNING - No viable dags retrieved from /opt/airflow/dags/bentoml/user_to_pik_rec_bento/bento_service_user_to_pik_rec.py
[2023-01-19T04:17:50.691+0000] {processor.py:178} INFO - Processing /opt/airflow/dags/bentoml/user_to_pik_rec_bento/bento_service_user_to_pik_rec.py took 2.212 seconds
[2023-01-19T04:18:21.020+0000] {processor.py:156} INFO - Started process (PID=4704) to work on /opt/airflow/dags/bentoml/user_to_pik_rec_bento/bento_service_user_to_pik_rec.py
[2023-01-19T04:18:21.021+0000] {processor.py:758} INFO - Processing file /opt/airflow/dags/bentoml/user_to_pik_rec_bento/bento_service_user_to_pik_rec.py for tasks to queue
[2023-01-19T04:18:21.021+0000] {logging_mixin.py:117} INFO - [2023-01-19T04:18:21.021+0000] {dagbag.py:525} INFO - Filling up the DagBag from /opt/airflow/dags/bentoml/user_to_pik_rec_bento/bento_service_user_to_pik_rec.py
[2023-01-19T04:18:23.190+0000] {logging_mixin.py:117} INFO - [2023-01-19T04:18:23.188+0000] {dagbag.py:330} ERROR - Failed to import: /opt/airflow/dags/bentoml/user_to_pik_rec_bento/bento_service_user_to_pik_rec.py
Traceback (most recent call last):
  File "/home/airflow/.local/lib/python3.8/site-packages/fs/osfs.py", line 647, in open
    return io.open(
FileNotFoundError: [Errno 2] No such file or directory: b'/home/airflow/bentoml/models/user_to_pik_recommender_model/latest'

During handling of the above exception, another exception occurred:

Traceback (most recent call last):
  File "/home/airflow/.local/lib/python3.8/site-packages/bentoml/_internal/store.py", line 132, in get
    _tag.version = self._fs.readtext(_tag.latest_path())
  File "/home/airflow/.local/lib/python3.8/site-packages/fs/base.py", line 693, in readtext
    self.open(
  File "/home/airflow/.local/lib/python3.8/site-packages/fs/osfs.py", line 647, in open
    return io.open(
  File "/home/airflow/.local/lib/python3.8/site-packages/fs/error_tools.py", line 89, in __exit__
    reraise(fserror, fserror(self._path, exc=exc_value), traceback)
  File "/home/airflow/.local/lib/python3.8/site-packages/six.py", line 718, in reraise
    raise value.with_traceback(tb)
  File "/home/airflow/.local/lib/python3.8/site-packages/fs/osfs.py", line 647, in open
    return io.open(
fs.errors.ResourceNotFound: resource 'user_to_pik_recommender_model/latest' not found

During handling of the above exception, another exception occurred:

Traceback (most recent call last):
  File "/home/airflow/.local/lib/python3.8/site-packages/bentoml/_internal/store.py", line 106, in _recreate_latest
    items = self.list(tag.name)
  File "/home/airflow/.local/lib/python3.8/site-packages/bentoml/_internal/store.py", line 83, in list
    raise NotFound(
bentoml.exceptions.NotFound: no Models with name 'user_to_pik_recommender_model' found

During handling of the above exception, another exception occurred:

Traceback (most recent call last):
  File "/home/airflow/.local/lib/python3.8/site-packages/airflow/models/dagbag.py", line 326, in parse
    loader.exec_module(new_module)
  File "<frozen importlib._bootstrap_external>", line 843, in exec_module
  File "<frozen importlib._bootstrap>", line 219, in _call_with_frames_removed
  File "/opt/airflow/dags/bentoml/user_to_pik_rec_bento/bento_service_user_to_pik_rec.py", line 24, in <module>
    runner = bentoml.transformers.get("user_to_pik_recommender_model:latest").to_runner()
  File "/home/airflow/.local/lib/python3.8/site-packages/bentoml/_internal/frameworks/transformers.py", line 151, in get
    model = bentoml.models.get(tag_like)
  File "/home/airflow/.local/lib/python3.8/site-packages/simple_di/__init__.py", line 139, in _
    return func(*_inject_args(bind.args), **_inject_kwargs(bind.kwargs))
  File "/home/airflow/.local/lib/python3.8/site-packages/bentoml/models.py", line 41, in get
    return _model_store.get(tag)
  File "/home/airflow/.local/lib/python3.8/site-packages/bentoml/_internal/store.py", line 137, in get
    self._recreate_latest(_tag)
  File "/home/airflow/.local/lib/python3.8/site-packages/bentoml/_internal/store.py", line 108, in _recreate_latest
    raise NotFound(
bentoml.exceptions.NotFound: no Models with name 'user_to_pik_recommender_model' exist in BentoML store <osfs '/home/airflow/bentoml/models'>
[2023-01-19T04:18:23.191+0000] {processor.py:770} WARNING - No viable dags retrieved from /opt/airflow/dags/bentoml/user_to_pik_rec_bento/bento_service_user_to_pik_rec.py
[2023-01-19T04:18:23.206+0000] {processor.py:178} INFO - Processing /opt/airflow/dags/bentoml/user_to_pik_rec_bento/bento_service_user_to_pik_rec.py took 2.189 seconds
[2023-01-19T04:18:53.344+0000] {processor.py:156} INFO - Started process (PID=4762) to work on /opt/airflow/dags/bentoml/user_to_pik_rec_bento/bento_service_user_to_pik_rec.py
[2023-01-19T04:18:53.345+0000] {processor.py:758} INFO - Processing file /opt/airflow/dags/bentoml/user_to_pik_rec_bento/bento_service_user_to_pik_rec.py for tasks to queue
[2023-01-19T04:18:53.345+0000] {logging_mixin.py:117} INFO - [2023-01-19T04:18:53.345+0000] {dagbag.py:525} INFO - Filling up the DagBag from /opt/airflow/dags/bentoml/user_to_pik_rec_bento/bento_service_user_to_pik_rec.py
[2023-01-19T04:18:55.494+0000] {logging_mixin.py:117} INFO - [2023-01-19T04:18:55.492+0000] {dagbag.py:330} ERROR - Failed to import: /opt/airflow/dags/bentoml/user_to_pik_rec_bento/bento_service_user_to_pik_rec.py
Traceback (most recent call last):
  File "/home/airflow/.local/lib/python3.8/site-packages/fs/osfs.py", line 647, in open
    return io.open(
FileNotFoundError: [Errno 2] No such file or directory: b'/home/airflow/bentoml/models/user_to_pik_recommender_model/latest'

During handling of the above exception, another exception occurred:

Traceback (most recent call last):
  File "/home/airflow/.local/lib/python3.8/site-packages/bentoml/_internal/store.py", line 132, in get
    _tag.version = self._fs.readtext(_tag.latest_path())
  File "/home/airflow/.local/lib/python3.8/site-packages/fs/base.py", line 693, in readtext
    self.open(
  File "/home/airflow/.local/lib/python3.8/site-packages/fs/osfs.py", line 647, in open
    return io.open(
  File "/home/airflow/.local/lib/python3.8/site-packages/fs/error_tools.py", line 89, in __exit__
    reraise(fserror, fserror(self._path, exc=exc_value), traceback)
  File "/home/airflow/.local/lib/python3.8/site-packages/six.py", line 718, in reraise
    raise value.with_traceback(tb)
  File "/home/airflow/.local/lib/python3.8/site-packages/fs/osfs.py", line 647, in open
    return io.open(
fs.errors.ResourceNotFound: resource 'user_to_pik_recommender_model/latest' not found

During handling of the above exception, another exception occurred:

Traceback (most recent call last):
  File "/home/airflow/.local/lib/python3.8/site-packages/bentoml/_internal/store.py", line 106, in _recreate_latest
    items = self.list(tag.name)
  File "/home/airflow/.local/lib/python3.8/site-packages/bentoml/_internal/store.py", line 83, in list
    raise NotFound(
bentoml.exceptions.NotFound: no Models with name 'user_to_pik_recommender_model' found

During handling of the above exception, another exception occurred:

Traceback (most recent call last):
  File "/home/airflow/.local/lib/python3.8/site-packages/airflow/models/dagbag.py", line 326, in parse
    loader.exec_module(new_module)
  File "<frozen importlib._bootstrap_external>", line 843, in exec_module
  File "<frozen importlib._bootstrap>", line 219, in _call_with_frames_removed
  File "/opt/airflow/dags/bentoml/user_to_pik_rec_bento/bento_service_user_to_pik_rec.py", line 24, in <module>
    runner = bentoml.transformers.get("user_to_pik_recommender_model:latest").to_runner()
  File "/home/airflow/.local/lib/python3.8/site-packages/bentoml/_internal/frameworks/transformers.py", line 151, in get
    model = bentoml.models.get(tag_like)
  File "/home/airflow/.local/lib/python3.8/site-packages/simple_di/__init__.py", line 139, in _
    return func(*_inject_args(bind.args), **_inject_kwargs(bind.kwargs))
  File "/home/airflow/.local/lib/python3.8/site-packages/bentoml/models.py", line 41, in get
    return _model_store.get(tag)
  File "/home/airflow/.local/lib/python3.8/site-packages/bentoml/_internal/store.py", line 137, in get
    self._recreate_latest(_tag)
  File "/home/airflow/.local/lib/python3.8/site-packages/bentoml/_internal/store.py", line 108, in _recreate_latest
    raise NotFound(
bentoml.exceptions.NotFound: no Models with name 'user_to_pik_recommender_model' exist in BentoML store <osfs '/home/airflow/bentoml/models'>
[2023-01-19T04:18:55.494+0000] {processor.py:770} WARNING - No viable dags retrieved from /opt/airflow/dags/bentoml/user_to_pik_rec_bento/bento_service_user_to_pik_rec.py
[2023-01-19T04:18:55.507+0000] {processor.py:178} INFO - Processing /opt/airflow/dags/bentoml/user_to_pik_rec_bento/bento_service_user_to_pik_rec.py took 2.166 seconds
[2023-01-19T04:19:26.321+0000] {processor.py:156} INFO - Started process (PID=4820) to work on /opt/airflow/dags/bentoml/user_to_pik_rec_bento/bento_service_user_to_pik_rec.py
[2023-01-19T04:19:26.321+0000] {processor.py:758} INFO - Processing file /opt/airflow/dags/bentoml/user_to_pik_rec_bento/bento_service_user_to_pik_rec.py for tasks to queue
[2023-01-19T04:19:26.322+0000] {logging_mixin.py:117} INFO - [2023-01-19T04:19:26.322+0000] {dagbag.py:525} INFO - Filling up the DagBag from /opt/airflow/dags/bentoml/user_to_pik_rec_bento/bento_service_user_to_pik_rec.py
[2023-01-19T04:19:28.557+0000] {logging_mixin.py:117} INFO - [2023-01-19T04:19:28.554+0000] {dagbag.py:330} ERROR - Failed to import: /opt/airflow/dags/bentoml/user_to_pik_rec_bento/bento_service_user_to_pik_rec.py
Traceback (most recent call last):
  File "/home/airflow/.local/lib/python3.8/site-packages/fs/osfs.py", line 647, in open
    return io.open(
FileNotFoundError: [Errno 2] No such file or directory: b'/home/airflow/bentoml/models/user_to_pik_recommender_model/latest'

During handling of the above exception, another exception occurred:

Traceback (most recent call last):
  File "/home/airflow/.local/lib/python3.8/site-packages/bentoml/_internal/store.py", line 132, in get
    _tag.version = self._fs.readtext(_tag.latest_path())
  File "/home/airflow/.local/lib/python3.8/site-packages/fs/base.py", line 693, in readtext
    self.open(
  File "/home/airflow/.local/lib/python3.8/site-packages/fs/osfs.py", line 647, in open
    return io.open(
  File "/home/airflow/.local/lib/python3.8/site-packages/fs/error_tools.py", line 89, in __exit__
    reraise(fserror, fserror(self._path, exc=exc_value), traceback)
  File "/home/airflow/.local/lib/python3.8/site-packages/six.py", line 718, in reraise
    raise value.with_traceback(tb)
  File "/home/airflow/.local/lib/python3.8/site-packages/fs/osfs.py", line 647, in open
    return io.open(
fs.errors.ResourceNotFound: resource 'user_to_pik_recommender_model/latest' not found

During handling of the above exception, another exception occurred:

Traceback (most recent call last):
  File "/home/airflow/.local/lib/python3.8/site-packages/bentoml/_internal/store.py", line 106, in _recreate_latest
    items = self.list(tag.name)
  File "/home/airflow/.local/lib/python3.8/site-packages/bentoml/_internal/store.py", line 83, in list
    raise NotFound(
bentoml.exceptions.NotFound: no Models with name 'user_to_pik_recommender_model' found

During handling of the above exception, another exception occurred:

Traceback (most recent call last):
  File "/home/airflow/.local/lib/python3.8/site-packages/airflow/models/dagbag.py", line 326, in parse
    loader.exec_module(new_module)
  File "<frozen importlib._bootstrap_external>", line 843, in exec_module
  File "<frozen importlib._bootstrap>", line 219, in _call_with_frames_removed
  File "/opt/airflow/dags/bentoml/user_to_pik_rec_bento/bento_service_user_to_pik_rec.py", line 24, in <module>
    runner = bentoml.transformers.get("user_to_pik_recommender_model:latest").to_runner()
  File "/home/airflow/.local/lib/python3.8/site-packages/bentoml/_internal/frameworks/transformers.py", line 151, in get
    model = bentoml.models.get(tag_like)
  File "/home/airflow/.local/lib/python3.8/site-packages/simple_di/__init__.py", line 139, in _
    return func(*_inject_args(bind.args), **_inject_kwargs(bind.kwargs))
  File "/home/airflow/.local/lib/python3.8/site-packages/bentoml/models.py", line 41, in get
    return _model_store.get(tag)
  File "/home/airflow/.local/lib/python3.8/site-packages/bentoml/_internal/store.py", line 137, in get
    self._recreate_latest(_tag)
  File "/home/airflow/.local/lib/python3.8/site-packages/bentoml/_internal/store.py", line 108, in _recreate_latest
    raise NotFound(
bentoml.exceptions.NotFound: no Models with name 'user_to_pik_recommender_model' exist in BentoML store <osfs '/home/airflow/bentoml/models'>
[2023-01-19T04:19:28.557+0000] {processor.py:770} WARNING - No viable dags retrieved from /opt/airflow/dags/bentoml/user_to_pik_rec_bento/bento_service_user_to_pik_rec.py
[2023-01-19T04:19:28.576+0000] {processor.py:178} INFO - Processing /opt/airflow/dags/bentoml/user_to_pik_rec_bento/bento_service_user_to_pik_rec.py took 2.258 seconds
